Workbook

Sheet Temperatura
A2: VARIABLE | B2: TEMPERATURA MINIMA (°C) | C2: MES | D2: =VLOOKUP(E2,Minimos!AS1:AU13,2,FALSE) -> AGOSTO | E2: 8 | F2: AÑO | G2: 2026 | H2: DIAS | I2: =VLOOKUP(E2,Minimos!AS1:AU13,3,FALSE) -> 31 | J2: Mínima | K2: =MIN(K5:K208) -> 4.3 | L2: =MIN(L5:L208) -> 0 | M2: =MIN(M5:M208) -> 0 | N2: =MIN(N5:N208) -> 0 | O2: =MIN(O5:O208) -> 0 | P2: =MIN(P5:P208) -> 0 | Q2: =MIN(Q5:Q208) -> 0 | R2: =MIN(R5:R208) -> 0 | ... AO2: =MIN(AO5:AO208) -> 0 | AP2: =MIN(K2:AO2) -> 0
A4: CODIGO | B4: ESTACION | C4: AREA_OP | D4: LON | E4: LAT | F4: ELEV | G4: COD_DPTO | H4: COD_MUNICIPIO | I4: DEPARTAMENTO | J4: MUNICIPIO | K4: 1 | L4: 2 | M4: 3 | N4: 4 | O4: 5 | P4: 6 | Q4: 7 | R4: 8 | S4: 9 | T4: 10 | U4: 11 | V4: 12 | W4: 13 | X4: 14 | Y4: 15 | Z4: 16 | AA4: 17 | AB4: 18 | AC4: 19 | AD4: 20 | AE4: 21 | AF4: 22 | AG4: 23 | AH4: 24 | AI4: 25 | AJ4: 26 | AK4: 27 | AL4: 28 | AM4: 29 | AN4: 30 | AO4: 31 | AP4: NUM_DATOS | AQ4: MEDIA_MENSUAL | AR4: MEDIA_MULTIANUAL | AS4: ANOMALIA | AT4: MIN_MES | AU4: MIN_HISTORICO | AV4: FECHA | AW4: DIFERENCIA
A5: 17015010 | B5: Aeropuerto Sesquicentenario | C5: Grupo Observación y Monitoreo | D5: -81.704 | E5: 12.587 | F5: 1 | G5: 88 | H5: 88001 | I5: Archipiélago de San Andres, Providencia y Santa Catalina | J5: Isla de San Andrés | K5: 26.1 | AP5: =COUNTIF(K5:AO5,">0") -> 1 | AQ5: =IF(AP5>14,AVERAGE(K5:AO5),"") | AR5: =IFERROR(VLOOKUP(A5,Climatologia!A:U,9+$E$2,FALSE),"") -> 26.259289 | AS5: =IF(OR(AQ5="",AR5=""),"",IFERROR(AQ5-AR5,"")) | AT5: =IF(COUNT(K5:AO5)=0,"",MIN(K5:AO5)) -> 26.1 | AU5: {=IFERROR( _xlfn.LET( _xlpm.mesTxt, INDEX({"ENERO","FEBRERO","MARZO","ABRIL","MAYO","JUNIO","JULIO","AGOSTO","SEPTIEMBRE","OCTUBRE","NOVIEMBRE","DICIEMBRE"}, E$2), _xlpm.colIni, MATCH(_xlpm.mesTxt, Minimos!$1:$1, 0), _xlpm.fila, MATCH($A5, Minimos!$A:$A, 0), _xlpm.val, INDEX(Minimos!$A:$ZZ, _xlpm.fila, _xlpm.colIni), IF(_xlpm.val="", "", _xlpm.val) ), "")} -> 21 | AV5: {=IFERROR( _xlfn.LET( _xlpm.mesNum, E$2, _xlpm.mesTxt, INDEX({"ENERO","FEBRERO","MARZO","ABRIL","MAYO","JUNIO","JULIO","AGOSTO","SEPTIEMBRE","OCTUBRE","NOVIEMBRE","DICIEMBRE"}, _xlpm.mesNum), _xlpm.colIni, MATCH(_xlpm.mesTxt, Minimos!$1:$1, 0), _xlpm.fila, MATCH($A5, Minimos!$A:$A, 0), _xlpm.anio, INDEX(Minimos!$A:$ZZ, _xlpm.fila, _xlpm.colIni+1), _xlpm.dia, INDEX(Minimos!$A:$ZZ, _xlpm.fila, _xlpm.colIni+2), IF(OR(_xlpm.anio="",_xlpm.dia=""), "", DATE(_xlpm.anio, _xlpm.mesNum, _xlpm.dia)) ), "")} -> 31637 | AW5: =IF(OR(AT5="",AU5=""),"NA",IFERROR(AT5-AU5,"NA")) -> 5.1
A6: 17025020 | B6: Aeropuerto El Embrujo | C6: Grupo Observación y Monitoreo | D6: -81.358 | E6: 13.36 | F6: 7 | G6: 88 | H6: 88564 | I6: Archipiélago de San Andres, Providencia y Santa Catalina | J6: Isla de Providencia | K6: 26.6 | AP6: =COUNTIF(K6:AO6,">0") -> 1 | AQ6: =IF(AP6>14,AVERAGE(K6:AO6),"") | AR6: =IFERROR(VLOOKUP(A6,Climatologia!A:U,9+$E$2,FALSE),"") -> 26.228813 | AS6: =IF(OR(AQ6="",AR6=""),"",IFERROR(AQ6-AR6,"")) | AT6: =IF(COUNT(K6:AO6)=0,"",MIN(K6:AO6)) -> 26.6 | AU6: {=IFERROR( _xlfn.LET( _xlpm.mesTxt, INDEX({"ENERO","FEBRERO","MARZO","ABRIL","MAYO","JUNIO","JULIO","AGOSTO","SEPTIEMBRE","OCTUBRE","NOVIEMBRE","DICIEMBRE"}, E$2), _xlpm.colIni, MATCH(_xlpm.mesTxt, Minimos!$1:$1, 0), _xlpm.fila, MATCH($A6, Minimos!$A:$A, 0), _xlpm.val, INDEX(Minimos!$A:$ZZ, _xlpm.fila, _xlpm.colIni), IF(_xlpm.val="", "", _xlpm.val) ), "")} -> 20.4 | AV6: {=IFERROR( _xlfn.LET( _xlpm.mesNum, E$2, _xlpm.mesTxt, INDEX({"ENERO","FEBRERO","MARZO","ABRIL","MAYO","JUNIO","JULIO","AGOSTO","SEPTIEMBRE","OCTUBRE","NOVIEMBRE","DICIEMBRE"}, _xlpm.mesNum), _xlpm.colIni, MATCH(_xlpm.mesTxt, Minimos!$1:$1, 0), _xlpm.fila, MATCH($A6, Minimos!$A:$A, 0), _xlpm.anio, INDEX(Minimos!$A:$ZZ, _xlpm.fila, _xlpm.colIni+1), _xlpm.dia, INDEX(Minimos!$A:$ZZ, _xlpm.fila, _xlpm.colIni+2), IF(OR(_xlpm.anio="",_xlpm.dia=""), "", DATE(_xlpm.anio, _xlpm.mesNum, _xlpm.dia)) ), "")} -> 39672 | AW6: =IF(OR(AT6="",AU6=""),"NA",IFERROR(AT6-AU6,"NA")) -> 6.2
A7: 15015050 | B7: Aeropuerto Simón Bolívar | C7: Grupo Observación y Monitoreo | D7: -74.229 | E7: 11.128 | F7: 4 | G7: 47 | H7: 47001 | I7: Magdalena | J7: Santa Marta | K7: 27 | AP7: =COUNTIF(K7:AO7,">0") -> 1 | AQ7: =IF(AP7>14,AVERAGE(K7:AO7),"") | AR7: =IFERROR(VLOOKUP(A7,Climatologia!A:U,9+$E$2,FALSE),"") -> 24.806007 | AS7: =IF(OR(AQ7="",AR7=""),"",IFERROR(AQ7-AR7,"")) | AT7: =IF(COUNT(K7:AO7)=0,"",MIN(K7:AO7)) -> 27 | AU7: {=IFERROR( _xlfn.LET( _xlpm.mesTxt, INDEX({"ENERO","FEBRERO","MARZO","ABRIL","MAYO","JUNIO","JULIO","AGOSTO","SEPTIEMBRE","OCTUBRE","NOVIEMBRE","DICIEMBRE"}, E$2), _xlpm.colIni, MATCH(_xlpm.mesTxt, Minimos!$1:$1, 0), _xlpm.fila, MATCH($A7, Minimos!$A:$A, 0), _xlpm.val, INDEX(Minimos!$A:$ZZ, _xlpm.fila, _xlpm.colIni), IF(_xlpm.val="", "", _xlpm.val) ), "")} -> 20.6 | AV7: {=IFERROR( _xlfn.LET( _xlpm.mesNum, E$2, _xlpm.mesTxt, INDEX({"ENERO","FEBRERO","MARZO","ABRIL","MAYO","JUNIO","JULIO","AGOSTO","SEPTIEMBRE","OCTUBRE","NOVIEMBRE","DICIEMBRE"}, _xlpm.mesNum), _xlpm.colIni, MATCH(_xlpm.mesTxt, Minimos!$1:$1, 0), _xlpm.fila, MATCH($A7, Minimos!$A:$A, 0), _xlpm.anio, INDEX(Minimos!$A:$ZZ, _xlpm.fila, _xlpm.colIni+1), _xlpm.dia, INDEX(Minimos!$A:$ZZ, _xlpm.fila, _xlpm.colIni+2), IF(OR(_xlpm.anio="",_xlpm.dia=""), "", DATE(_xlpm.anio, _xlpm.mesNum, _xlpm.dia)) ), "")} -> 28704 | AW7: =IF(OR(AT7="",AU7=""),"NA",IFERROR(AT7-AU7,"NA")) -> 6.4
A8: 14015080 | B8: Aeropuerto Rafael Nuñez | C8: Grupo Observación y Monitoreo | D8: -75.516 | E8: 10.447 | F8: 2 | G8: 13 | H8: 13001 | I8: Bolívar | J8: Cartagena de Indias | K8: 26.5 | AP8: =COUNTIF(K8:AO8,">0") -> 1 | AQ8: =IF(AP8>14,AVERAGE(K8:AO8),"") | AR8: =IFERROR(VLOOKUP(A8,Climatologia!A:U,9+$E$2,FALSE),"") -> 25.862303 | AS8: =IF(OR(AQ8="",AR8=""),"",IFERROR(AQ8-AR8,"")) | AT8: =IF(COUNT(K8:AO8)=0,"",MIN(K8:AO8)) -> 26.5 | AU8: {=IFERROR( _xlfn.LET( _xlpm.mesTxt, INDEX({"ENERO","FEBRERO","MARZO","ABRIL","MAYO","JUNIO","JULIO","AGOSTO","SEPTIEMBRE","OCTUBRE","NOVIEMBRE","DICIEMBRE"}, E$2), _xlpm.colIni, MATCH(_xlpm.mesTxt, Minimos!$1:$1, 0), _xlpm.fila, MATCH($A8, Minimos!$A:$A, 0), _xlpm.val, INDEX(Minimos!$A:$ZZ, _xlpm.fila, _xlpm.colIni), IF(_xlpm.val="", "", _xlpm.val) ), "")} -> 20.2 | AV8: {=IFERROR( _xlfn.LET( _xlpm.mesNum, E$2, _xlpm.mesTxt, INDEX({"ENERO","FEBRERO","MARZO","ABRIL","MAYO","JUNIO","JULIO","AGOSTO","SEPTIEMBRE","OCTUBRE","NOVIEMBRE","DICIEMBRE"}, _xlpm.mesNum), _xlpm.colIni, MATCH(_xlpm.mesTxt, Minimos!$1:$1, 0), _xlpm.fila, MATCH($A8, Minimos!$A:$A, 0), _xlpm.anio, INDEX(Minimos!$A:$ZZ, _xlpm.fila, _xlpm.colIni+1), _xlpm.dia, INDEX(Minimos!$A:$ZZ, _xlpm.fila, _xlpm.colIni+2), IF(OR(_xlpm.anio="",_xlpm.dia=""), "", DATE(_xlpm.anio, _xlpm.mesNum, _xlpm.dia)) ), "")} -> 29807 | AW8: =IF(OR(AT8="",AU8=""),"NA",IFERROR(AT8-AU8,"NA")) -> 6.3
A9: 29045190 | B9: Aeropuerto Ernesto Cortissoz - AUT | C9: Grupo Observación y Monitoreo | D9: -74.78 | E9: 10.918 | F9: 14 | G9: 8 | H9: 8758 | I9: Atlántico | J9: Soledad | K9: 25.8 | AP9: =COUNTIF(K9:AO9,">0") -> 1 | AQ9: =IF(AP9>14,AVERAGE(K9:AO9),"") | AR9: =IFERROR(VLOOKUP(A9,Climatologia!A:U,9+$E$2,FALSE),"") -> 24.752959 | AS9: =IF(OR(AQ9="",AR9=""),"",IFERROR(AQ9-AR9,"")) | AT9: =IF(COUNT(K9:AO9)=0,"",MIN(K9:AO9)) -> 25.8 | AU9: {=IFERROR( _xlfn.LET( _xlpm.mesTxt, INDEX({"ENERO","FEBRERO","MARZO","ABRIL","MAYO","JUNIO","JULIO","AGOSTO","SEPTIEMBRE","OCTUBRE","NOVIEMBRE","DICIEMBRE"}, E$2), _xlpm.colIni, MATCH(_xlpm.mesTxt, Minimos!$1:$1, 0), _xlpm.fila, MATCH($A9, Minimos!$A:$A, 0), _xlpm.val, INDEX(Minimos!$A:$ZZ, _xlpm.fila, _xlpm.colIni), IF(_xlpm.val="", "", _xlpm.val) ), "")} -> 20.4 | AV9: {=IFERROR( _xlfn.LET( _xlpm.mesNum, E$2, _xlpm.mesTxt, INDEX({"ENERO","FEBRERO","MARZO","ABRIL","MAYO","JUNIO","JULIO","AGOSTO","SEPTIEMBRE","OCTUBRE","NOVIEMBRE","DICIEMBRE"}, _xlpm.mesNum), _xlpm.colIni, MATCH(_xlpm.mesTxt, Minimos!$1:$1, 0), _xlpm.fila, MATCH($A9, Minimos!$A:$A, 0), _xlpm.anio, INDEX(Minimos!$A:$ZZ, _xlpm.fila, _xlpm.colIni+1), _xlpm.dia, INDEX(Minimos!$A:$ZZ, _xlpm.fila, _xlpm.colIni+2), IF(OR(_xlpm.anio="",_xlpm.dia=""), "", DATE(_xlpm.anio, _xlpm.mesNum, _xlpm.dia)) ), "")} -> 35652 | AW9: =IF(OR(AT9="",AU9=""),"NA",IFERROR(AT9-AU9,"NA")) -> 5.4
A10: 15065180 | B10: Aeropuerto Almirante Padilla | C10: Grupo Observación y Monitoreo | D10: -72.918 | E10: 11.53 | F10: 4 | G10: 44 | H10: 44001 | I10: La Guajira | J10: Riohacha | K10: 28.3 | AP10: =COUNTIF(K10:AO10,">0") -> 1 | AQ10: =IF(AP10>14,AVERAGE(K10:AO10),"") | AR10: =IFERROR(VLOOKUP(A10,Climatologia!A:U,9+$E$2,FALSE),"") -> 25.518421 | AS10: =IF(OR(AQ10="",AR10=""),"",IFERROR(AQ10-AR10,"")) | AT10: =IF(COUNT(K10:AO10)=0,"",MIN(K10:AO10)) -> 28.3 | AU10: {=IFERROR( _xlfn.LET( _xlpm.mesTxt, INDEX({"ENERO","FEBRERO","MARZO","ABRIL","MAYO","JUNIO","JULIO","AGOSTO","SEPTIEMBRE","OCTUBRE","NOVIEMBRE","DICIEMBRE"}, E$2), _xlpm.colIni, MATCH(_xlpm.mesTxt, Minimos!$1:$1, 0), _xlpm.fila, MATCH($A10, Minimos!$A:$A, 0), _xlpm.val, INDEX(Minimos!$A:$ZZ, _xlpm.fila, _xlpm.colIni), IF(_xlpm.val="", "", _xlpm.val) ), "")} -> 21.4 | AV10: {=IFERROR( _xlfn.LET( _xlpm.mesNum, E$2, _xlpm.mesTxt, INDEX({"ENERO","FEBRERO","MARZO","ABRIL","MAYO","JUNIO","JULIO","AGOSTO","SEPTIEMBRE","OCTUBRE","NOVIEMBRE","DICIEMBRE"}, _xlpm.mesNum), _xlpm.colIni, MATCH(_xlpm.mesTxt, Minimos!$1:$1, 0), _xlpm.fila, MATCH($A10, Minimos!$A:$A, 0), _xlpm.anio, INDEX(Minimos!$A:$ZZ, _xlpm.fila, _xlpm.colIni+1), _xlpm.dia, INDEX(Minimos!$A:$ZZ, _xlpm.fila, _xlpm.colIni+2), IF(OR(_xlpm.anio="",_xlpm.dia=""), "", DATE(_xlpm.anio, _xlpm.mesNum, _xlpm.dia)) ), "")} -> 31648 | AW10: =IF(OR(AT10="",AU10=""),"NA",IFERROR(AT10-AU10,"NA")) -> 6.9
A11: 28025502 | B11: Aeropuerto Alfonso López | C11: Grupo Observación y Monitoreo | D11: -73.248 | E11: 10.436 | F11: 138 | G11: 20 | H11: 20001 | I11: Cesar | J11: Valledupar | K11: 26.9 | AP11: =COUNTIF(K11:AO11,">0") -> 1 | AQ11: =IF(AP11>14,AVERAGE(K11:AO11),"") | AR11: =IFERROR(VLOOKUP(A11,Climatologia!A:U,9+$E$2,FALSE),"") -> 24.333982 | AS11: =IF(OR(AQ11="",AR11=""),"",IFERROR(AQ11-AR11,"")) | AT11: =IF(COUNT(K11:AO11)=0,"",MIN(K11:AO11)) -> 26.9 | AU11: {=IFERROR( _xlfn.LET( _xlpm.mesTxt, INDEX({"ENERO","FEBRERO","MARZO","ABRIL","MAYO","JUNIO","JULIO","AGOSTO","SEPTIEMBRE","OCTUBRE","NOVIEMBRE","DICIEMBRE"}, E$2), _xlpm.colIni, MATCH(_xlpm.mesTxt, Minimos!$1:$1, 0), _xlpm.fila, MATCH($A11, Minimos!$A:$A, 0), _xlpm.val, INDEX(Minimos!$A:$ZZ, _xlpm.fila, _xlpm.colIni), IF(_xlpm.val="", "", _xlpm.val) ), "")} -> 20 | AV11: {=IFERROR( _xlfn.LET( _xlpm.mesNum, E$2, _xlpm.mesTxt, INDEX({"ENERO","FEBRERO","MARZO","ABRIL","MAYO","JUNIO","JULIO","AGOSTO","SEPTIEMBRE","OCTUBRE","NOVIEMBRE","DICIEMBRE"}, _xlpm.mesNum), _xlpm.colIni, MATCH(_xlpm.mesTxt, Minimos!$1:$1, 0), _xlpm.fila, MATCH($A11, Minimos!$A:$A, 0), _xlpm.anio, INDEX(Minimos!$A:$ZZ, _xlpm.fila, _xlpm.colIni+1), _xlpm.dia, INDEX(Minimos!$A:$ZZ, _xlpm.fila, _xlpm.colIni+2), IF(OR(_xlpm.anio="",_xlpm.dia=""), "", DATE(_xlpm.anio, _xlpm.mesNum, _xlpm.dia)) ), "")} -> 29088 | AW11: =IF(OR(AT11="",AU11=""),"NA",IFERROR(AT11-AU11,"NA")) -> 6.9
A12: 13035501 | B12: Aeropuerto Los Garzones | C12: Grupo Observación y Monitoreo | D12: -75.825 | E12: 8.826 | F12: 20 | G12: 23 | H12: 23001 | I12: Córdoba | J12: Montería | K12: 26.3 | AP12: =COUNTIF(K12:AO12,">0") -> 1 | AQ12: =IF(AP12>14,AVERAGE(K12:AO12),"") | AR12: =IFERROR(VLOOKUP(A12,Climatologia!A:U,9+$E$2,FALSE),"") -> 23.252867 | AS12: =IF(OR(AQ12="",AR12=""),"",IFERROR(AQ12-AR12,"")) | AT12: =IF(COUNT(K12:AO12)=0,"",MIN(K12:AO12)) -> 26.3 | AU12: {=IFERROR( _xlfn.LET( _xlpm.mesTxt, INDEX({"ENERO","FEBRERO","MARZO","ABRIL","MAYO","JUNIO","JULIO","AGOSTO","SEPTIEMBRE","OCTUBRE","NOVIEMBRE","DICIEMBRE"}, E$2), _xlpm.colIni, MATCH(_xlpm.mesTxt, Minimos!$1:$1, 0), _xlpm.fila, MATCH($A12, Minimos!$A:$A, 0), _xlpm.val, INDEX(Minimos!$A:$ZZ, _xlpm.fila, _xlpm.colIni), IF(_xlpm.val="", "", _xlpm.val) ), "")} -> 19.8 | AV12: {=IFERROR( _xlfn.LET( _xlpm.mesNum, E$2, _xlpm.mesTxt, INDEX({"ENERO","FEBRERO","MARZO","ABRIL","MAYO","JUNIO","JULIO","AGOSTO","SEPTIEMBRE","OCTUBRE","NOVIEMBRE","DICIEMBRE"}, _xlpm.mesNum), _xlpm.colIni, MATCH(_xlpm.mesTxt, Minimos!$1:$1, 0), _xlpm.fila, MATCH($A12, Minimos!$A:$A, 0), _xlpm.anio, INDEX(Minimos!$A:$ZZ, _xlpm.fila, _xlpm.colIni+1), _xlpm.dia, INDEX(Minimos!$A:$ZZ, _xlpm.fila, _xlpm.colIni+2), IF(OR(_xlpm.anio="",_xlpm.dia=""), "", DATE(_xlpm.anio, _xlpm.mesNum, _xlpm.dia)) ), "")} -> 36751 | AW12: =IF(OR(AT12="",AU12=""),"NA",IFERROR(AT12-AU12,"NA")) -> 6.5
A13: 23155030 | B13: Aeropuerto Yariguies | C13: Grupo Observación y Monitoreo | D13: -73.809 | E13: 7.026 | F13: 126 | G13: 68 | H13: 68081 | I13: Santander | J13: Barrancabermeja | K13: 26 | AP13: =COUNTIF(K13:AO13,">0") -> 1 | AQ13: =IF(AP13>14,AVERAGE(K13:AO13),"") | AR13: =IFERROR(VLOOKUP(A13,Climatologia!A:U,9+$E$2,FALSE),"") -> 23.256381 | AS13: =IF(OR(AQ13="",AR13=""),"",IFERROR(AQ13-AR13,"")) | AT13: =IF(COUNT(K13:AO13)=0,"",MIN(K13:AO13)) -> 26 | AU13: {=IFERROR( _xlfn.LET( _xlpm.mesTxt, INDEX({"ENERO","FEBRERO","MARZO","ABRIL","MAYO","JUNIO","JULIO","AGOSTO","SEPTIEMBRE","OCTUBRE","NOVIEMBRE","DICIEMBRE"}, E$2), _xlpm.colIni, MATCH(_xlpm.mesTxt, Minimos!$1:$1, 0), _xlpm.fila, MATCH($A13, Minimos!$A:$A, 0), _xlpm.val, INDEX(Minimos!$A:$ZZ, _xlpm.fila, _xlpm.colIni), IF(_xlpm.val="", "", _xlpm.val) ), "")} -> 19.6 | AV13: {=IFERROR( _xlfn.LET( _xlpm.mesNum, E$2, _xlpm.mesTxt, INDEX({"ENERO","FEBRERO","MARZO","ABRIL","MAYO","JUNIO","JULIO","AGOSTO","SEPTIEMBRE","OCTUBRE","NOVIEMBRE","DICIEMBRE"}, _xlpm.mesNum), _xlpm.colIni, MATCH(_xlpm.mesTxt, Minimos!$1:$1, 0), _xlpm.fila, MATCH($A13, Minimos!$A:$A, 0), _xlpm.anio, INDEX(Minimos!$A:$ZZ, _xlpm.fila, _xlpm.colIni+1), _xlpm.dia, INDEX(Minimos!$A:$ZZ, _xlpm.fila, _xlpm.colIni+2), IF(OR(_xlpm.anio="",_xlpm.dia=""), "", DATE(_xlpm.anio, _xlpm.mesNum, _xlpm.dia)) ), "")} -> 30529 | AW13: =IF(OR(AT13="",AU13=""),"NA",IFERROR(AT13-AU13,"NA")) -> 6.4
A14: 23195502 | B14: Aeropuerto Palonegro | C14: Grupo Observación y Monitoreo | D14: -73.185 | E14: 7.121 | F14: 1189 | G14: 68 | H14: 68406 | I14: Santander | J14: Lebrija | K14: 20.6 | AP14: =COUNTIF(K14:AO14,">0") -> 1 | AQ14: =IF(AP14>14,AVERAGE(K14:AO14),"") | AR14: =IFERROR(VLOOKUP(A14,Climatologia!A:U,9+$E$2,FALSE),"") -> 18.604611 | AS14: =IF(OR(AQ14="",AR14=""),"",IFERROR(AQ14-AR14,"")) | AT14: =IF(COUNT(K14:AO14)=0,"",MIN(K14:AO14)) -> 20.6 | AU14: {=IFERROR( _xlfn.LET( _xlpm.mesTxt, INDEX({"ENERO","FEBRERO","MARZO","ABRIL","MAYO","JUNIO","JULIO","AGOSTO","SEPTIEMBRE","OCTUBRE","NOVIEMBRE","DICIEMBRE"}, E$2), _xlpm.colIni, MATCH(_xlpm.mesTxt, Minimos!$1:$1, 0), _xlpm.fila, MATCH($A14, Minimos!$A:$A, 0), _xlpm.val, INDEX(Minimos!$A:$ZZ, _xlpm.fila, _xlpm.colIni), IF(_xlpm.val="", "", _xlpm.val) ), "")} -> 16.4 | AV14: {=IFERROR( _xlfn.LET( _xlpm.mesNum, E$2, _xlpm.mesTxt, INDEX({"ENERO","FEBRERO","MARZO","ABRIL","MAYO","JUNIO","JULIO","AGOSTO","SEPTIEMBRE","OCTUBRE","NOVIEMBRE","DICIEMBRE"}, _xlpm.mesNum), _xlpm.colIni, MATCH(_xlpm.mesTxt, Minimos!$1:$1, 0), _xlpm.fila, MATCH($A14, Minimos!$A:$A, 0), _xlpm.anio, INDEX(Minimos!$A:$ZZ, _xlpm.fila, _xlpm.colIni+1), _xlpm.dia, INDEX(Minimos!$A:$ZZ, _xlpm.fila, _xlpm.colIni+2), IF(OR(_xlpm.anio="",_xlpm.dia=""), "", DATE(_xlpm.anio, _xlpm.mesNum, _xlpm.dia)) ), "")} -> 29098 | AW14: =IF(OR(AT14="",AU14=""),"NA",IFERROR(AT14-AU14,"NA")) -> 4.2
A15: 16015010 | B15: Aeropuerto Camilo Daza | C15: Grupo Observación y Monitoreo | D15: -72.509 | E15: 7.93 | F15: 250 | G15: 54 | H15: 54001 | I15: Norte de Santander | J15: Cúcuta | K15: 27.3 | AP15: =COUNTIF(K15:AO15,">0") -> 1 | AQ15: =IF(AP15>14,AVERAGE(K15:AO15),"") | AR15: =IFERROR(VLOOKUP(A15,Climatologia!A:U,9+$E$2,FALSE),"") -> 23.891303 | AS15: =IF(OR(AQ15="",AR15=""),"",IFERROR(AQ15-AR15,"")) | AT15: =IF(COUNT(K15:AO15)=0,"",MIN(K15:AO15)) -> 27.3 | AU15: {=IFERROR( _xlfn.LET( _xlpm.mesTxt, INDEX({"ENERO","FEBRERO","MARZO","ABRIL","MAYO","JUNIO","JULIO","AGOSTO","SEPTIEMBRE","OCTUBRE","NOVIEMBRE","DICIEMBRE"}, E$2), _xlpm.colIni, MATCH(_xlpm.mesTxt, Minimos!$1:$1, 0), _xlpm.fila, MATCH($A15, Minimos!$A:$A, 0), _xlpm.val, INDEX(Minimos!$A:$ZZ, _xlpm.fila, _xlpm.colIni), IF(_xlpm.val="", "", _xlpm.val) ), "")} -> 18.8 | AV15: {=IFERROR( _xlfn.LET( _xlpm.mesNum, E$2, _xlpm.mesTxt, INDEX({"ENERO","FEBRERO","MARZO","ABRIL","MAYO","JUNIO","JULIO","AGOSTO","SEPTIEMBRE","OCTUBRE","NOVIEMBRE","DICIEMBRE"}, _xlpm.mesNum), _xlpm.colIni, MATCH(_xlpm.mesTxt, Minimos!$1:$1, 0), _xlpm.fila, MATCH($A15, Minimos!$A:$A, 0), _xlpm.anio, INDEX(Minimos!$A:$ZZ, _xlpm.fila, _xlpm.colIni+1), _xlpm.dia, INDEX(Minimos!$A:$ZZ, _xlpm.fila, _xlpm.colIni+2), IF(OR(_xlpm.anio="",_xlpm.dia=""), "", DATE(_xlpm.anio, _xlpm.mesNum, _xlpm.dia)) ), "")} -> 31646 | AW15: =IF(OR(AT15="",AU15=""),"NA",IFERROR(AT15-AU15,"NA")) -> 8.5
A16: 12015070 | B16: Aeropuerto Los Cedros | C16: Grupo Observación y Monitoreo | D16: -76.718 | E16: 7.816 | F16: 41 | G16: 5 | H16: 5147 | I16: Antioquia | J16: Carepa | K16: 25.9 | AP16: =COUNTIF(K16:AO16,">0") -> 1 | AQ16: =IF(AP16>14,AVERAGE(K16:AO16),"") | AR16: =IFERROR(VLOOKUP(A16,Climatologia!A:U,9+$E$2,FALSE),"") -> 23.404405 | AS16: =IF(OR(AQ16="",AR16=""),"",IFERROR(AQ16-AR16,"")) | AT16: =IF(COUNT(K16:AO16)=0,"",MIN(K16:AO16)) -> 25.9 | AU16: {=IFERROR( _xlfn.LET( _xlpm.mesTxt, INDEX({"ENERO","FEBRERO","MARZO","ABRIL","MAYO","JUNIO","JULIO","AGOSTO","SEPTIEMBRE","OCTUBRE","NOVIEMBRE","DICIEMBRE"}, E$2), _xlpm.colIni, MATCH(_xlpm.mesTxt, Minimos!$1:$1, 0), _xlpm.fila, MATCH($A16, Minimos!$A:$A, 0), _xlpm.val, INDEX(Minimos!$A:$ZZ, _xlpm.fila, _xlpm.colIni), IF(_xlpm.val="", "", _xlpm.val) ), "")} -> 19 | AV16: {=IFERROR( _xlfn.LET( _xlpm.mesNum, E$2, _xlpm.mesTxt, INDEX({"ENERO","FEBRERO","MARZO","ABRIL","MAYO","JUNIO","JULIO","AGOSTO","SEPTIEMBRE","OCTUBRE","NOVIEMBRE","DICIEMBRE"}, _xlpm.mesNum), _xlpm.colIni, MATCH(_xlpm.mesTxt, Minimos!$1:$1, 0), _xlpm.fila, MATCH($A16, Minimos!$A:$A, 0), _xlpm.anio, INDEX(Minimos!$A:$ZZ, _xlpm.fila, _xlpm.colIni+1), _xlpm.dia, INDEX(Minimos!$A:$ZZ, _xlpm.fila, _xlpm.colIni+2), IF(OR(_xlpm.anio="",_xlpm.dia=""), "", DATE(_xlpm.anio, _xlpm.mesNum, _xlpm.dia)) ), "")} -> 36763 | AW16: =IF(OR(AT16="",AU16=""),"NA",IFERROR(AT16-AU16,"NA")) -> 6.9
... A32: 11075020 | B32: Urrao | C32: Area Operativa 01 - Antioquia-Chocó | D32: -76.143306 | E32: 6.2983056 | F32: 1833 | G32: 5 | H32: 5847 | I32: Antioquia | J32: Urrao | K32: 14.2 | AP32: =COUNTIF(K32:AO32,">0") -> 1 | AQ32: =IF(AP32>14,AVERAGE(K32:AO32),"") | AR32: =IFERROR(VLOOKUP(A32,Climatologia!A:U,9+$E$2,FALSE),"") -> 13.384747 | AS32: =IF(OR(AQ32="",AR32=""),"",IFERROR(AQ32-AR32,"")) | AT32: =IF(COUNT(K32:AO32)=0,"",MIN(K32:AO32)) -> 14.2 | AU32: {=IFERROR( _xlfn.LET( _xlpm.mesTxt, INDEX({"ENERO","FEBRERO","MARZO","ABRIL","MAYO","JUNIO","JULIO","AGOSTO","SEPTIEMBRE","OCTUBRE","NOVIEMBRE","DICIEMBRE"}, E$2), _xlpm.colIni, MATCH(_xlpm.mesTxt, Minimos!$1:$1, 0), _xlpm.fila, MATCH($A32, Minimos!$A:$A, 0), _xlpm.val, INDEX(Minimos!$A:$ZZ, _xlpm.fila, _xlpm.colIni), IF(_xlpm.val="", "", _xlpm.val) ), "")} -> 9.2 | AV32: {=IFERROR( _xlfn.LET( _xlpm.mesNum, E$2, _xlpm.mesTxt, INDEX({"ENERO","FEBRERO","MARZO","ABRIL","MAYO","JUNIO","JULIO","AGOSTO","SEPTIEMBRE","OCTUBRE","NOVIEMBRE","DICIEMBRE"}, _xlpm.mesNum), _xlpm.colIni, MATCH(_xlpm.mesTxt, Minimos!$1:$1, 0), _xlpm.fila, MATCH($A32, Minimos!$A:$A, 0), _xlpm.anio, INDEX(Minimos!$A:$ZZ, _xlpm.fila, _xlpm.colIni+1), _xlpm.dia, INDEX(Minimos!$A:$ZZ, _xlpm.fila, _xlpm.colIni+2), IF(OR(_xlpm.anio="",_xlpm.dia=""), "", DATE(_xlpm.anio, _xlpm.mesNum, _xlpm.dia)) ), "")} -> 45898 | AW32: =IF(OR(AT32="",AU32=""),"NA",IFERROR(AT32-AU32,"NA")) -> 5
A33: 12015020 | B33: Uniban | C33: Area Operativa 01 - Antioquia-Chocó | D33: -76.651333 | E33: 7.8259167 | F33: 43 | G33: 5 | H33: 5045 | I33: Antioquia | J33: Apartadó | AP33: =COUNTIF(K33:AO33,">0") -> 0 | AQ33: =IF(AP33>14,AVERAGE(K33:AO33),"") | AR33: =IFERROR(VLOOKUP(A33,Climatologia!A:U,9+$E$2,FALSE),"") -> 23.414845 | AS33: =IF(OR(AQ33="",AR33=""),"",IFERROR(AQ33-AR33,"")) | AT33: =IF(COUNT(K33:AO33)=0,"",MIN(K33:AO33)) | AU33: {=IFERROR( _xlfn.LET( _xlpm.mesTxt, INDEX({"ENERO","FEBRERO","MARZO","ABRIL","MAYO","JUNIO","JULIO","AGOSTO","SEPTIEMBRE","OCTUBRE","NOVIEMBRE","DICIEMBRE"}, E$2), _xlpm.colIni, MATCH(_xlpm.mesTxt, Minimos!$1:$1, 0), _xlpm.fila, MATCH($A33, Minimos!$A:$A, 0), _xlpm.val, INDEX(Minimos!$A:$ZZ, _xlpm.fila, _xlpm.colIni), IF(_xlpm.val="", "", _xlpm.val) ), "")} -> 19 | AV33: {=IFERROR( _xlfn.LET( _xlpm.mesNum, E$2, _xlpm.mesTxt, INDEX({"ENERO","FEBRERO","MARZO","ABRIL","MAYO","JUNIO","JULIO","AGOSTO","SEPTIEMBRE","OCTUBRE","NOVIEMBRE","DICIEMBRE"}, _xlpm.mesNum), _xlpm.colIni, MATCH(_xlpm.mesTxt, Minimos!$1:$1, 0), _xlpm.fila, MATCH($A33, Minimos!$A:$A, 0), _xlpm.anio, INDEX(Minimos!$A:$ZZ, _xlpm.fila, _xlpm.colIni+1), _xlpm.dia, INDEX(Minimos!$A:$ZZ, _xlpm.fila, _xlpm.colIni+2), IF(OR(_xlpm.anio="",_xlpm.dia=""), "", DATE(_xlpm.anio, _xlpm.mesNum, _xlpm.dia)) ), "")} -> 35299 | AW33: =IF(OR(AT33="",AU33=""),"NA",IFERROR(AT33-AU33,"NA")) -> NA
A34: 23085030 | B34: Alejandria | C34: Area Operativa 01 - Antioquia-Chocó | D34: -75.143389 | E34: 6.37625 | F34: 1712 | G34: 5 | H34: 5021 | I34: Antioquia | J34: Alejandría | K34: 15.2 | AP34: =COUNTIF(K34:AO34,">0") -> 1 | AQ34: =IF(AP34>14,AVERAGE(K34:AO34),"") | AR34: =IFERROR(VLOOKUP(A34,Climatologia!A:U,9+$E$2,FALSE),"") -> 14.785404 | AS34: =IF(OR(AQ34="",AR34=""),"",IFERROR(AQ34-AR34,"")) | AT34: =IF(COUNT(K34:AO34)=0,"",MIN(K34:AO34)) -> 15.2 | AU34: {=IFERROR( _xlfn.LET( _xlpm.mesTxt, INDEX({"ENERO","FEBRERO","MARZO","ABRIL","MAYO","JUNIO","JULIO","AGOSTO","SEPTIEMBRE","OCTUBRE","NOVIEMBRE","DICIEMBRE"}, E$2), _xlpm.colIni, MATCH(_xlpm.mesTxt, Minimos!$1:$1, 0), _xlpm.fila, MATCH($A34, Minimos!$A:$A, 0), _xlpm.val, INDEX(Minimos!$A:$ZZ, _xlpm.fila, _xlpm.colIni), IF(_xlpm.val="", "", _xlpm.val) ), "")} -> 10 | AV34: {=IFERROR( _xlfn.LET( _xlpm.mesNum, E$2, _xlpm.mesTxt, INDEX({"ENERO","FEBRERO","MARZO","ABRIL","MAYO","JUNIO","JULIO","AGOSTO","SEPTIEMBRE","OCTUBRE","NOVIEMBRE","DICIEMBRE"}, _xlpm.mesNum), _xlpm.colIni, MATCH(_xlpm.mesTxt, Minimos!$1:$1, 0), _xlpm.fila, MATCH($A34, Minimos!$A:$A, 0), _xlpm.anio, INDEX(Minimos!$A:$ZZ, _xlpm.fila, _xlpm.colIni+1), _xlpm.dia, INDEX(Minimos!$A:$ZZ, _xlpm.fila, _xlpm.colIni+2), IF(OR(_xlpm.anio="",_xlpm.dia=""), "", DATE(_xlpm.anio, _xlpm.mesNum, _xlpm.dia)) ), "")} -> 37835 | AW34: =IF(OR(AT34="",AU34=""),"NA",IFERROR(AT34-AU34,"NA")) -> 5.2
A35: 23085110 | B35: El Penol | C35: Area Operativa 01 - Antioquia-Chocó | D35: -75.241389 | E35: 6.2138889 | F35: 2022 | G35: 5 | H35: 5541 | I35: Antioquia | J35: Peñol | K35: 15 | AP35: =COUNTIF(K35:AO35,">0") -> 1 | AQ35: =IF(AP35>14,AVERAGE(K35:AO35),"") | AR35: =IFERROR(VLOOKUP(A35,Climatologia!A:U,9+$E$2,FALSE),"") -> 13.292897 | AS35: =IF(OR(AQ35="",AR35=""),"",IFERROR(AQ35-AR35,"")) | AT35: =IF(COUNT(K35:AO35)=0,"",MIN(K35:AO35)) -> 15 | AU35: {=IFERROR( _xlfn.LET( _xlpm.mesTxt, INDEX({"ENERO","FEBRERO","MARZO","ABRIL","MAYO","JUNIO","JULIO","AGOSTO","SEPTIEMBRE","OCTUBRE","NOVIEMBRE","DICIEMBRE"}, E$2), _xlpm.colIni, MATCH(_xlpm.mesTxt, Minimos!$1:$1, 0), _xlpm.fila, MATCH($A35, Minimos!$A:$A, 0), _xlpm.val, INDEX(Minimos!$A:$ZZ, _xlpm.fila, _xlpm.colIni), IF(_xlpm.val="", "", _xlpm.val) ), "")} -> 9 | AV35: {=IFERROR( _xlfn.LET( _xlpm.mesNum, E$2, _xlpm.mesTxt, INDEX({"ENERO","FEBRERO","MARZO","ABRIL","MAYO","JUNIO","JULIO","AGOSTO","SEPTIEMBRE","OCTUBRE","NOVIEMBRE","DICIEMBRE"}, _xlpm.mesNum), _xlpm.colIni, MATCH(_xlpm.mesTxt, Minimos!$1:$1, 0), _xlpm.fila, MATCH($A35, Minimos!$A:$A, 0), _xlpm.anio, INDEX(Minimos!$A:$ZZ, _xlpm.fila, _xlpm.colIni+1), _xlpm.dia, INDEX(Minimos!$A:$ZZ, _xlpm.fila, _xlpm.colIni+2), IF(OR(_xlpm.anio="",_xlpm.dia=""), "", DATE(_xlpm.anio, _xlpm.mesNum, _xlpm.dia)) ), "")} -> 28723 | AW35: =IF(OR(AT35="",AU35=""),"NA",IFERROR(AT35-AU35,"NA")) -> 6
A36: 26175040 | B36: Hacienda Tunez | C36: Area Operativa 01 - Antioquia-Chocó | D36: -75.650972 | E36: 5.80025 | F36: 604 | G36: 5 | H36: 5282 | I36: Antioquia | J36: Fredonia | K36: 17.8 | AP36: =COUNTIF(K36:AO36,">0") -> 1 | AQ36: =IF(AP36>14,AVERAGE(K36:AO36),"") | AR36: =IFERROR(VLOOKUP(A36,Climatologia!A:U,9+$E$2,FALSE),"") -> 19.435919 | AS36: =IF(OR(AQ36="",AR36=""),"",IFERROR(AQ36-AR36,"")) | AT36: =IF(COUNT(K36:AO36)=0,"",MIN(K36:AO36)) -> 17.8 | AU36: {=IFERROR( _xlfn.LET( _xlpm.mesTxt, INDEX({"ENERO","FEBRERO","MARZO","ABRIL","MAYO","JUNIO","JULIO","AGOSTO","SEPTIEMBRE","OCTUBRE","NOVIEMBRE","DICIEMBRE"}, E$2), _xlpm.colIni, MATCH(_xlpm.mesTxt, Minimos!$1:$1, 0), _xlpm.fila, MATCH($A36, Minimos!$A:$A, 0), _xlpm.val, INDEX(Minimos!$A:$ZZ, _xlpm.fila, _xlpm.colIni), IF(_xlpm.val="", "", _xlpm.val) ), "")} -> 15 | AV36: {=IFERROR( _xlfn.LET( _xlpm.mesNum, E$2, _xlpm.mesTxt, INDEX({"ENERO","FEBRERO","MARZO","ABRIL","MAYO","JUNIO","JULIO","AGOSTO","SEPTIEMBRE","OCTUBRE","NOVIEMBRE","DICIEMBRE"}, _xlpm.mesNum), _xlpm.colIni, MATCH(_xlpm.mesTxt, Minimos!$1:$1, 0), _xlpm.fila, MATCH($A36, Minimos!$A:$A, 0), _xlpm.anio, INDEX(Minimos!$A:$ZZ, _xlpm.fila, _xlpm.colIni+1), _xlpm.dia, INDEX(Minimos!$A:$ZZ, _xlpm.fila, _xlpm.colIni+2), IF(OR(_xlpm.anio="",_xlpm.dia=""), "", DATE(_xlpm.anio, _xlpm.mesNum, _xlpm.dia)) ), "")} -> 28720 | AW36: =IF(OR(AT36="",AU36=""),"NA",IFERROR(AT36-AU36,"NA")) -> 2.8
A37: 26185020 | B37: Mesopotamia | C37: Area Operativa 01 - Antioquia-Chocó | D37: -75.318639 | E37: 5.8863611 | F37: 2408 | G37: 5 | H37: 5400 | I37: Antioquia | J37: La Unión | K37: 8.8 | AP37: =COUNTIF(K37:AO37,">0") -> 1 | AQ37: =IF(AP37>14,AVERAGE(K37:AO37),"") | AR37: =IFERROR(VLOOKUP(A37,Climatologia!A:U,9+$E$2,FALSE),"") -> 9.4603029 | AS37: =IF(OR(AQ37="",AR37=""),"",IFERROR(AQ37-AR37,"")) | AT37: =IF(COUNT(K37:AO37)=0,"",MIN(K37:AO37)) -> 8.8 | AU37: {=IFERROR( _xlfn.LET( _xlpm.mesTxt, INDEX({"ENERO","FEBRERO","MARZO","ABRIL","MAYO","JUNIO","JULIO","AGOSTO","SEPTIEMBRE","OCTUBRE","NOVIEMBRE","DICIEMBRE"}, E$2), _xlpm.colIni, MATCH(_xlpm.mesTxt, Minimos!$1:$1, 0), _xlpm.fila, MATCH($A37, Minimos!$A:$A, 0), _xlpm.val, INDEX(Minimos!$A:$ZZ, _xlpm.fila, _xlpm.colIni), IF(_xlpm.val="", "", _xlpm.val) ), "")} | AV37: {=IFERROR( _xlfn.LET( _xlpm.mesNum, E$2, _xlpm.mesTxt, INDEX({"ENERO","FEBRERO","MARZO","ABRIL","MAYO","JUNIO","JULIO","AGOSTO","SEPTIEMBRE","OCTUBRE","NOVIEMBRE","DICIEMBRE"}, _xlpm.mesNum), _xlpm.colIni, MATCH(_xlpm.mesTxt, Minimos!$1:$1, 0), _xlpm.fila, MATCH($A37, Minimos!$A:$A, 0), _xlpm.anio, INDEX(Minimos!$A:$ZZ, _xlpm.fila, _xlpm.colIni+1), _xlpm.dia, INDEX(Minimos!$A:$ZZ, _xlpm.fila, _xlpm.colIni+2), IF(OR(_xlpm.anio="",_xlpm.dia=""), "", DATE(_xlpm.anio, _xlpm.mesNum, _xlpm.dia)) ), "")} | AW37: =IF(OR(AT37="",AU37=""),"NA",IFERROR(AT37-AU37,"NA")) -> NA
A38: 26205080 | B38: La Aldea | C38: Area Operativa 01 - Antioquia-Chocó | D38: -75.700944 | E38: 6.3410556 | F38: 1737 | G38: 5 | H38: 5001 | I38: Antioquia | J38: Medellín | K38: 17.2 | AP38: =COUNTIF(K38:AO38,">0") -> 1 | AQ38: =IF(AP38>14,AVERAGE(K38:AO38),"") | AR38: =IFERROR(VLOOKUP(A38,Climatologia!A:U,9+$E$2,FALSE),"") | AS38: =IF(OR(AQ38="",AR38=""),"",IFERROR(AQ38-AR38,"")) | AT38: =IF(COUNT(K38:AO38)=0,"",MIN(K38:AO38)) -> 17.2 | AU38: {=IFERROR( _xlfn.LET( _xlpm.mesTxt, INDEX({"ENERO","FEBRERO","MARZO","ABRIL","MAYO","JUNIO","JULIO","AGOSTO","SEPTIEMBRE","OCTUBRE","NOVIEMBRE","DICIEMBRE"}, E$2), _xlpm.colIni, MATCH(_xlpm.mesTxt, Minimos!$1:$1, 0), _xlpm.fila, MATCH($A38, Minimos!$A:$A, 0), _xlpm.val, INDEX(Minimos!$A:$ZZ, _xlpm.fila, _xlpm.colIni), IF(_xlpm.val="", "", _xlpm.val) ), "")} -> 14 | AV38: {=IFERROR( _xlfn.LET( _xlpm.mesNum, E$2, _xlpm.mesTxt, INDEX({"ENERO","FEBRERO","MARZO","ABRIL","MAYO","JUNIO","JULIO","AGOSTO","SEPTIEMBRE","OCTUBRE","NOVIEMBRE","DICIEMBRE"}, _xlpm.mesNum), _xlpm.colIni, MATCH(_xlpm.mesTxt, Minimos!$1:$1, 0), _xlpm.fila, MATCH($A38, Minimos!$A:$A, 0), _xlpm.anio, INDEX(Minimos!$A:$ZZ, _xlpm.fila, _xlpm.colIni+1), _xlpm.dia, INDEX(Minimos!$A:$ZZ, _xlpm.fila, _xlpm.colIni+2), IF(OR(_xlpm.anio="",_xlpm.dia=""), "", DATE(_xlpm.anio, _xlpm.mesNum, _xlpm.dia)) ), "")} -> 44423 | AW38: =IF(OR(AT38="",AU38=""),"NA",IFERROR(AT38-AU38,"NA")) -> 3.2
A39: 27015090 | B39: Tulio Ospina | C39: Area Operativa 01 - Antioquia-Chocó | D39: -75.55325 | E39: 6.3196944 | F39: 1453 | G39: 5 | H39: 5088 | I39: Antioquia | J39: Bello | K39: 19 | AP39: =COUNTIF(K39:AO39,">0") -> 1 | AQ39: =IF(AP39>14,AVERAGE(K39:AO39),"") | AR39: =IFERROR(VLOOKUP(A39,Climatologia!A:U,9+$E$2,FALSE),"") -> 17.32409 | AS39: =IF(OR(AQ39="",AR39=""),"",IFERROR(AQ39-AR39,"")) | AT39: =IF(COUNT(K39:AO39)=0,"",MIN(K39:AO39)) -> 19 | AU39: {=IFERROR( _xlfn.LET( _xlpm.mesTxt, INDEX({"ENERO","FEBRERO","MARZO","ABRIL","MAYO","JUNIO","JULIO","AGOSTO","SEPTIEMBRE","OCTUBRE","NOVIEMBRE","DICIEMBRE"}, E$2), _xlpm.colIni, MATCH(_xlpm.mesTxt, Minimos!$1:$1, 0), _xlpm.fila, MATCH($A39, Minimos!$A:$A, 0), _xlpm.val, INDEX(Minimos!$A:$ZZ, _xlpm.fila, _xlpm.colIni), IF(_xlpm.val="", "", _xlpm.val) ), "")} -> 12.2 | AV39: {=IFERROR( _xlfn.LET( _xlpm.mesNum, E$2, _xlpm.mesTxt, INDEX({"ENERO","FEBRERO","MARZO","ABRIL","MAYO","JUNIO","JULIO","AGOSTO","SEPTIEMBRE","OCTUBRE","NOVIEMBRE","DICIEMBRE"}, _xlpm.mesNum), _xlpm.colIni, MATCH(_xlpm.mesTxt, Minimos!$1:$1, 0), _xlpm.fila, MATCH($A39, Minimos!$A:$A, 0), _xlpm.anio, INDEX(Minimos!$A:$ZZ, _xlpm.fila, _xlpm.colIni+1), _xlpm.dia, INDEX(Minimos!$A:$ZZ, _xlpm.fila, _xlpm.colIni+2), IF(OR(_xlpm.anio="",_xlpm.dia=""), "", DATE(_xlpm.anio, _xlpm.mesNum, _xlpm.dia)) ), "")} -> 29457 | AW39: =IF(OR(AT39="",AU39=""),"NA",IFERROR(AT39-AU39,"NA")) -> 6.8
A40: 27015260 | B40: La Salada | C40: Area Operativa 01 - Antioquia-Chocó | D40: -75.624667 | E40: 6.0483611 | F40: 1923 | G40: 5 | H40: 5129 | I40: Antioquia | J40: Caldas | K40: 14.2 | AP40: =COUNTIF(K40:AO40,">0") -> 1 | AQ40: =IF(AP40>14,AVERAGE(K40:AO40),"") | AR40: =IFERROR(VLOOKUP(A40,Climatologia!A:U,9+$E$2,FALSE),"") -> 13.024959 | AS40: =IF(OR(AQ40="",AR40=""),"",IFERROR(AQ40-AR40,"")) | AT40: =IF(COUNT(K40:AO40)=0,"",MIN(K40:AO40)) -> 14.2 | AU40: {=IFERROR( _xlfn.LET( _xlpm.mesTxt, INDEX({"ENERO","FEBRERO","MARZO","ABRIL","MAYO","JUNIO","JULIO","AGOSTO","SEPTIEMBRE","OCTUBRE","NOVIEMBRE","DICIEMBRE"}, E$2), _xlpm.colIni, MATCH(_xlpm.mesTxt, Minimos!$1:$1, 0), _xlpm.fila, MATCH($A40, Minimos!$A:$A, 0), _xlpm.val, INDEX(Minimos!$A:$ZZ, _xlpm.fila, _xlpm.colIni), IF(_xlpm.val="", "", _xlpm.val) ), "")} -> 9.4 | AV40: {=IFERROR( _xlfn.LET( _xlpm.mesNum, E$2, _xlpm.mesTxt, INDEX({"ENERO","FEBRERO","MARZO","ABRIL","MAYO","JUNIO","JULIO","AGOSTO","SEPTIEMBRE","OCTUBRE","NOVIEMBRE","DICIEMBRE"}, _xlpm.mesNum), _xlpm.colIni, MATCH(_xlpm.mesTxt, Minimos!$1:$1, 0), _xlpm.fila, MATCH($A40, Minimos!$A:$A, 0), _xlpm.anio, INDEX(Minimos!$A:$ZZ, _xlpm.fila, _xlpm.colIni+1), _xlpm.dia, INDEX(Minimos!$A:$ZZ, _xlpm.fila, _xlpm.colIni+2), IF(OR(_xlpm.anio="",_xlpm.dia=""), "", DATE(_xlpm.anio, _xlpm.mesNum, _xlpm.dia)) ), "")} -> 37470 | AW40: =IF(OR(AT40="",AU40=""),"NA",IFERROR(AT40-AU40,"NA")) -> 4.8
A41: 12045010 | B41: Arboletes | C41: Area Operativa 02 - Atlántico-Bolivar-Sucre | D41: -76.431944 | E41: 8.8469444 | F41: 4 | G41: 5 | H41: 5051 | I41: Antioquia | J41: Arboletes | K41: 24 | AP41: =COUNTIF(K41:AO41,">0") -> 1 | AQ41: =IF(AP41>14,AVERAGE(K41:AO41),"") | AR41: =IFERROR(VLOOKUP(A41,Climatologia!A:U,9+$E$2,FALSE),"") | AS41: =IF(OR(AQ41="",AR41=""),"",IFERROR(AQ41-AR41,"")) | AT41: =IF(COUNT(K41:AO41)=0,"",MIN(K41:AO41)) -> 24 | AU41: {=IFERROR( _xlfn.LET( _xlpm.mesTxt, INDEX({"ENERO","FEBRERO","MARZO","ABRIL","MAYO","JUNIO","JULIO","AGOSTO","SEPTIEMBRE","OCTUBRE","NOVIEMBRE","DICIEMBRE"}, E$2), _xlpm.colIni, MATCH(_xlpm.mesTxt, Minimos!$1:$1, 0), _xlpm.fila, MATCH($A41, Minimos!$A:$A, 0), _xlpm.val, INDEX(Minimos!$A:$ZZ, _xlpm.fila, _xlpm.colIni), IF(_xlpm.val="", "", _xlpm.val) ), "")} -> 17.2 | AV41: {=IFERROR( _xlfn.LET( _xlpm.mesNum, E$2, _xlpm.mesTxt, INDEX({"ENERO","FEBRERO","MARZO","ABRIL","MAYO","JUNIO","JULIO","AGOSTO","SEPTIEMBRE","OCTUBRE","NOVIEMBRE","DICIEMBRE"}, _xlpm.mesNum), _xlpm.colIni, MATCH(_xlpm.mesTxt, Minimos!$1:$1, 0), _xlpm.fila, MATCH($A41, Minimos!$A:$A, 0), _xlpm.anio, INDEX(Minimos!$A:$ZZ, _xlpm.fila, _xlpm.colIni+1), _xlpm.dia, INDEX(Minimos!$A:$ZZ, _xlpm.fila, _xlpm.colIni+2), IF(OR(_xlpm.anio="",_xlpm.dia=""), "", DATE(_xlpm.anio, _xlpm.mesNum, _xlpm.dia)) ), "")} -> 33461 | AW41: =IF(OR(AT41="",AU41=""),"NA",IFERROR(AT41-AU41,"NA")) -> 6.8
A42: 12045020 | B42: Cristo Rey - Aut | C42: Area Operativa 02 - Atlántico-Bolivar-Sucre | D42: -76.224444 | E42: 9.0711111 | F42: 15 | G42: 23 | H42: 23574 | I42: Córdoba | J42: Puerto Escondido | K42: 27 | AP42: =COUNTIF(K42:AO42,">0") -> 1 | AQ42: =IF(AP42>14,AVERAGE(K42:AO42),"") | AR42: =IFERROR(VLOOKUP(A42,Climatologia!A:U,9+$E$2,FALSE),"") -> 24.242888 | AS42: =IF(OR(AQ42="",AR42=""),"",IFERROR(AQ42-AR42,"")) | AT42: =IF(COUNT(K42:AO42)=0,"",MIN(K42:AO42)) -> 27 | AU42: {=IFERROR( _xlfn.LET( _xlpm.mesTxt, INDEX({"ENERO","FEBRERO","MARZO","ABRIL","MAYO","JUNIO","JULIO","AGOSTO","SEPTIEMBRE","OCTUBRE","NOVIEMBRE","DICIEMBRE"}, E$2), _xlpm.colIni, MATCH(_xlpm.mesTxt, Minimos!$1:$1, 0), _xlpm.fila, MATCH($A42, Minimos!$A:$A, 0), _xlpm.val, INDEX(Minimos!$A:$ZZ, _xlpm.fila, _xlpm.colIni), IF(_xlpm.val="", "", _xlpm.val) ), "")} | AV42: {=IFERROR( _xlfn.LET( _xlpm.mesNum, E$2, _xlpm.mesTxt, INDEX({"ENERO","FEBRERO","MARZO","ABRIL","MAYO","JUNIO","JULIO","AGOSTO","SEPTIEMBRE","OCTUBRE","NOVIEMBRE","DICIEMBRE"}, _xlpm.mesNum), _xlpm.colIni, MATCH(_xlpm.mesTxt, Minimos!$1:$1, 0), _xlpm.fila, MATCH($A42, Minimos!$A:$A, 0), _xlpm.anio, INDEX(Minimos!$A:$ZZ, _xlpm.fila, _xlpm.colIni+1), _xlpm.dia, INDEX(Minimos!$A:$ZZ, _xlpm.fila, _xlpm.colIni+2), IF(OR(_xlpm.anio="",_xlpm.dia=""), "", DATE(_xlpm.anio, _xlpm.mesNum, _xlpm.dia)) ), "")} | AW42: =IF(OR(AT42="",AU42=""),"NA",IFERROR(AT42-AU42,"NA")) -> NA
A43: 13015040 | B43: Represa Urra | C43: Area Operativa 02 - Atlántico-Bolivar-Sucre | D43: -76.203056 | E43: 8.0141667 | F43: 300 | G43: 23 | H43: 23807 | I43: Córdoba | J43: Tierralta | K43: 23.5 | AP43: =COUNTIF(K43:AO43,">0") -> 1 | AQ43: =IF(AP43>14,AVERAGE(K43:AO43),"") | AR43: =IFERROR(VLOOKUP(A43,Climatologia!A:U,9+$E$2,FALSE),"") -> 23.780114 | AS43: =IF(OR(AQ43="",AR43=""),"",IFERROR(AQ43-AR43,"")) | AT43: =IF(COUNT(K43:AO43)=0,"",MIN(K43:AO43)) -> 23.5 | AU43: {=IFERROR( _xlfn.LET( _xlpm.mesTxt, INDEX({"ENERO","FEBRERO","MARZO","ABRIL","MAYO","JUNIO","JULIO","AGOSTO","SEPTIEMBRE","OCTUBRE","NOVIEMBRE","DICIEMBRE"}, E$2), _xlpm.colIni, MATCH(_xlpm.mesTxt, Minimos!$1:$1, 0), _xlpm.fila, MATCH($A43, Minimos!$A:$A, 0), _xlpm.val, INDEX(Minimos!$A:$ZZ, _xlpm.fila, _xlpm.colIni), IF(_xlpm.val="", "", _xlpm.val) ), "")} -> 19.4 | AV43: {=IFERROR( _xlfn.LET( _xlpm.mesNum, E$2, _xlpm.mesTxt, INDEX({"ENERO","FEBRERO","MARZO","ABRIL","MAYO","JUNIO","JULIO","AGOSTO","SEPTIEMBRE","OCTUBRE","NOVIEMBRE","DICIEMBRE"}, _xlpm.mesNum), _xlpm.colIni, MATCH(_xlpm.mesTxt, Minimos!$1:$1, 0), _xlpm.fila, MATCH($A43, Minimos!$A:$A, 0), _xlpm.anio, INDEX(Minimos!$A:$ZZ, _xlpm.fila, _xlpm.colIni+1), _xlpm.dia, INDEX(Minimos!$A:$ZZ, _xlpm.fila, _xlpm.colIni+2), IF(OR(_xlpm.anio="",_xlpm.dia=""), "", DATE(_xlpm.anio, _xlpm.mesNum, _xlpm.dia)) ), "")} -> 39298 | AW43: =IF(OR(AT43="",AU43=""),"NA",IFERROR(AT43-AU43,"NA")) -> 4.1
A44: 13075010 | B44: Chima | C44: Area Operativa 02 - Atlántico-Bolivar-Sucre | D44: -75.622083 | E44: 9.15075 | F44: 20 | G44: 5 | H44: 5172 | I44: Antioquia | J44: Chigorodó | K44: 25.6 | AP44: =COUNTIF(K44:AO44,">0") -> 1 | AQ44: =IF(AP44>14,AVERAGE(K44:AO44),"") | AR44: =IFERROR(VLOOKUP(A44,Climatologia!A:U,9+$E$2,FALSE),"") -> 23.055415 | AS44: =IF(OR(AQ44="",AR44=""),"",IFERROR(AQ44-AR44,"")) | AT44: =IF(COUNT(K44:AO44)=0,"",MIN(K44:AO44)) -> 25.6 | AU44: {=IFERROR( _xlfn.LET( _xlpm.mesTxt, INDEX({"ENERO","FEBRERO","MARZO","ABRIL","MAYO","JUNIO","JULIO","AGOSTO","SEPTIEMBRE","OCTUBRE","NOVIEMBRE","DICIEMBRE"}, E$2), _xlpm.colIni, MATCH(_xlpm.mesTxt, Minimos!$1:$1, 0), _xlpm.fila, MATCH($A44, Minimos!$A:$A, 0), _xlpm.val, INDEX(Minimos!$A:$ZZ, _xlpm.fila, _xlpm.colIni), IF(_xlpm.val="", "", _xlpm.val) ), "")} -> 16.2 | AV44: {=IFERROR( _xlfn.LET( _xlpm.mesNum, E$2, _xlpm.mesTxt, INDEX({"ENERO","FEBRERO","MARZO","ABRIL","MAYO","JUNIO","JULIO","AGOSTO","SEPTIEMBRE","OCTUBRE","NOVIEMBRE","DICIEMBRE"}, _xlpm.mesNum), _xlpm.colIni, MATCH(_xlpm.mesTxt, Minimos!$1:$1, 0), _xlpm.fila, MATCH($A44, Minimos!$A:$A, 0), _xlpm.anio, INDEX(Minimos!$A:$ZZ, _xlpm.fila, _xlpm.colIni+1), _xlpm.dia, INDEX(Minimos!$A:$ZZ, _xlpm.fila, _xlpm.colIni+2), IF(OR(_xlpm.anio="",_xlpm.dia=""), "", DATE(_xlpm.anio, _xlpm.mesNum, _xlpm.dia)) ), "")} -> 33095 | AW44: =IF(OR(AT44="",AU44=""),"NA",IFERROR(AT44-AU44,"NA")) -> 9.4
A45: 13075020 | B45: El Salado | C45: Area Operativa 02 - Atlántico-Bolivar-Sucre | D45: -75.582222 | E45: 8.9138889 | F45: 40 | G45: 23 | H45: 23189 | I45: Córdoba | J45: Ciénaga De Oro | AP45: =COUNTIF(K45:AO45,">0") -> 0 | AQ45: =IF(AP45>14,AVERAGE(K45:AO45),"") | AR45: =IFERROR(VLOOKUP(A45,Climatologia!A:U,9+$E$2,FALSE),"") -> 23.345876 | AS45: =IF(OR(AQ45="",AR45=""),"",IFERROR(AQ45-AR45,"")) | AT45: =IF(COUNT(K45:AO45)=0,"",MIN(K45:AO45)) | AU45: {=IFERROR( _xlfn.LET( _xlpm.mesTxt, INDEX({"ENERO","FEBRERO","MARZO","ABRIL","MAYO","JUNIO","JULIO","AGOSTO","SEPTIEMBRE","OCTUBRE","NOVIEMBRE","DICIEMBRE"}, E$2), _xlpm.colIni, MATCH(_xlpm.mesTxt, Minimos!$1:$1, 0), _xlpm.fila, MATCH($A45, Minimos!$A:$A, 0), _xlpm.val, INDEX(Minimos!$A:$ZZ, _xlpm.fila, _xlpm.colIni), IF(_xlpm.val="", "", _xlpm.val) ), "")} -> 15.3 | AV45: {=IFERROR( _xlfn.LET( _xlpm.mesNum, E$2, _xlpm.mesTxt, INDEX({"ENERO","FEBRERO","MARZO","ABRIL","MAYO","JUNIO","JULIO","AGOSTO","SEPTIEMBRE","OCTUBRE","NOVIEMBRE","DICIEMBRE"}, _xlpm.mesNum), _xlpm.colIni, MATCH(_xlpm.mesTxt, Minimos!$1:$1, 0), _xlpm.fila, MATCH($A45, Minimos!$A:$A, 0), _xlpm.anio, INDEX(Minimos!$A:$ZZ, _xlpm.fila, _xlpm.colIni+1), _xlpm.dia, INDEX(Minimos!$A:$ZZ, _xlpm.fila, _xlpm.colIni+2), IF(OR(_xlpm.anio="",_xlpm.dia=""), "", DATE(_xlpm.anio, _xlpm.mesNum, _xlpm.dia)) ), "")} -> 34913 | AW45: =IF(OR(AT45="",AU45=""),"NA",IFERROR(AT45-AU45,"NA")) -> NA
A46: 13085030 | B46: San Bernardo Del Viento | C46: Area Operativa 02 - Atlántico-Bolivar-Sucre | D46: -75.95 | E46: 9.37 | F46: 22 | G46: 23 | H46: 23675 | I46: Córdoba | J46: San Bernardo Del Viento | AP46: =COUNTIF(K46:AO46,">0") -> 0 | AQ46: =IF(AP46>14,AVERAGE(K46:AO46),"") | AR46: =IFERROR(VLOOKUP(A46,Climatologia!A:U,9+$E$2,FALSE),"") -> 22.153487 | AS46: =IF(OR(AQ46="",AR46=""),"",IFERROR(AQ46-AR46,"")) | AT46: =IF(COUNT(K46:AO46)=0,"",MIN(K46:AO46)) | AU46: {=IFERROR( _xlfn.LET( _xlpm.mesTxt, INDEX({"ENERO","FEBRERO","MARZO","ABRIL","MAYO","JUNIO","JULIO","AGOSTO","SEPTIEMBRE","OCTUBRE","NOVIEMBRE","DICIEMBRE"}, E$2), _xlpm.colIni, MATCH(_xlpm.mesTxt, Minimos!$1:$1, 0), _xlpm.fila, MATCH($A46, Minimos!$A:$A, 0), _xlpm.val, INDEX(Minimos!$A:$ZZ, _xlpm.fila, _xlpm.colIni), IF(_xlpm.val="", "", _xlpm.val) ), "")} -> 17 | AV46: {=IFERROR( _xlfn.LET( _xlpm.mesNum, E$2, _xlpm.mesTxt, INDEX({"ENERO","FEBRERO","MARZO","ABRIL","MAYO","JUNIO","JULIO","AGOSTO","SEPTIEMBRE","OCTUBRE","NOVIEMBRE","DICIEMBRE"}, _xlpm.mesNum), _xlpm.colIni, MATCH(_xlpm.mesTxt, Minimos!$1:$1, 0), _xlpm.fila, MATCH($A46, Minimos!$A:$A, 0), _xlpm.anio, INDEX(Minimos!$A:$ZZ, _xlpm.fila, _xlpm.colIni+1), _xlpm.dia, INDEX(Minimos!$A:$ZZ, _xlpm.fila, _xlpm.colIni+2), IF(OR(_xlpm.anio="",_xlpm.dia=""), "", DATE(_xlpm.anio, _xlpm.mesNum, _xlpm.dia)) ), "")} -> 32733 | AW46: =IF(OR(AT46="",AU46=""),"NA",IFERROR(AT46-AU46,"NA")) -> NA
A47: 25025080 | B47: Aeropuerto Rafael Barvo | C47: Area Operativa 02 - Atlántico-Bolivar-Sucre | D47: -75.283056 | E47: 9.3338889 | F47: 166 | G47: 70 | H47: 70215 | I47: Sucre | J47: Corozal | K47: 26.4 | AP47: =COUNTIF(K47:AO47,">0") -> 1 | AQ47: =IF(AP47>14,AVERAGE(K47:AO47),"") | AR47: =IFERROR(VLOOKUP(A47,Climatologia!A:U,9+$E$2,FALSE),"") -> 22.672444 | AS47: =IF(OR(AQ47="",AR47=""),"",IFERROR(AQ47-AR47,"")) | AT47: =IF(COUNT(K47:AO47)=0,"",MIN(K47:AO47)) -> 26.4 | AU47: {=IFERROR( _xlfn.LET( _xlpm.mesTxt, INDEX({"ENERO","FEBRERO","MARZO","ABRIL","MAYO","JUNIO","JULIO","AGOSTO","SEPTIEMBRE","OCTUBRE","NOVIEMBRE","DICIEMBRE"}, E$2), _xlpm.colIni, MATCH(_xlpm.mesTxt, Minimos!$1:$1, 0), _xlpm.fila, MATCH($A47, Minimos!$A:$A, 0), _xlpm.val, INDEX(Minimos!$A:$ZZ, _xlpm.fila, _xlpm.colIni), IF(_xlpm.val="", "", _xlpm.val) ), "")} -> 18.4 | AV47: {=IFERROR( _xlfn.LET( _xlpm.mesNum, E$2, _xlpm.mesTxt, INDEX({"ENERO","FEBRERO","MARZO","ABRIL","MAYO","JUNIO","JULIO","AGOSTO","SEPTIEMBRE","OCTUBRE","NOVIEMBRE","DICIEMBRE"}, _xlpm.mesNum), _xlpm.colIni, MATCH(_xlpm.mesTxt, Minimos!$1:$1, 0), _xlpm.fila, MATCH($A47, Minimos!$A:$A, 0), _xlpm.anio, INDEX(Minimos!$A:$ZZ, _xlpm.fila, _xlpm.colIni+1), _xlpm.dia, INDEX(Minimos!$A:$ZZ, _xlpm.fila, _xlpm.colIni+2), IF(OR(_xlpm.anio="",_xlpm.dia=""), "", DATE(_xlpm.anio, _xlpm.mesNum, _xlpm.dia)) ), "")} -> 37846 | AW47: =IF(OR(AT47="",AU47=""),"NA",IFERROR(AT47-AU47,"NA")) -> 8
A48: 25025160 | B48: Cuba Hacienda | C48: Area Operativa 02 - Atlántico-Bolivar-Sucre | D48: -75.402778 | E48: 8.0038889 | F48: 50 | G48: 23 | H48: 23466 | I48: Córdoba | J48: Montelíbano | AP48: =COUNTIF(K48:AO48,">0") -> 0 | AQ48: =IF(AP48>14,AVERAGE(K48:AO48),"") | AR48: =IFERROR(VLOOKUP(A48,Climatologia!A:U,9+$E$2,FALSE),"") -> 22.897474 | AS48: =IF(OR(AQ48="",AR48=""),"",IFERROR(AQ48-AR48,"")) | AT48: =IF(COUNT(K48:AO48)=0,"",MIN(K48:AO48)) | AU48: {=IFERROR( _xlfn.LET( _xlpm.mesTxt, INDEX({"ENERO","FEBRERO","MARZO","ABRIL","MAYO","JUNIO","JULIO","AGOSTO","SEPTIEMBRE","OCTUBRE","NOVIEMBRE","DICIEMBRE"}, E$2), _xlpm.colIni, MATCH(_xlpm.mesTxt, Minimos!$1:$1, 0), _xlpm.fila, MATCH($A48, Minimos!$A:$A, 0), _xlpm.val, INDEX(Minimos!$A:$ZZ, _xlpm.fila, _xlpm.colIni), IF(_xlpm.val="", "", _xlpm.val) ), "")} -> 18.1 | AV48: {=IFERROR( _xlfn.LET( _xlpm.mesNum, E$2, _xlpm.mesTxt, INDEX({"ENERO","FEBRERO","MARZO","ABRIL","MAYO","JUNIO","JULIO","AGOSTO","SEPTIEMBRE","OCTUBRE","NOVIEMBRE","DICIEMBRE"}, _xlpm.mesNum), _xlpm.colIni, MATCH(_xlpm.mesTxt, Minimos!$1:$1, 0), _xlpm.fila, MATCH($A48, Minimos!$A:$A, 0), _xlpm.anio, INDEX(Minimos!$A:$ZZ, _xlpm.fila, _xlpm.colIni+1), _xlpm.dia, INDEX(Minimos!$A:$ZZ, _xlpm.fila, _xlpm.colIni+2), IF(OR(_xlpm.anio="",_xlpm.dia=""), "", DATE(_xlpm.anio, _xlpm.mesNum, _xlpm.dia)) ), "")} -> 28711 | AW48: =IF(OR(AT48="",AU48=""),"NA",IFERROR(AT48-AU48,"NA")) -> NA
A49: 25025190 | B49: Planeta Rica - Aut | C49: Area Operativa 02 - Atlántico-Bolivar-Sucre | D49: -75.583722 | E49: 8.3993333 | F49: 90 | G49: 23 | H49: 23555 | I49: Córdoba | J49: Planeta Rica | AP49: =COUNTIF(K49:AO49,">0") -> 0 | AQ49: =IF(AP49>14,AVERAGE(K49:AO49),"") | AR49: =IFERROR(VLOOKUP(A49,Climatologia!A:U,9+$E$2,FALSE),"") -> 23.226657 | AS49: =IF(OR(AQ49="",AR49=""),"",IFERROR(AQ49-AR49,"")) | AT49: =IF(COUNT(K49:AO49)=0,"",MIN(K49:AO49)) | AU49: {=IFERROR( _xlfn.LET( _xlpm.mesTxt, INDEX({"ENERO","FEBRERO","MARZO","ABRIL","MAYO","JUNIO","JULIO","AGOSTO","SEPTIEMBRE","OCTUBRE","NOVIEMBRE","DICIEMBRE"}, E$2), _xlpm.colIni, MATCH(_xlpm.mesTxt, Minimos!$1:$1, 0), _xlpm.fila, MATCH($A49, Minimos!$A:$A, 0), _xlpm.val, INDEX(Minimos!$A:$ZZ, _xlpm.fila, _xlpm.colIni), IF(_xlpm.val="", "", _xlpm.val) ), "")} -> 19.2 | AV49: {=IFERROR( _xlfn.LET( _xlpm.mesNum, E$2, _xlpm.mesTxt, INDEX({"ENERO","FEBRERO","MARZO","ABRIL","MAYO","JUNIO","JULIO","AGOSTO","SEPTIEMBRE","OCTUBRE","NOVIEMBRE","DICIEMBRE"}, _xlpm.mesNum), _xlpm.colIni, MATCH(_xlpm.mesTxt, Minimos!$1:$1, 0), _xlpm.fila, MATCH($A49, Minimos!$A:$A, 0), _xlpm.anio, INDEX(Minimos!$A:$ZZ, _xlpm.fila, _xlpm.colIni+1), _xlpm.dia, INDEX(Minimos!$A:$ZZ, _xlpm.fila, _xlpm.colIni+2), IF(OR(_xlpm.anio="",_xlpm.dia=""), "", DATE(_xlpm.anio, _xlpm.mesNum, _xlpm.dia)) ), "")} -> 33091 | AW49: =IF(OR(AT49="",AU49=""),"NA",IFERROR(AT49-AU49,"NA")) -> NA
A50: 25025210 | B50: Pinillos | C50: Area Operativa 02 - Atlántico-Bolivar-Sucre | D50: -74.457778 | E50: 8.9113889 | F50: 10 | G50: 13 | H50: 13549 | I50: Bolívar | J50: Pinillos | AP50: =COUNTIF(K50:AO50,">0") -> 0 | AQ50: =IF(AP50>14,AVERAGE(K50:AO50),"") | AR50: =IFERROR(VLOOKUP(A50,Climatologia!A:U,9+$E$2,FALSE),"") | AS50: =IF(OR(AQ50="",AR50=""),"",IFERROR(AQ50-AR50,"")) | AT50: =IF(COUNT(K50:AO50)=0,"",MIN(K50:AO50)) | AU50: {=IFERROR( _xlfn.LET( _xlpm.mesTxt, INDEX({"ENERO","FEBRERO","MARZO","ABRIL","MAYO","JUNIO","JULIO","AGOSTO","SEPTIEMBRE","OCTUBRE","NOVIEMBRE","DICIEMBRE"}, E$2), _xlpm.colIni, MATCH(_xlpm.mesTxt, Minimos!$1:$1, 0), _xlpm.fila, MATCH($A50, Minimos!$A:$A, 0), _xlpm.val, INDEX(Minimos!$A:$ZZ, _xlpm.fila, _xlpm.colIni), IF(_xlpm.val="", "", _xlpm.val) ), "")} -> 19.2 | AV50: {=IFERROR( _xlfn.LET( _xlpm.mesNum, E$2, _xlpm.mesTxt, INDEX({"ENERO","FEBRERO","MARZO","ABRIL","MAYO","JUNIO","JULIO","AGOSTO","SEPTIEMBRE","OCTUBRE","NOVIEMBRE","DICIEMBRE"}, _xlpm.mesNum), _xlpm.colIni, MATCH(_xlpm.mesTxt, Minimos!$1:$1, 0), _xlpm.fila, MATCH($A50, Minimos!$A:$A, 0), _xlpm.anio, INDEX(Minimos!$A:$ZZ, _xlpm.fila, _xlpm.colIni+1), _xlpm.dia, INDEX(Minimos!$A:$ZZ, _xlpm.fila, _xlpm.colIni+2), IF(OR(_xlpm.anio="",_xlpm.dia=""), "", DATE(_xlpm.anio, _xlpm.mesNum, _xlpm.dia)) ), "")} -> 43338 | AW50: =IF(OR(AT50="",AU50=""),"NA",IFERROR(AT50-AU50,"NA")) -> NA
A51: 25025270 | B51: Unisucre Aut | C51: Area Operativa 02 - Atlántico-Bolivar-Sucre | D51: -75.3875 | E51: 9.3163889 | F51: 160 | G51: 70 | H51: 70670 | I51: Sucre | J51: Sampués | K51: 26.6 | AP51: =COUNTIF(K51:AO51,">0") -> 1 | AQ51: =IF(AP51>14,AVERAGE(K51:AO51),"") | AR51: =IFERROR(VLOOKUP(A51,Climatologia!A:U,9+$E$2,FALSE),"") -> 23.046735 | AS51: =IF(OR(AQ51="",AR51=""),"",IFERROR(AQ51-AR51,"")) | AT51: =IF(COUNT(K51:AO51)=0,"",MIN(K51:AO51)) -> 26.6 | AU51: {=IFERROR( _xlfn.LET( _xlpm.mesTxt, INDEX({"ENERO","FEBRERO","MARZO","ABRIL","MAYO","JUNIO","JULIO","AGOSTO","SEPTIEMBRE","OCTUBRE","NOVIEMBRE","DICIEMBRE"}, E$2), _xlpm.colIni, MATCH(_xlpm.mesTxt, Minimos!$1:$1, 0), _xlpm.fila, MATCH($A51, Minimos!$A:$A, 0), _xlpm.val, INDEX(Minimos!$A:$ZZ, _xlpm.fila, _xlpm.colIni), IF(_xlpm.val="", "", _xlpm.val) ), "")} -> 17 | AV51: {=IFERROR( _xlfn.LET( _xlpm.mesNum, E$2, _xlpm.mesTxt, INDEX({"ENERO","FEBRERO","MARZO","ABRIL","MAYO","JUNIO","JULIO","AGOSTO","SEPTIEMBRE","OCTUBRE","NOVIEMBRE","DICIEMBRE"}, _xlpm.mesNum), _xlpm.colIni, MATCH(_xlpm.mesTxt, Minimos!$1:$1, 0), _xlpm.fila, MATCH($A51, Minimos!$A:$A, 0), _xlpm.anio, INDEX(Minimos!$A:$ZZ, _xlpm.fila, _xlpm.colIni+1), _xlpm.dia, INDEX(Minimos!$A:$ZZ, _xlpm.fila, _xlpm.colIni+2), IF(OR(_xlpm.anio="",_xlpm.dia=""), "", DATE(_xlpm.anio, _xlpm.mesNum, _xlpm.dia)) ), "")} -> 36021 | AW51: =IF(OR(AT51="",AU51=""),"NA",IFERROR(AT51-AU51,"NA")) -> 9.6
A52: 25025380 | B52: San Benito - Aut | C52: Area Operativa 02 - Atlántico-Bolivar-Sucre | D52: -75.044722 | E52: 9.1638889 | F52: 20 | G52: 70 | H52: 70678 | I52: Sucre | J52: San Benito Abad | K52: 27 | AP52: =COUNTIF(K52:AO52,">0") -> 1 | AQ52: =IF(AP52>14,AVERAGE(K52:AO52),"") | AR52: =IFERROR(VLOOKUP(A52,Climatologia!A:U,9+$E$2,FALSE),"") -> 22.420117 | AS52: =IF(OR(AQ52="",AR52=""),"",IFERROR(AQ52-AR52,"")) | AT52: =IF(COUNT(K52:AO52)=0,"",MIN(K52:AO52)) -> 27 | AU52: {=IFERROR( _xlfn.LET( _xlpm.mesTxt, INDEX({"ENERO","FEBRERO","MARZO","ABRIL","MAYO","JUNIO","JULIO","AGOSTO","SEPTIEMBRE","OCTUBRE","NOVIEMBRE","DICIEMBRE"}, E$2), _xlpm.colIni, MATCH(_xlpm.mesTxt, Minimos!$1:$1, 0), _xlpm.fila, MATCH($A52, Minimos!$A:$A, 0), _xlpm.val, INDEX(Minimos!$A:$ZZ, _xlpm.fila, _xlpm.colIni), IF(_xlpm.val="", "", _xlpm.val) ), "")} -> 18.2 | AV52: {=IFERROR( _xlfn.LET( _xlpm.mesNum, E$2, _xlpm.mesTxt, INDEX({"ENERO","FEBRERO","MARZO","ABRIL","MAYO","JUNIO","JULIO","AGOSTO","SEPTIEMBRE","OCTUBRE","NOVIEMBRE","DICIEMBRE"}, _xlpm.mesNum), _xlpm.colIni, MATCH(_xlpm.mesTxt, Minimos!$1:$1, 0), _xlpm.fila, MATCH($A52, Minimos!$A:$A, 0), _xlpm.anio, INDEX(Minimos!$A:$ZZ, _xlpm.fila, _xlpm.colIni+1), _xlpm.dia, INDEX(Minimos!$A:$ZZ, _xlpm.fila, _xlpm.colIni+2), IF(OR(_xlpm.anio="",_xlpm.dia=""), "", DATE(_xlpm.anio, _xlpm.mesNum, _xlpm.dia)) ), "")} -> 33101 | AW52: =IF(OR(AT52="",AU52=""),"NA",IFERROR(AT52-AU52,"NA")) -> 8.8
A53: 29015000 | B53: El Guamo - Aut | C53: Area Operativa 02 - Atlántico-Bolivar-Sucre | D53: -74.976638 | E53: 10.034607 | F53: 75 | G53: 13 | H53: 13248 | I53: Bolívar | J53: El Guamo | K53: 25.8 | AP53: =COUNTIF(K53:AO53,">0") -> 1 | AQ53: =IF(AP53>14,AVERAGE(K53:AO53),"") | AR53: =IFERROR(VLOOKUP(A53,Climatologia!A:U,9+$E$2,FALSE),"") | AS53: =IF(OR(AQ53="",AR53=""),"",IFERROR(AQ53-AR53,"")) | AT53: =IF(COUNT(K53:AO53)=0,"",MIN(K53:AO53)) -> 25.8 | AU53: {=IFERROR( _xlfn.LET( _xlpm.mesTxt, INDEX({"ENERO","FEBRERO","MARZO","ABRIL","MAYO","JUNIO","JULIO","AGOSTO","SEPTIEMBRE","OCTUBRE","NOVIEMBRE","DICIEMBRE"}, E$2), _xlpm.colIni, MATCH(_xlpm.mesTxt, Minimos!$1:$1, 0), _xlpm.fila, MATCH($A53, Minimos!$A:$A, 0), _xlpm.val, INDEX(Minimos!$A:$ZZ, _xlpm.fila, _xlpm.colIni), IF(_xlpm.val="", "", _xlpm.val) ), "")} -> 17.6 | AV53: {=IFERROR( _xlfn.LET( _xlpm.mesNum, E$2, _xlpm.mesTxt, INDEX({"ENERO","FEBRERO","MARZO","ABRIL","MAYO","JUNIO","JULIO","AGOSTO","SEPTIEMBRE","OCTUBRE","NOVIEMBRE","DICIEMBRE"}, _xlpm.mesNum), _xlpm.colIni, MATCH(_xlpm.mesTxt, Minimos!$1:$1, 0), _xlpm.fila, MATCH($A53, Minimos!$A:$A, 0), _xlpm.anio, INDEX(Minimos!$A:$ZZ, _xlpm.fila, _xlpm.colIni+1), _xlpm.dia, INDEX(Minimos!$A:$ZZ, _xlpm.fila, _xlpm.colIni+2), IF(OR(_xlpm.anio="",_xlpm.dia=""), "", DATE(_xlpm.anio, _xlpm.mesNum, _xlpm.dia)) ), "")} -> 34931 | AW53: =IF(OR(AT53="",AU53=""),"NA",IFERROR(AT53-AU53,"NA")) -> 8.2
A54: 29035000 | B54: Sincerin - Aut | C54: Area Operativa 02 - Atlántico-Bolivar-Sucre | D54: -75.278278 | E54: 10.142583 | F54: 10 | G54: 13 | H54: 13052 | I54: Bolívar | J54: Arjona | K54: 22.2 | AP54: =COUNTIF(K54:AO54,">0") -> 1 | AQ54: =IF(AP54>14,AVERAGE(K54:AO54),"") | AR54: =IFERROR(VLOOKUP(A54,Climatologia!A:U,9+$E$2,FALSE),"") | AS54: =IF(OR(AQ54="",AR54=""),"",IFERROR(AQ54-AR54,"")) | AT54: =IF(COUNT(K54:AO54)=0,"",MIN(K54:AO54)) -> 22.2 | AU54: {=IFERROR( _xlfn.LET( _xlpm.mesTxt, INDEX({"ENERO","FEBRERO","MARZO","ABRIL","MAYO","JUNIO","JULIO","AGOSTO","SEPTIEMBRE","OCTUBRE","NOVIEMBRE","DICIEMBRE"}, E$2), _xlpm.colIni, MATCH(_xlpm.mesTxt, Minimos!$1:$1, 0), _xlpm.fila, MATCH($A54, Minimos!$A:$A, 0), _xlpm.val, INDEX(Minimos!$A:$ZZ, _xlpm.fila, _xlpm.colIni), IF(_xlpm.val="", "", _xlpm.val) ), "")} -> 20 | AV54: {=IFERROR( _xlfn.LET( _xlpm.mesNum, E$2, _xlpm.mesTxt, INDEX({"ENERO","FEBRERO","MARZO","ABRIL","MAYO","JUNIO","JULIO","AGOSTO","SEPTIEMBRE","OCTUBRE","NOVIEMBRE","DICIEMBRE"}, _xlpm.mesNum), _xlpm.colIni, MATCH(_xlpm.mesTxt, Minimos!$1:$1, 0), _xlpm.fila, MATCH($A54, Minimos!$A:$A, 0), _xlpm.anio, INDEX(Minimos!$A:$ZZ, _xlpm.fila, _xlpm.colIni+1), _xlpm.dia, INDEX(Minimos!$A:$ZZ, _xlpm.fila, _xlpm.colIni+2), IF(OR(_xlpm.anio="",_xlpm.dia=""), "", DATE(_xlpm.anio, _xlpm.mesNum, _xlpm.dia)) ), "")} -> 34930 | AW54: =IF(OR(AT54="",AU54=""),"NA",IFERROR(AT54-AU54,"NA")) -> 2.2
A55: 29035030 | B55: Presa Ay Grande | C55: Area Operativa 02 - Atlántico-Bolivar-Sucre | D55: -75.326301 | E55: 9.879634 | F55: 60 | G55: 13 | H55: 13442 | I55: Bolívar | J55: María La Baja | AP55: =COUNTIF(K55:AO55,">0") -> 0 | AQ55: =IF(AP55>14,AVERAGE(K55:AO55),"") | AR55: =IFERROR(VLOOKUP(A55,Climatologia!A:U,9+$E$2,FALSE),"") | AS55: =IF(OR(AQ55="",AR55=""),"",IFERROR(AQ55-AR55,"")) | AT55: =IF(COUNT(K55:AO55)=0,"",MIN(K55:AO55)) | AU55: {=IFERROR( _xlfn.LET( _xlpm.mesTxt, INDEX({"ENERO","FEBRERO","MARZO","ABRIL","MAYO","JUNIO","JULIO","AGOSTO","SEPTIEMBRE","OCTUBRE","NOVIEMBRE","DICIEMBRE"}, E$2), _xlpm.colIni, MATCH(_xlpm.mesTxt, Minimos!$1:$1, 0), _xlpm.fila, MATCH($A55, Minimos!$A:$A, 0), _xlpm.val, INDEX(Minimos!$A:$ZZ, _xlpm.fila, _xlpm.colIni), IF(_xlpm.val="", "", _xlpm.val) ), "")} -> 20 | AV55: {=IFERROR( _xlfn.LET( _xlpm.mesNum, E$2, _xlpm.mesTxt, INDEX({"ENERO","FEBRERO","MARZO","ABRIL","MAYO","JUNIO","JULIO","AGOSTO","SEPTIEMBRE","OCTUBRE","NOVIEMBRE","DICIEMBRE"}, _xlpm.mesNum), _xlpm.colIni, MATCH(_xlpm.mesTxt, Minimos!$1:$1, 0), _xlpm.fila, MATCH($A55, Minimos!$A:$A, 0), _xlpm.anio, INDEX(Minimos!$A:$ZZ, _xlpm.fila, _xlpm.colIni+1), _xlpm.dia, INDEX(Minimos!$A:$ZZ, _xlpm.fila, _xlpm.colIni+2), IF(OR(_xlpm.anio="",_xlpm.dia=""), "", DATE(_xlpm.anio, _xlpm.mesNum, _xlpm.dia)) ), "")} -> 38585 | AW55: =IF(OR(AT55="",AU55=""),"NA",IFERROR(AT55-AU55,"NA")) -> NA
A56: 29035080 | B56: Normal Manati - Aut | C56: Area Operativa 02 - Atlántico-Bolivar-Sucre | D56: -74.954726 | E56: 10.453966 | F56: 10 | G56: 8 | H56: 8436 | I56: Atlántico | J56: Manatí | AP56: =COUNTIF(K56:AO56,">0") -> 0 | AQ56: =IF(AP56>14,AVERAGE(K56:AO56),"") | AR56: =IFERROR(VLOOKUP(A56,Climatologia!A:U,9+$E$2,FALSE),"") -> 24.266259 | AS56: =IF(OR(AQ56="",AR56=""),"",IFERROR(AQ56-AR56,"")) | AT56: =IF(COUNT(K56:AO56)=0,"",MIN(K56:AO56)) | AU56: {=IFERROR( _xlfn.LET( _xlpm.mesTxt, INDEX({"ENERO","FEBRERO","MARZO","ABRIL","MAYO","JUNIO","JULIO","AGOSTO","SEPTIEMBRE","OCTUBRE","NOVIEMBRE","DICIEMBRE"}, E$2), _xlpm.colIni, MATCH(_xlpm.mesTxt, Minimos!$1:$1, 0), _xlpm.fila, MATCH($A56, Minimos!$A:$A, 0), _xlpm.val, INDEX(Minimos!$A:$ZZ, _xlpm.fila, _xlpm.colIni), IF(_xlpm.val="", "", _xlpm.val) ), "")} -> 18.6 | AV56: {=IFERROR( _xlfn.LET( _xlpm.mesNum, E$2, _xlpm.mesTxt, INDEX({"ENERO","FEBRERO","MARZO","ABRIL","MAYO","JUNIO","JULIO","AGOSTO","SEPTIEMBRE","OCTUBRE","NOVIEMBRE","DICIEMBRE"}, _xlpm.mesNum), _xlpm.colIni, MATCH(_xlpm.mesTxt, Minimos!$1:$1, 0), _xlpm.fila, MATCH($A56, Minimos!$A:$A, 0), _xlpm.anio, INDEX(Minimos!$A:$ZZ, _xlpm.fila, _xlpm.colIni+1), _xlpm.dia, INDEX(Minimos!$A:$ZZ, _xlpm.fila, _xlpm.colIni+2), IF(OR(_xlpm.anio="",_xlpm.dia=""), "", DATE(_xlpm.anio, _xlpm.mesNum, _xlpm.dia)) ), "")} -> 29817 | AW56: =IF(OR(AT56="",AU56=""),"NA",IFERROR(AT56-AU56,"NA")) -> NA
A57: 29035110 | B57: San Pablo | C57: Area Operativa 02 - Atlántico-Bolivar-Sucre | D57: -75.258611 | E57: 10.043167 | F57: 20 | G57: 13 | H57: 13442 | I57: Bolívar | J57: María La Baja | K57: 26 | AP57: =COUNTIF(K57:AO57,">0") -> 1 | AQ57: =IF(AP57>14,AVERAGE(K57:AO57),"") | AR57: =IFERROR(VLOOKUP(A57,Climatologia!A:U,9+$E$2,FALSE),"") -> 23.979265 | AS57: =IF(OR(AQ57="",AR57=""),"",IFERROR(AQ57-AR57,"")) | AT57: =IF(COUNT(K57:AO57)=0,"",MIN(K57:AO57)) -> 26 | AU57: {=IFERROR( _xlfn.LET( _xlpm.mesTxt, INDEX({"ENERO","FEBRERO","MARZO","ABRIL","MAYO","JUNIO","JULIO","AGOSTO","SEPTIEMBRE","OCTUBRE","NOVIEMBRE","DICIEMBRE"}, E$2), _xlpm.colIni, MATCH(_xlpm.mesTxt, Minimos!$1:$1, 0), _xlpm.fila, MATCH($A57, Minimos!$A:$A, 0), _xlpm.val, INDEX(Minimos!$A:$ZZ, _xlpm.fila, _xlpm.colIni), IF(_xlpm.val="", "", _xlpm.val) ), "")} -> 17.8 | AV57: {=IFERROR( _xlfn.LET( _xlpm.mesNum, E$2, _xlpm.mesTxt, INDEX({"ENERO","FEBRERO","MARZO","ABRIL","MAYO","JUNIO","JULIO","AGOSTO","SEPTIEMBRE","OCTUBRE","NOVIEMBRE","DICIEMBRE"}, _xlpm.mesNum), _xlpm.colIni, MATCH(_xlpm.mesTxt, Minimos!$1:$1, 0), _xlpm.fila, MATCH($A57, Minimos!$A:$A, 0), _xlpm.anio, INDEX(Minimos!$A:$ZZ, _xlpm.fila, _xlpm.colIni+1), _xlpm.dia, INDEX(Minimos!$A:$ZZ, _xlpm.fila, _xlpm.colIni+2), IF(OR(_xlpm.anio="",_xlpm.dia=""), "", DATE(_xlpm.anio, _xlpm.mesNum, _xlpm.dia)) ), "")} -> 28733 | AW57: =IF(OR(AT57="",AU57=""),"NA",IFERROR(AT57-AU57,"NA")) -> 8.2
...

Sheet Climatologia
A1: INFORMACIÓN GENERAL ESTACIONES | J1: NORMAL CLIMATOLÓGICA ESTÁNDAR DE LA TEMPERATURA MINIMA PARA EL PERIODO 1991-2020 (°C) | W1: Cumplen la directriz No 1203 del 2017 de la OMM
A2: CÓDIGO | B2: CATEGORÍA | C2: NOMBRE | D2: MUNICIPIO | E2: DEPARTAMENTO | F2: AO | G2: ELEVACIÓN (m) | H2: LONGITUD | I2: LATITUD | J2: ENE | K2: FEB | L2: MAR | M2: ABR | N2: MAY | O2: JUN | P2: JUL | Q2: AGO | R2: SEP | S2: OCT | T2: NOV | U2: DIC | V2: ANUAL | W2: Número de meses | X2: % de cumplimiento
A3: 48015050 | B3: SP | C3: Aeropuerto Vásquez Cobo | D3: Leticia | E3: Amazonas | F3: 11 | G3: 84 | H3: -69.940917 | I3: -4.1938611 | J3: 23.177079 | K3: 23.144265 | L3: 23.220972 | M3: 23.19556 | N3: 23.001741 | O3: 22.229531 | P3: 21.59282 | Q3: 21.82883 | R3: 22.350397 | S3: 22.908834 | T3: 23.161927 | U3: 23.166595 | V3: 22.748213 | W3: 314 | X3: 0.87222222
A4: 23085030 | B4: CO | C4: Alejandría | D4: Alejandría | E4: Antioquia | F4: 1 | G4: 1712 | H4: -75.143389 | I4: 6.37625 | J4: 14.716171 | K4: 14.811488 | L4: 15.177771 | M4: 15.437553 | N4: 15.617673 | O4: 15.226738 | P4: 14.773956 | Q4: 14.785404 | R4: 15.029762 | S4: 15.194157 | T4: 15.422869 | U4: 15.010688 | V4: 15.100352 | W4: 343 | X4: 0.95277778
A5: 26195020 | B5: PM | C5: Ita Andes | D5: Andes | E5: Antioquia | F5: 1 | G5: 1180 | H5: -75.880222 | I5: 5.691 | J5: 16.488765 | K5: 16.979963 | L5: 17.115707 | M5: 17.057628 | N5: 17.102392 | O5: 16.660917 | P5: 16.495189 | Q5: 16.446428 | R5: 16.628005 | S5: 16.630249 | T5: 16.973087 | U5: 16.863381 | V5: 16.786809 | W5: 293 | X5: 0.81388889
A6: 27025030 | B6: CO | C6: Anorí | D6: Anorí | E6: Antioquia | F6: 1 | G6: 1601 | H6: -75.150528 | I6: 7.0719167 | J6: 14.830824 | K6: 15.149268 | L6: 15.562986 | M6: 15.921864 | N6: 16.136926 | O6: 15.907921 | P6: 15.700556 | Q6: 15.713385 | R6: 15.594401 | S6: 15.594886 | T6: 15.581394 | U6: 15.31599 | V6: 15.5842 | W6: 316 | X6: 0.87777778
A7: 12015020 | B7: AM | C7: Uniban | D7: Apartadó | E7: Antioquia | F7: 1 | G7: 43 | H7: -76.651333 | I7: 7.8259167 | J7: 23.478517 | K7: 23.520371 | L7: 23.698444 | M7: 23.86102 | N7: 23.718104 | O7: 23.506471 | P7: 23.317239 | Q7: 23.414845 | R7: 23.367964 | S7: 23.197178 | T7: 23.157932 | U7: 23.336842 | V7: 23.464577 | W7: 293 | X7: 0.81388889
A8: 27015090 | B8: CO | C8: Tulio Ospina | D8: Bello | E8: Antioquia | F8: 1 | G8: 1453 | H8: -75.55325 | I8: 6.3196944 | J8: 16.9981 | K8: 17.30888 | L8: 17.500943 | M8: 17.755935 | N8: 17.754916 | O8: 17.42114 | P8: 17.205067 | Q8: 17.32409 | R8: 17.370087 | S8: 17.338957 | T8: 17.363827 | U8: 17.283107 | V8: 17.385421 | W8: 310 | X8: 0.86111111
A9: 26225040 | B9: CO | C9: Hacienda Piunti | D9: Buriticá | E9: Antioquia | F9: 1 | G9: 1650 | H9: -75.912972 | I9: 6.7295 | J9: 16.283264 | K9: 16.448349 | L9: 16.569784 | M9: 16.606958 | N9: 16.570344 | O9: 16.555581 | P9: 16.367986 | Q9: 16.3928 | R9: 16.291944 | S9: 16.309027 | T9: 16.344598 | U9: 16.376738 | V9: 16.426448 | W9: 222 | X9: 0.925
A10: 27015260 | B10: AM | C10: La Salada | D10: Caldas | E10: Antioquia | F10: 1 | G10: 1923 | H10: -75.624667 | I10: 6.0483611 | J10: 12.682619 | K10: 12.892049 | L10: 13.210012 | M10: 13.458282 | N10: 13.751722 | O10: 13.236944 | P10: 12.945465 | Q10: 13.024959 | R10: 13.010984 | S10: 13.219427 | T10: 13.404811 | U10: 13.140323 | V10: 13.1648 | W10: 215 | X10: 0.89583333
A11: 11115020 | B11: CO | C11: Cañasgordas - Aut | D11: Cañasgordas | E11: Antioquia | F11: 1 | G11: 1294 | H11: -76.029667 | I11: 6.7580278 | J11: 15.872612 | K11: 16.068372 | L11: 16.303646 | M11: 16.576727 | N11: 16.819651 | O11: 16.794557 | P11: 16.588551 | Q11: 16.522879 | R11: 16.438869 | S11: 16.389007 | T11: 16.355192 | U11: 16.172913 | V11: 16.408581 | W11: 341 | X11: 0.94722222
A12: 12015070 | B12: SP | C12: Aeropuerto Los Cedros | D12: Carepa | E12: Antioquia | F12: 1 | G12: 41 | H12: -76.717889 | I12: 7.8163889 | J12: 23.728305 | K12: 23.896131 | L12: 23.9766 | M12: 24.109386 | N12: 23.818532 | O12: 23.515431 | P12: 23.317826 | Q12: 23.404405 | R12: 23.201043 | S12: 23.207567 | T12: 23.186159 | U12: 23.541934 | V12: 23.575276 | W12: 342 | X12: 0.95
A13: 12015060 | B13: CO | C13: Tulenapa | D13: Carepa | E13: Antioquia | F13: 1 | G13: 39 | H13: -76.67 | I13: 7.77 | J13: 23.233484 | K13: 23.423158 | L13: 23.568392 | M13: 23.97538 | N13: 23.840457 | O13: 23.296313 | P13: 23.243949 | Q13: 23.515384 | R13: 23.352842 | S13: 23.361908 | T13: 23.219752 | U13: 23.238537 | V13: 23.43913 | W13: 207 | X13: 0.8625
A14: 11025010 | B14: CO | C14: La Mansa | D14: Ciudad Bolívar | E14: Antioquia | F14: 1 | G14: 2018 | H14: -76.084333 | I14: 5.8783056 | J14: 13.09284 | K14: 13.481901 | L14: 13.593113 | M14: 13.79912 | N14: 13.846824 | O14: 13.509455 | P14: 13.086423 | Q14: 12.977878 | R14: 13.187741 | S14: 13.22638 | T14: 13.468376 | U14: 13.446296 | V14: 13.393029 | W14: 346 | X14: 0.96111111
