Workbook

Sheet Temperatura
A2: VARIABLE | B2: TEMPERATURA MEDIA (°C) | C2: MES | D2: =VLOOKUP(E2,Climatologia_TMED!AA1:AC13,2,FALSE) -> JULIO | E2: 7 | F2: AÑO | G2: 2026 | H2: DIAS | I2: =VLOOKUP(E2,Climatologia_TMED!AA1:AC13,3,FALSE) -> 31
A4: CODIGO | B4: ESTACION | C4: AREA_OP | D4: LON | E4: LAT | F4: ELEV | G4: COD_DPTO | H4: COD_MUNICIPIO | I4: DEPARTAMENTO | J4: MUNICIPIO | K4: 1 | L4: 2 | M4: 3 | N4: 4 | O4: 5 | P4: 6 | Q4: 7 | R4: 8 | S4: 9 | T4: 10 | U4: 11 | V4: 12 | W4: 13 | X4: 14 | Y4: 15 | Z4: 16 | AA4: 17 | AB4: 18 | AC4: 19 | AD4: 20 | AE4: 21 | AF4: 22 | AG4: 23 | AH4: 24 | AI4: 25 | AJ4: 26 | AK4: 27 | AL4: 28 | AM4: 29 | AN4: 30 | AO4: 31 | AP4: NUM_DATOS | AQ4: MEDIA_MENSUAL | AR4: MEDIA_MULTIANUAL | AS4: ANOMALIA
A5: 17015010 | B5: Aeropuerto Sesquicentenario | C5: Met_Aeronautica | D5: -81.704 | E5: 12.587 | F5: 1 | G5: 88 | H5: 88001 | I5: Archipiélago de San Andres, Providencia y Santa Catalina | J5: Isla de San Andrés | K5: 30 | L5: 29.8 | M5: 29.1 | N5: 26.5 | O5: 28.3 | P5: 29.9 | Q5: 29.2 | R5: 29.4 | S5: 29.9 | T5: 29.1 | U5: 29.8 | V5: 28.5 | W5: 27.1 | X5: 28 | Y5: 28.4 | Z5: 28.9 | AA5: 29.5 | AB5: 29.2 | AC5: 29.4 | AD5: 26.7 | AE5: 28.8 | AF5: 28.8 | AG5: 29.2 | AH5: 27.8 | AI5: 28.8 | AP5: =COUNTIF(K5:AO5,">0") -> 25 | AQ5: =IF(AP5>14,AVERAGE(K5:AO5),"") -> 28.804 | AR5: =IFERROR(VLOOKUP(A5,Climatologia_TMED!A:U,9+$E$2,FALSE),"") -> 28.153215 | AS5: =IF(OR(AQ5="",AR5=""),"",IFERROR(AQ5-AR5,"")) -> 0.65078511
A6: 17025020 | B6: Aeropuerto El Embrujo | C6: Met_Aeronautica | D6: -81.358 | E6: 13.36 | F6: 7 | G6: 88 | H6: 88564 | I6: Archipiélago de San Andres, Providencia y Santa Catalina | J6: Isla de Providencia | K6: 29 | L6: 29.7 | M6: 29.7 | N6: 27.8 | O6: 27.5 | P6: 29 | Q6: 29 | R6: 29 | S6: 29.4 | T6: 28.7 | U6: 29.1 | V6: 29.5 | W6: 28.6 | X6: 28.4 | Y6: 28.7 | Z6: 29.5 | AA6: 29.3 | AB6: 28.9 | AC6: 28.3 | AD6: 28.2 | AE6: 28.7 | AF6: 29.3 | AG6: 28.8 | AH6: 27.5 | AI6: 29.2 | AP6: =COUNTIF(K6:AO6,">0") -> 25 | AQ6: =IF(AP6>14,AVERAGE(K6:AO6),"") -> 28.832 | AR6: =IFERROR(VLOOKUP(A6,Climatologia_TMED!A:U,9+$E$2,FALSE),"") -> 28.395234 | AS6: =IF(OR(AQ6="",AR6=""),"",IFERROR(AQ6-AR6,"")) -> 0.43676611
A7: 15015050 | B7: Aeropuerto Simón Bolívar | C7: Met_Aeronautica | D7: -74.229 | E7: 11.128 | F7: 4 | G7: 47 | H7: 47001 | I7: Magdalena | J7: Santa Marta | K7: 30.9 | L7: 32.4 | M7: 30.9 | N7: 29.4 | O7: 31.5 | P7: 31.9 | Q7: 34 | R7: 34.2 | S7: 30.6 | T7: 30.2 | U7: 32 | V7: 32.5 | W7: 31.1 | X7: 33 | Y7: 33.1 | Z7: 33.4 | AA7: 33.8 | AB7: 31.9 | AC7: 31.6 | AD7: 27.1 | AE7: 29.1 | AF7: 32.1 | AG7: 29.6 | AH7: 28.8 | AI7: 31 | AP7: =COUNTIF(K7:AO7,">0") -> 25 | AQ7: =IF(AP7>14,AVERAGE(K7:AO7),"") -> 31.444 | AR7: =IFERROR(VLOOKUP(A7,Climatologia_TMED!A:U,9+$E$2,FALSE),"") -> 29.20018 | AS7: =IF(OR(AQ7="",AR7=""),"",IFERROR(AQ7-AR7,"")) -> 2.2438195
A8: 14015080 | B8: Aeropuerto Rafael Nuñez | C8: Met_Aeronautica | D8: -75.516 | E8: 10.447 | F8: 2 | G8: 13 | H8: 13001 | I8: Bolívar | J8: Cartagena de Indias | K8: 29.5 | L8: 30.1 | M8: 29 | N8: 28.6 | O8: 29.7 | P8: 30.1 | Q8: 30.7 | R8: 31 | S8: 30.3 | T8: 30.1 | U8: 30.5 | V8: 30 | W8: 29 | X8: 30.2 | Y8: 30.7 | Z8: 30.4 | AA8: 30.6 | AB8: 30.9 | AC8: 29.5 | AD8: 27.2 | AE8: 29 | AF8: 29.2 | AG8: 28.6 | AH8: 28.4 | AI8: 29.5 | AP8: =COUNTIF(K8:AO8,">0") -> 25 | AQ8: =IF(AP8>14,AVERAGE(K8:AO8),"") -> 29.712 | AR8: =IFERROR(VLOOKUP(A8,Climatologia_TMED!A:U,9+$E$2,FALSE),"") -> 28.578539 | AS8: =IF(OR(AQ8="",AR8=""),"",IFERROR(AQ8-AR8,"")) -> 1.1334607
A9: 29045190 | B9: Aeropuerto Ernesto Cortissoz - AUT | C9: Met_Aeronautica | D9: -74.78 | E9: 10.918 | F9: 14 | G9: 8 | H9: 8758 | I9: Atlántico | J9: Soledad | K9: 29.6 | L9: 29.4 | M9: 28.7 | N9: 28.1 | O9: 29.9 | P9: 29.4 | Q9: 30.5 | R9: 30.6 | S9: 29.9 | T9: 29.1 | U9: 29.7 | V9: 29.5 | W9: 29.1 | X9: 30.8 | Y9: 30.5 | Z9: 30 | AA9: 30.1 | AB9: 29.8 | AC9: 29.3 | AD9: 25.4 | AE9: 29.1 | AF9: 29.1 | AG9: 29.1 | AH9: 28.7 | AI9: 29.2 | AP9: =COUNTIF(K9:AO9,">0") -> 25 | AQ9: =IF(AP9>14,AVERAGE(K9:AO9),"") -> 29.384 | AR9: =IFERROR(VLOOKUP(A9,Climatologia_TMED!A:U,9+$E$2,FALSE),"") -> 29.787469 | AS9: =IF(OR(AQ9="",AR9=""),"",IFERROR(AQ9-AR9,"")) -> -0.40346898
A10: 15065180 | B10: Aeropuerto Almirante Padilla | C10: Met_Aeronautica | D10: -72.918 | E10: 11.53 | F10: 4 | G10: 44 | H10: 44001 | I10: La Guajira | J10: Riohacha | K10: 31.2 | L10: 31 | M10: 30.7 | N10: 31 | O10: 32.1 | P10: 31.6 | Q10: 33.1 | R10: 33.2 | S10: 32.1 | T10: 31.1 | U10: 30.7 | V10: 32.5 | W10: 31.1 | X10: 32.5 | Y10: 33 | Z10: 32.2 | AA10: 32.9 | AB10: 31.8 | AC10: 30.6 | AD10: 32 | AE10: 32.5 | AF10: 30 | AG10: 31 | AH10: 31.7 | AI10: 30.5 | AP10: =COUNTIF(K10:AO10,">0") -> 25 | AQ10: =IF(AP10>14,AVERAGE(K10:AO10),"") -> 31.684 | AR10: =IFERROR(VLOOKUP(A10,Climatologia_TMED!A:U,9+$E$2,FALSE),"") -> 30.079422 | AS10: =IF(OR(AQ10="",AR10=""),"",IFERROR(AQ10-AR10,"")) -> 1.604578
A11: 28025502 | B11: Aeropuerto Alfonso López | C11: Met_Aeronautica | D11: -73.248 | E11: 10.436 | F11: 138 | G11: 20 | H11: 20001 | I11: Cesar | J11: Valledupar | K11: 34 | L11: 32.9 | M11: 31.1 | N11: 31.3 | O11: 33.5 | P11: 33.1 | Q11: 34.6 | R11: 33.9 | S11: 32.9 | T11: 33.1 | U11: 33.5 | V11: 31.2 | W11: 32.2 | X11: 34.1 | Y11: 34.4 | Z11: 33.8 | AA11: 34.1 | AB11: 32.8 | AC11: 32.5 | AD11: 29.2 | AE11: 31.5 | AF11: 31.7 | AG11: 30 | AH11: 31.7 | AI11: 33.2 | AP11: =COUNTIF(K11:AO11,">0") -> 25 | AQ11: =IF(AP11>14,AVERAGE(K11:AO11),"") -> 32.652 | AR11: =IFERROR(VLOOKUP(A11,Climatologia_TMED!A:U,9+$E$2,FALSE),"") -> 30.003914 | AS11: =IF(OR(AQ11="",AR11=""),"",IFERROR(AQ11-AR11,"")) -> 2.6480859
A12: 13035501 | B12: Aeropuerto Los Garzones | C12: Met_Aeronautica | D12: -75.825 | E12: 8.826 | F12: 20 | G12: 23 | H12: 23001 | I12: Córdoba | J12: Montería | K12: 30.7 | L12: 28.7 | M12: 30.7 | N12: 28.3 | O12: 31.3 | P12: 31 | Q12: 31.5 | R12: 31.7 | S12: 27.2 | T12: 30.9 | U12: 30.7 | V12: 29.8 | W12: 29 | X12: 31.8 | Y12: 31.5 | Z12: 32 | AA12: 31.8 | AB12: 31.5 | AC12: 28.5 | AD12: 27.9 | AE12: 30 | AF12: 30.5 | AG12: 25.8 | AH12: 29.2 | AI12: 30.9 | AP12: =COUNTIF(K12:AO12,">0") -> 25 | AQ12: =IF(AP12>14,AVERAGE(K12:AO12),"") -> 30.116 | AR12: =IFERROR(VLOOKUP(A12,Climatologia_TMED!A:U,9+$E$2,FALSE),"") -> 28.265666 | AS12: =IF(OR(AQ12="",AR12=""),"",IFERROR(AQ12-AR12,"")) -> 1.8503336
A13: 23155030 | B13: Aeropuerto Yariguies | C13: Met_Aeronautica | D13: -73.809 | E13: 7.026 | F13: 126 | G13: 68 | H13: 68081 | I13: Santander | J13: Barrancabermeja | K13: 30.7 | L13: 28.7 | M13: 29.6 | N13: 27.6 | O13: 30.8 | P13: 31.4 | Q13: 32.4 | R13: 32.4 | S13: 26.4 | T13: 29.7 | U13: 30.3 | V13: 27.9 | W13: 29.8 | X13: 31.3 | Y13: 31.7 | Z13: 32.9 | AA13: 33.7 | AB13: 30.8 | AC13: 28.6 | AD13: 27.8 | AE13: 27.6 | AF13: 29.9 | AG13: 26.9 | AH13: 29.6 | AI13: 30.3 | AP13: =COUNTIF(K13:AO13,">0") -> 25 | AQ13: =IF(AP13>14,AVERAGE(K13:AO13),"") -> 29.952 | AR13: =IFERROR(VLOOKUP(A13,Climatologia_TMED!A:U,9+$E$2,FALSE),"") -> 28.329395 | AS13: =IF(OR(AQ13="",AR13=""),"",IFERROR(AQ13-AR13,"")) -> 1.6226053
A14: 23195502 | B14: Aeropuerto Palonegro | C14: Met_Aeronautica | D14: -73.185 | E14: 7.121 | F14: 1189 | G14: 68 | H14: 68406 | I14: Santander | J14: Lebrija | K14: 24.9 | L14: 22.7 | M14: 23 | N14: 22.6 | O14: 24.2 | P14: 24.6 | Q14: 25.9 | R14: 25.2 | S14: 21.4 | T14: 23.2 | U14: 23.7 | V14: 22.5 | W14: 23.6 | X14: 23.2 | Y14: 25.4 | Z14: 26.2 | AA14: 25.3 | AB14: 23.5 | AC14: 22.9 | AD14: 21.9 | AE14: 22 | AF14: 24.7 | AG14: 21.9 | AH14: 22.4 | AI14: 23.1 | AP14: =COUNTIF(K14:AO14,">0") -> 25 | AQ14: =IF(AP14>14,AVERAGE(K14:AO14),"") -> 23.6 | AR14: =IFERROR(VLOOKUP(A14,Climatologia_TMED!A:U,9+$E$2,FALSE),"") -> 21.72154 | AS14: =IF(OR(AQ14="",AR14=""),"",IFERROR(AQ14-AR14,"")) -> 1.87846
A15: 16015010 | B15: Aeropuerto Camilo Daza | C15: Met_Aeronautica | D15: -72.509 | E15: 7.93 | F15: 250 | G15: 54 | H15: 54001 | I15: Norte de Santander | J15: Cúcuta | K15: 25.2 | L15: 26.6 | M15: 27.3 | N15: 28.5 | O15: 30.7 | P15: 31 | Q15: 30.2 | R15: 32.4 | S15: 27.3 | T15: 30.5 | U15: 29 | V15: 27.8 | W15: 29.7 | X15: 29.4 | Y15: 31.2 | Z15: 30.1 | AA15: 31 | AB15: 28 | AC15: 28.5 | AD15: 26.2 | AE15: 29.1 | AF15: 31.3 | AG15: 28.1 | AH15: 31 | AI15: 28.9 | AP15: =COUNTIF(K15:AO15,">0") -> 25 | AQ15: =IF(AP15>14,AVERAGE(K15:AO15),"") -> 29.16 | AR15: =IFERROR(VLOOKUP(A15,Climatologia_TMED!A:U,9+$E$2,FALSE),"") -> 28.235505 | AS15: =IF(OR(AQ15="",AR15=""),"",IFERROR(AQ15-AR15,"")) -> 0.92449462
A16: 12015070 | B16: Aeropuerto Los Cedros | C16: Met_Aeronautica | D16: -76.718 | E16: 7.816 | F16: 41 | G16: 5 | H16: 5147 | I16: Antioquia | J16: Carepa | K16: 28.1 | L16: 28.6 | M16: 28.1 | N16: 27.2 | O16: 29.7 | P16: 27.5 | Q16: 30.1 | R16: 30.1 | S16: 25.3 | T16: 28.9 | U16: 27.5 | V16: 27 | W16: 28.7 | X16: 30 | Y16: 30.5 | Z16: 30.4 | AA16: 30.1 | AB16: 27.8 | AC16: 26.9 | AD16: 27.5 | AE16: 28.4 | AF16: 29 | AG16: 24.6 | AH16: 28.1 | AI16: 29.6 | AP16: =COUNTIF(K16:AO16,">0") -> 25 | AQ16: =IF(AP16>14,AVERAGE(K16:AO16),"") -> 28.388 | AR16: =IFERROR(VLOOKUP(A16,Climatologia_TMED!A:U,9+$E$2,FALSE),"") -> 27.637653 | AS16: =IF(OR(AQ16="",AR16=""),"",IFERROR(AQ16-AR16,"")) -> 0.75034715
... A37: 26175040 | B37: Hacienda Tunez | C37: Area Operativa 01 - Antioquia-Chocó | D37: -75.650972 | E37: 5.80025 | F37: 604 | G37: 5 | H37: 5282 | I37: Antioquia | J37: Fredonia | K37: 27.9 | L37: 25.65 | M37: 26.85 | N37: 25.8 | O37: 27.05 | P37: 27.85 | Q37: 28.45 | R37: 27.25 | S37: 27.3 | T37: 28.9 | U37: 26.75 | V37: 26.85 | W37: 28.7 | X37: 28.2 | Y37: 27.1 | Z37: 28.3 | AA37: 28.05 | AB37: 27.95 | AC37: 26.85 | AD37: 27.7 | AE37: 27.2 | AF37: 28.25 | AG37: 25.1 | AH37: 27.45 | AI37: 27.4 | AP37: =COUNTIF(K37:AO37,">0") -> 25 | AQ37: =IF(AP37>14,AVERAGE(K37:AO37),"") -> 27.394 | AR37: =IFERROR(VLOOKUP(A37,Climatologia_TMED!A:U,9+$E$2,FALSE),"") -> 25.88623 | AS37: =IF(OR(AQ37="",AR37=""),"",IFERROR(AQ37-AR37,"")) -> 1.5077701
A38: 26185020 | B38: Mesopotamia | C38: Area Operativa 01 - Antioquia-Chocó | D38: -75.318639 | E38: 5.8863611 | F38: 2408 | G38: 5 | H38: 5400 | I38: Antioquia | J38: La Unión | K38: 17.2 | L38: 15.4 | M38: 16.4 | N38: 14.95 | O38: 15.95 | P38: 15.6 | Q38: 17.2 | R38: 17.25 | S38: 15.6 | T38: 16.7 | U38: 15.4 | V38: 14.75 | W38: 16 | Y38: 16.1 | Z38: 16.2 | AA38: 17.45 | AB38: 15.95 | AC38: 15.5 | AE38: 15.85 | AF38: 15.55 | AG38: 14.9 | AH38: 16.3 | AI38: 15.2 | AP38: =COUNTIF(K38:AO38,">0") -> 23 | AQ38: =IF(AP38>14,AVERAGE(K38:AO38),"") -> 15.973913 | AR38: =IFERROR(VLOOKUP(A38,Climatologia_TMED!A:U,9+$E$2,FALSE),"") -> 15.017929 | AS38: =IF(OR(AQ38="",AR38=""),"",IFERROR(AQ38-AR38,"")) -> 0.95598404
A39: 26205080 | B39: La Aldea | C39: Area Operativa 01 - Antioquia-Chocó | D39: -75.700944 | E39: 6.3410556 | F39: 1737 | G39: 5 | H39: 5001 | I39: Antioquia | J39: Medellín | K39: 23.466667 | L39: 23.4 | M39: 22.666667 | N39: 19.666667 | O39: 22.133333 | P39: 24.266667 | Q39: 24.333333 | R39: 24.4 | S39: 20.866667 | T39: 23.133333 | U39: 21.733333 | V39: 20.133333 | W39: 22.8 | Y39: 23 | Z39: 24.666667 | AA39: 24.933333 | AB39: 23.2 | AC39: 21.4 | AD39: 19.733333 | AE39: 21.333333 | AF39: 21.8 | AG39: 19.133333 | AH39: 21.866667 | AI39: 21.8 | AP39: =COUNTIF(K39:AO39,">0") -> 24 | AQ39: =IF(AP39>14,AVERAGE(K39:AO39),"") -> 22.327778 | AR39: =IFERROR(VLOOKUP(A39,Climatologia_TMED!A:U,9+$E$2,FALSE),"") | AS39: =IF(OR(AQ39="",AR39=""),"",IFERROR(AQ39-AR39,""))
A40: 27015090 | B40: Tulio Ospina | C40: Area Operativa 01 - Antioquia-Chocó | D40: -75.55325 | E40: 6.3196944 | F40: 1453 | G40: 5 | H40: 5088 | I40: Antioquia | J40: Bello | K40: 25.666667 | M40: 25.6 | N40: 23.4 | O40: 24.733333 | P40: 27.133333 | Q40: 27.533333 | R40: 27.066667 | S40: 24.333333 | T40: 25.466667 | U40: 25.066667 | V40: 22.266667 | Y40: 25.2 | Z40: 26.733333 | AA40: 26.2 | AB40: 26.2 | AC40: 24.8 | AF40: 25.15 | AH40: 24.333333 | AI40: 24.133333 | AP40: =COUNTIF(K40:AO40,">0") -> 19 | AQ40: =IF(AP40>14,AVERAGE(K40:AO40),"") -> 25.316667 | AR40: =IFERROR(VLOOKUP(A40,Climatologia_TMED!A:U,9+$E$2,FALSE),"") -> 22.851791 | AS40: =IF(OR(AQ40="",AR40=""),"",IFERROR(AQ40-AR40,"")) -> 2.4648759
A41: 27015260 | B41: La Salada | C41: Area Operativa 01 - Antioquia-Chocó | D41: -75.624667 | E41: 6.0483611 | F41: 1923 | G41: 5 | H41: 5129 | I41: Antioquia | J41: Caldas | K41: 20.733333 | L41: 20 | M41: 21.2 | N41: 20.4 | O41: 21 | P41: 21.6 | Q41: 21.933333 | R41: 21.866667 | S41: 21.133333 | T41: 21.6 | U41: 19.6 | V41: 18.4 | W41: 20.133333 | X41: 21.266667 | Y41: 19.533333 | Z41: 21.533333 | AA41: 20.333333 | AB41: 18.866667 | AD41: 17.9 | AE41: 19.8 | AF41: 18.8 | AG41: 18.4 | AH41: 18 | AI41: 20.466667 | AP41: =COUNTIF(K41:AO41,">0") -> 24 | AQ41: =IF(AP41>14,AVERAGE(K41:AO41),"") -> 20.1875 | AR41: =IFERROR(VLOOKUP(A41,Climatologia_TMED!A:U,9+$E$2,FALSE),"") -> 18.492109 | AS41: =IF(OR(AQ41="",AR41=""),"",IFERROR(AQ41-AR41,"")) -> 1.6953908
A42: 12045010 | B42: Arboletes | C42: Area Operativa 02 - Atlántico-Bolivar-Sucre | D42: -76.431944 | E42: 8.8469444 | F42: 4 | G42: 5 | H42: 5051 | I42: Antioquia | J42: Arboletes | K42: 28.85 | L42: 28.4 | M42: 27.5 | N42: 26.8 | O42: 28.7 | P42: 28.45 | Q42: 28.65 | R42: 28.5 | S42: 25.8 | T42: 28.15 | U42: 28.6 | V42: 27.95 | W42: 26.9 | X42: 28.95 | Y42: 28.9 | Z42: 29.55 | AA42: 29.05 | AB42: 28.6 | AC42: 28.5 | AD42: 26.55 | AE42: 27.825 | AF42: 28.6 | AG42: 24.7 | AH42: 27.5 | AI42: 28.55 | AP42: =COUNTIF(K42:AO42,">0") -> 25 | AQ42: =IF(AP42>14,AVERAGE(K42:AO42),"") -> 28.021 | AR42: =IFERROR(VLOOKUP(A42,Climatologia_TMED!A:U,9+$E$2,FALSE),"") -> 27.752686 | AS42: =IF(OR(AQ42="",AR42=""),"",IFERROR(AQ42-AR42,"")) -> 0.26831448
A43: 12045020 | B43: Cristo Rey - Aut | C43: Area Operativa 02 - Atlántico-Bolivar-Sucre | D43: -76.224444 | E43: 9.0711111 | F43: 15 | G43: 23 | H43: 23574 | I43: Córdoba | J43: Puerto Escondido | K43: 30.75 | N43: 28.55 | O43: 29.85 | P43: 29.95 | Q43: 30.55 | R43: 29.4 | S43: 29.15 | T43: 28.75 | U43: 29.85 | V43: 28.9 | W43: 27.8 | X43: 29.85 | Y43: 30.55 | Z43: 30.75 | AA43: 30.65 | AB43: 30.5 | AC43: 29.4 | AD43: 27.25 | AE43: 28.85 | AF43: 29.85 | AG43: 26.1 | AH43: 28.6 | AI43: 29.75 | AP43: =COUNTIF(K43:AO43,">0") -> 23 | AQ43: =IF(AP43>14,AVERAGE(K43:AO43),"") -> 29.373913 | AR43: =IFERROR(VLOOKUP(A43,Climatologia_TMED!A:U,9+$E$2,FALSE),"") | AS43: =IF(OR(AQ43="",AR43=""),"",IFERROR(AQ43-AR43,""))
A44: 13015040 | B44: Represa Urra | C44: Area Operativa 02 - Atlántico-Bolivar-Sucre | D44: -76.203056 | E44: 8.0141667 | F44: 300 | G44: 23 | H44: 23807 | I44: Córdoba | J44: Tierralta | K44: 28.575 | L44: 26.675 | M44: 26.95 | N44: 27.275 | O44: 29.5 | P44: 28.3 | Q44: 29.9 | R44: 28.975 | S44: 25.45 | T44: 28.8 | U44: 29.45 | V44: 26.65 | W44: 27.7 | X44: 29.45 | Y44: 31.35 | Z44: 31.2 | AA44: 29.925 | AB44: 30.05 | AC44: 28.75 | AD44: 27.425 | AE44: 28.45 | AF44: 28.425 | AG44: 25.55 | AH44: 28.9 | AI44: 28.95 | AP44: =COUNTIF(K44:AO44,">0") -> 25 | AQ44: =IF(AP44>14,AVERAGE(K44:AO44),"") -> 28.505 | AR44: =IFERROR(VLOOKUP(A44,Climatologia_TMED!A:U,9+$E$2,FALSE),"") -> 27.342343 | AS44: =IF(OR(AQ44="",AR44=""),"",IFERROR(AQ44-AR44,"")) -> 1.1626566
A45: 25025080 | B45: Aeropuerto Rafael Barvo | C45: Area Operativa 02 - Atlántico-Bolivar-Sucre | D45: -75.283056 | E45: 9.3338889 | F45: 166 | G45: 70 | H45: 70215 | I45: Sucre | J45: Corozal | K45: 29.55 | L45: 29.5 | M45: 30.1 | N45: 27.45 | O45: 29.6 | P45: 30.65 | Q45: 30.5 | R45: 30.8 | S45: 28.75 | T45: 29.9 | U45: 30.2 | V45: 29 | W45: 28.35 | X45: 29.6 | Y45: 30.1 | Z45: 31 | AA45: 31.35 | AB45: 30 | AC45: 27.75 | AD45: 27 | AE45: 27.95 | AF45: 29.65 | AG45: 25.65 | AH45: 28.45 | AI45: 29.65 | AP45: =COUNTIF(K45:AO45,">0") -> 25 | AQ45: =IF(AP45>14,AVERAGE(K45:AO45),"") -> 29.3 | AR45: =IFERROR(VLOOKUP(A45,Climatologia_TMED!A:U,9+$E$2,FALSE),"") -> 27.768107 | AS45: =IF(OR(AQ45="",AR45=""),"",IFERROR(AQ45-AR45,"")) -> 1.5318925
A46: 13075010 | B46: Chima | C46: Area Operativa 02 - Atlántico-Bolivar-Sucre | D46: -75.622083 | E46: 9.15075 | F46: 20 | G46: 5 | H46: 5172 | I46: Antioquia | J46: Chigorodó | K46: 30.375 | L46: 29 | M46: 28.8 | N46: 27.7 | O46: 29.25 | P46: 29.65 | Q46: 29.8 | R46: 30.1 | S46: 28.2 | T46: 28.6 | U46: 28.8 | V46: 28.55 | W46: 28.15 | X46: 28.75 | Y46: 29.55 | Z46: 30.05 | AA46: 30.35 | AB46: 29.65 | AC46: 28.5 | AD46: 27 | AE46: 28.9 | AF46: 28.55 | AG46: 27.1 | AH46: 29.3 | AI46: 29.4 | AP46: =COUNTIF(K46:AO46,">0") -> 25 | AQ46: =IF(AP46>14,AVERAGE(K46:AO46),"") -> 28.963 | AR46: =IFERROR(VLOOKUP(A46,Climatologia_TMED!A:U,9+$E$2,FALSE),"") -> 27.906198 | AS46: =IF(OR(AQ46="",AR46=""),"",IFERROR(AQ46-AR46,"")) -> 1.0568024
A47: 13075020 | B47: El Salado | C47: Area Operativa 02 - Atlántico-Bolivar-Sucre | D47: -75.582222 | E47: 8.9138889 | F47: 40 | G47: 23 | H47: 23189 | I47: Córdoba | J47: Ciénaga De Oro | K47: 31.166667 | L47: 29.533333 | M47: 30.366667 | N47: 28.3 | O47: 31 | P47: 30.866667 | Q47: 31.133333 | R47: 31.133333 | S47: 26.8 | T47: 29.866667 | U47: 30.333333 | V47: 30.066667 | W47: 29.2 | X47: 31.733333 | Y47: 31.666667 | Z47: 31.933333 | AA47: 31.8 | AB47: 31.6 | AC47: 26.466667 | AD47: 27.733333 | AE47: 30.333333 | AF47: 30.466667 | AG47: 25.933333 | AH47: 29.333333 | AI47: 31.4 | AP47: =COUNTIF(K47:AO47,">0") -> 25 | AQ47: =IF(AP47>14,AVERAGE(K47:AO47),"") -> 30.006667 | AR47: =IFERROR(VLOOKUP(A47,Climatologia_TMED!A:U,9+$E$2,FALSE),"") -> 27.968876 | AS47: =IF(OR(AQ47="",AR47=""),"",IFERROR(AQ47-AR47,"")) -> 2.0377908
A48: 13085010 | B48: La Doctrina | C48: Area Operativa 02 - Atlántico-Bolivar-Sucre | D48: -75.892778 | E48: 9.2972222 | F48: 20 | G48: 23 | H48: 23417 | I48: Córdoba | J48: Lorica | AP48: =COUNTIF(K48:AO48,">0") -> 0 | AQ48: =IF(AP48>14,AVERAGE(K48:AO48),"") | AR48: =IFERROR(VLOOKUP(A48,Climatologia_TMED!A:U,9+$E$2,FALSE),"") -> 28.301925 | AS48: =IF(OR(AQ48="",AR48=""),"",IFERROR(AQ48-AR48,""))
A49: 13085030 | B49: San Bernardo Del Viento | C49: Area Operativa 02 - Atlántico-Bolivar-Sucre | D49: -75.95 | E49: 9.37 | F49: 22 | G49: 23 | H49: 23675 | I49: Córdoba | J49: San Bernardo Del Viento | AP49: =COUNTIF(K49:AO49,">0") -> 0 | AQ49: =IF(AP49>14,AVERAGE(K49:AO49),"") | AR49: =IFERROR(VLOOKUP(A49,Climatologia_TMED!A:U,9+$E$2,FALSE),"") -> 27.33464 | AS49: =IF(OR(AQ49="",AR49=""),"",IFERROR(AQ49-AR49,""))
A50: 25025160 | B50: Cuba Hacienda | C50: Area Operativa 02 - Atlántico-Bolivar-Sucre | D50: -75.402778 | E50: 8.0038889 | F50: 50 | G50: 23 | H50: 23466 | I50: Córdoba | J50: Montelíbano | K50: 28.95 | L50: 28.5 | M50: 30.95 | N50: 28.9 | O50: 31.05 | P50: 31.2 | Q50: 31.05 | R50: 30.55 | S50: 26.4 | T50: 29.15 | U50: 30.9 | V50: 28.3 | W50: 28.4 | X50: 29.35 | Y50: 31.25 | Z50: 30.2 | AA50: 31.3 | AB50: 29.6 | AC50: 28.8 | AD50: 26.85 | AE50: 28.25 | AF50: 28.85 | AG50: 25.65 | AH50: 28.35 | AI50: 29.05 | AP50: =COUNTIF(K50:AO50,">0") -> 25 | AQ50: =IF(AP50>14,AVERAGE(K50:AO50),"") -> 29.272 | AR50: =IFERROR(VLOOKUP(A50,Climatologia_TMED!A:U,9+$E$2,FALSE),"") -> 27.28869 | AS50: =IF(OR(AQ50="",AR50=""),"",IFERROR(AQ50-AR50,"")) -> 1.9833097
A51: 25025190 | B51: Planeta Rica - Aut | C51: Area Operativa 02 - Atlántico-Bolivar-Sucre | D51: -75.583722 | E51: 8.3993333 | F51: 90 | G51: 23 | H51: 23555 | I51: Córdoba | J51: Planeta Rica | K51: 30 | L51: 29.1 | M51: 28.95 | N51: 28.5 | O51: 29.8 | P51: 29.025 | Q51: 30.7 | R51: 31.55 | S51: 26.1 | T51: 29.4 | U51: 29.9 | V51: 28.05 | W51: 28.65 | X51: 30.85 | AP51: =COUNTIF(K51:AO51,">0") -> 14 | AQ51: =IF(AP51>14,AVERAGE(K51:AO51),"") | AR51: =IFERROR(VLOOKUP(A51,Climatologia_TMED!A:U,9+$E$2,FALSE),"") -> 27.938143 | AS51: =IF(OR(AQ51="",AR51=""),"",IFERROR(AQ51-AR51,""))
A52: 25025210 | B52: Pinillos | C52: Area Operativa 02 - Atlántico-Bolivar-Sucre | D52: -74.457778 | E52: 8.9113889 | F52: 10 | G52: 13 | H52: 13549 | I52: Bolívar | J52: Pinillos | AP52: =COUNTIF(K52:AO52,">0") -> 0 | AQ52: =IF(AP52>14,AVERAGE(K52:AO52),"") | AR52: =IFERROR(VLOOKUP(A52,Climatologia_TMED!A:U,9+$E$2,FALSE),"") | AS52: =IF(OR(AQ52="",AR52=""),"",IFERROR(AQ52-AR52,""))
A53: 25025270 | B53: Unisucre Aut | C53: Area Operativa 02 - Atlántico-Bolivar-Sucre | D53: -75.3875 | E53: 9.3163889 | F53: 160 | G53: 70 | H53: 70670 | I53: Sucre | J53: Sampués | K53: 30.55 | L53: 29.65 | M53: 28.05 | N53: 26.55 | O53: 29.2 | P53: 30.1 | Q53: 31.15 | R53: 31.8 | S53: 26.65 | T53: 29.35 | U53: 29.6 | V53: 27.8 | W53: 27.8 | X53: 30.15 | Y53: 30.65 | Z53: 30.9 | AA53: 31.15 | AB53: 29.7 | AC53: 27.85 | AD53: 26.7 | AE53: 27.75 | AF53: 28.15 | AG53: 25.5 | AH53: 27.65 | AI53: 29 | AP53: =COUNTIF(K53:AO53,">0") -> 25 | AQ53: =IF(AP53>14,AVERAGE(K53:AO53),"") -> 28.936 | AR53: =IFERROR(VLOOKUP(A53,Climatologia_TMED!A:U,9+$E$2,FALSE),"") -> 27.359246 | AS53: =IF(OR(AQ53="",AR53=""),"",IFERROR(AQ53-AR53,"")) -> 1.5767537
A54: 25025380 | B54: San Benito - Aut | C54: Area Operativa 02 - Atlántico-Bolivar-Sucre | D54: -75.044722 | E54: 9.1638889 | F54: 20 | G54: 70 | H54: 70678 | I54: Sucre | J54: San Benito Abad | K54: 30.85 | L54: 28.7 | M54: 30.85 | N54: 28.75 | O54: 31.2 | P54: 31.65 | Q54: 31.7 | R54: 32.15 | S54: 27.35 | T54: 30.1 | U54: 30.1 | V54: 30.2 | W54: 29.15 | X54: 30.85 | Y54: 31.7 | Z54: 31.8 | AA54: 31.65 | AB54: 31.3 | AC54: 28.95 | AD54: 27.7 | AE54: 29.5 | AF54: 31.2 | AG54: 26.15 | AH54: 29.45 | AI54: 30.45 | AP54: =COUNTIF(K54:AO54,">0") -> 25 | AQ54: =IF(AP54>14,AVERAGE(K54:AO54),"") -> 30.138 | AR54: =IFERROR(VLOOKUP(A54,Climatologia_TMED!A:U,9+$E$2,FALSE),"") -> 28.498226 | AS54: =IF(OR(AQ54="",AR54=""),"",IFERROR(AQ54-AR54,"")) -> 1.639774
A55: 29015000 | B55: El Guamo - Aut | C55: Area Operativa 02 - Atlántico-Bolivar-Sucre | D55: -74.976638 | E55: 10.034607 | F55: 75 | G55: 13 | H55: 13248 | I55: Bolívar | J55: El Guamo | L55: 29.8 | R55: 32.65 | S55: 30.35 | T55: 31.8 | U55: 30.5 | V55: 28.9 | W55: 29.55 | X55: 30.4 | Y55: 33.2 | Z55: 33.5 | AA55: 31.85 | AB55: 29.95 | AC55: 30.3 | AE55: 29 | AF55: 27.65 | AG55: 28 | AH55: 29.35 | AI55: 28.95 | AP55: =COUNTIF(K55:AO55,">0") -> 18 | AQ55: =IF(AP55>14,AVERAGE(K55:AO55),"") -> 30.316667 | AR55: =IFERROR(VLOOKUP(A55,Climatologia_TMED!A:U,9+$E$2,FALSE),"") -> 28.43096 | AS55: =IF(OR(AQ55="",AR55=""),"",IFERROR(AQ55-AR55,"")) -> 1.885707
A56: 29035000 | B56: Sincerin - Aut | C56: Area Operativa 02 - Atlántico-Bolivar-Sucre | D56: -75.278278 | E56: 10.142583 | F56: 10 | G56: 13 | H56: 13052 | I56: Bolívar | J56: Arjona | K56: 30.15 | L56: 28.85 | M56: 29.3 | N56: 29.5 | O56: 30.25 | P56: 30.7 | Q56: 30.25 | R56: 30.8 | S56: 29.8 | T56: 30.4 | U56: 29.95 | V56: 29.25 | W56: 29.7 | X56: 30.55 | Y56: 30.25 | Z56: 29.95 | AA56: 29.9 | AB56: 30.45 | AC56: 29.25 | AD56: 29 | AE56: 28.2 | AF56: 27.05 | AG56: 27.9 | AH56: 27.8 | AI56: 27.45 | AP56: =COUNTIF(K56:AO56,">0") -> 25 | AQ56: =IF(AP56>14,AVERAGE(K56:AO56),"") -> 29.466 | AR56: =IFERROR(VLOOKUP(A56,Climatologia_TMED!A:U,9+$E$2,FALSE),"") | AS56: =IF(OR(AQ56="",AR56=""),"",IFERROR(AQ56-AR56,""))
A57: 29035030 | B57: Presa Ay Grande | C57: Area Operativa 02 - Atlántico-Bolivar-Sucre | D57: -75.326301 | E57: 9.879634 | F57: 60 | G57: 13 | H57: 13442 | I57: Bolívar | J57: María La Baja | AP57: =COUNTIF(K57:AO57,">0") -> 0 | AQ57: =IF(AP57>14,AVERAGE(K57:AO57),"") | AR57: =IFERROR(VLOOKUP(A57,Climatologia_TMED!A:U,9+$E$2,FALSE),"") | AS57: =IF(OR(AQ57="",AR57=""),"",IFERROR(AQ57-AR57,""))
A58: 29035080 | B58: Normal Manati - Aut | C58: Area Operativa 02 - Atlántico-Bolivar-Sucre | D58: -74.954726 | E58: 10.453966 | F58: 10 | G58: 8 | H58: 8436 | I58: Atlántico | J58: Manatí | AP58: =COUNTIF(K58:AO58,">0") -> 0 | AQ58: =IF(AP58>14,AVERAGE(K58:AO58),"") | AR58: =IFERROR(VLOOKUP(A58,Climatologia_TMED!A:U,9+$E$2,FALSE),"") -> 27.866212 | AS58: =IF(OR(AQ58="",AR58=""),"",IFERROR(AQ58-AR58,""))
A59: 29035110 | B59: San Pablo | C59: Area Operativa 02 - Atlántico-Bolivar-Sucre | D59: -75.258611 | E59: 10.043167 | F59: 20 | G59: 13 | H59: 13442 | I59: Bolívar | J59: María La Baja | K59: 29.15 | L59: 29 | M59: 29.7 | N59: 27.95 | O59: 28.95 | P59: 29.9 | Q59: 28.3 | R59: 29.95 | S59: 29 | T59: 30.4 | U59: 29.1 | V59: 27.65 | W59: 27.7 | X59: 29.625 | Y59: 30.05 | Z59: 32.45 | AA59: 31.55 | AB59: 29.65 | AC59: 29 | AD59: 26.7 | AE59: 28.5 | AF59: 28.75 | AH59: 26.65 | AI59: 28.7 | AP59: =COUNTIF(K59:AO59,">0") -> 24 | AQ59: =IF(AP59>14,AVERAGE(K59:AO59),"") -> 29.098958 | AR59: =IFERROR(VLOOKUP(A59,Climatologia_TMED!A:U,9+$E$2,FALSE),"") -> 28.11422 | AS59: =IF(OR(AQ59="",AR59=""),"",IFERROR(AQ59-AR59,"")) -> 0.9847385
A60: 31015010 | B60: El Trueno | C60: Area Operativa 03 - Meta-Guaviare-Guainía | D60: -72.639861 | E60: 2.372592 | F60: 216 | G60: 95 | H60: 95025 | I60: Guaviare | J60: El Retorno | L60: 24.55 | M60: 25.3 | N60: 25 | O60: 25.5 | P60: 26 | Q60: 25 | S60: 24.8 | T60: 26.25 | U60: 25.5 | V60: 24.9 | W60: 26.75 | X60: 25.55 | Z60: 26.5 | AA60: 26.9 | AB60: 26.3 | AC60: 25.1 | AD60: 27.4 | AE60: 26.55 | AP60: =COUNTIF(K60:AO60,">0") -> 18 | AQ60: =IF(AP60>14,AVERAGE(K60:AO60),"") -> 25.769444 | AR60: =IFERROR(VLOOKUP(A60,Climatologia_TMED!A:U,9+$E$2,FALSE),"") -> 24.144564 | AS60: =IF(OR(AQ60="",AR60=""),"",IFERROR(AQ60-AR60,"")) -> 1.6248802
A61: 31095030 | B61: Puerto Inirida - Aut | C61: Area Operativa 03 - Meta-Guaviare-Guainía | D61: -67.919111 | E61: 3.874444 | F61: 98 | G61: 94 | H61: 94001 | I61: Guainía | J61: Inírida | K61: 26.5 | L61: 26.9 | M61: 26.5 | N61: 25.75 | O61: 24.05 | P61: 26.45 | Q61: 26.75 | R61: 25.8 | S61: 27.1 | T61: 27.05 | U61: 26.35 | V61: 26.8 | W61: 26.65 | X61: 27.45 | Y61: 27 | Z61: 27.3 | AA61: 27.85 | AB61: 27.05 | AC61: 25.45 | AD61: 26.3 | AE61: 27.95 | AF61: 25.6 | AG61: 27.25 | AH61: 27.25 | AI61: 27.6 | AP61: =COUNTIF(K61:AO61,">0") -> 25 | AQ61: =IF(AP61>14,AVERAGE(K61:AO61),"") -> 26.668 | AR61: =IFERROR(VLOOKUP(A61,Climatologia_TMED!A:U,9+$E$2,FALSE),"") -> 25.706672 | AS61: =IF(OR(AQ61="",AR61=""),"",IFERROR(AQ61-AR61,"")) -> 0.96132832
A62: 32035010 | B62: La Macarena | C62: Area Operativa 03 - Meta-Guaviare-Guainía | D62: -73.793472 | E62: 2.176139 | F62: 227 | G62: 50 | H62: 50350 | I62: Meta | J62: La Macarena | K62: 25.066667 | L62: 24.333333 | M62: 25.666667 | N62: 26 | O62: 25.733333 | P62: 26.733333 | Q62: 25.8 | R62: 24.8 | S62: 24.333333 | T62: 26.066667 | U62: 25.533333 | V62: 25.866667 | W62: 26.533333 | X62: 25.2 | Y62: 26.6 | Z62: 26.733333 | AA62: 25.933333 | AB62: 25.4 | AC62: 26.333333 | AD62: 27.4 | AE62: 26.6 | AF62: 26.6 | AG62: 25.066667 | AH62: 27.733333 | AP62: =COUNTIF(K62:AO62,">0") -> 24 | AQ62: =IF(AP62>14,AVERAGE(K62:AO62),"") -> 25.919444 | AR62: =IFERROR(VLOOKUP(A62,Climatologia_TMED!A:U,9+$E$2,FALSE),"") -> 24.539004 | AS62: =IF(OR(AQ62="",AR62=""),"",IFERROR(AQ62-AR62,"")) -> 1.3804405
...

Sheet DHIME
A1: Código | B1: Nombre | C1: Departamento | D1: Municipio | E1: Área Operativa | F1: Etiqueta | G1: Latitud | H1: Longitud | I1: Altitud | J1: 01 | K1: 02 | L1: 03 | M1: 04 | N1: 05 | O1: 06 | P1: 07 | Q1: 08 | R1: 09 | S1: 10 | T1: 11 | U1: 12 | V1: 13 | W1: 14 | X1: 15 | Y1: 16 | Z1: 17 | AA1: 18 | AB1: 19 | AC1: 20 | AD1: 21 | AE1: 22 | AF1: 23 | AG1: 24 | AH1: 25 | AI1: 26 | AJ1: 27 | AK1: 28 | AL1: 29 | AM1: 30 | AN1: 31 | AO1: PROM TMED 1981-2010 | AP1: PROM MES | AQ1: ANOM MES
A2: 51025090 | B2: GRANJA EL MIRA - - AUT [51025090] | C2: Nariño | D2: Tumaco | E2: Area Operativa 07 - Nariño-Putumayo | F2: TSSM_MEDIA_D | G2: 1.550194444 | H2: -78.69558333 | I2: 16 | J2: 26.866667 | K2: 26.166667 | L2: 26.066667 | M2: 25.033333 | N2: 26.633333 | O2: 26.6 | P2: 26.466667 | Q2: 27.066667 | R2: 26.733333 | S2: 26.966667 | T2: 26.466667 | U2: 26.666667 | V2: 26.233333 | W2: 26.266667 | X2: 25.666667 | Y2: 26.833333 | Z2: 27.333333 | AA2: 26.633333 | AB2: 27.066667 | AC2: 27.6 | AD2: 27.433333 | AE2: 24.8 | AF2: 26.533333 | AG2: 27.2 | AH2: 26.9 | AI2: 25.833333 | AJ2: 26.8 | AK2: 27.2 | AL2: 26.366667 | AM2: 26.7 | AN2: 26.3 | AP2: 26.562366
A3: 52055210 | B3: BOTANA - AUT [52055210] | C3: Nariño | D3: Pasto | E3: Area Operativa 07 - Nariño-Putumayo | F3: TSSM_MEDIA_D | G3: 1.16 | H3: -77.27880556 | I3: 2820 | J3: 13.733333 | K3: 14 | L3: 14.666667 | M3: 14.133333 | N3: 12.6 | O3: 13.933333 | P3: 14.466667 | Q3: 11.866667 | R3: 13.666667 | S3: 14.466667 | T3: 12.866667 | U3: 12.533333 | V3: 13.6 | W3: 13.2 | X3: 13.066667 | Y3: 13.266667 | Z3: 13.933333 | AA3: 13.733333 | AB3: 15.8 | AC3: 13.866667 | AD3: 14.533333 | AE3: 12.266667 | AF3: 13.2 | AG3: 13.6 | AH3: 13.8 | AI3: 13.466667 | AJ3: 13.133333 | AK3: 13.066667 | AL3: 13.4 | AM3: 13.133333 | AN3: 14.066667 | AP3: 13.582796
A4: 53045040 | B4: AEROPUERTO GUAPI - AUT [53045040] | C4: Cauca | D4: Guapi | E4: Area Operativa 07 - Nariño-Putumayo | F4: TSSM_MEDIA_D | G4: 2.574416667 | H4: -77.89475 | I4: 42 | J4: 26.333333 | K4: 24.8 | L4: 26.733333 | M4: 26.333333 | N4: 25.333333 | O4: 25.333333 | P4: 25.466667 | R4: 26.666667 | S4: 26.333333 | T4: 24.6 | U4: 25.666667 | V4: 25.6 | W4: 25.733333 | X4: 25 | Y4: 25.8 | Z4: 26.266667 | AA4: 27.266667 | AB4: 24.866667 | AC4: 26.333333 | AD4: 25.6 | AE4: 24 | AF4: 26.433333 | AG4: 26.766667 | AH4: 26.666667 | AI4: 25.866667 | AJ4: 26.8 | AK4: 26.4 | AL4: 25.4 | AM4: 25.8 | AN4: 26.466667 | AP4: 25.888889
A5: 35025110 | B5: LA LIBERTAD - AUT [35025110] | C5: Meta | D5: Villavicencio | E5: Area Operativa 03 - Meta-Guaviare-Guainía | F5: TSSM_MEDIA_D | G5: 4.057415 | H5: -73.467865 | I5: 340 | L5: 25.7 | M5: 28.25 | N5: 25.75 | O5: 23.4 | P5: 25.05 | Q5: 27.9 | R5: 27.35 | S5: 26.6 | T5: 26.3 | U5: 26.7 | V5: 24.1 | W5: 25.45 | X5: 25.5 | Y5: 25.45 | Z5: 27.1 | AA5: 27 | AB5: 27.75 | AC5: 28.2 | AD5: 28.1 | AE5: 27.05 | AH5: 28.5 | AI5: 27.15 | AJ5: 26.05 | AK5: 26.5 | AL5: 25.9 | AM5: 24.7 | AN5: 25.4 | AP5: 26.403704
A6: 31095030 | B6: PUERTO INIRIDA - AUT [31095030] | C6: Guainía | D6: Inírida | E6: Area Operativa 03 - Meta-Guaviare-Guainía | F6: TSSM_MEDIA_D | G6: 3.874444 | H6: -67.91911111 | I6: 98 | Z6: 27.35 | AA6: 26.45 | AB6: 28.15 | AC6: 28.7 | AD6: 29 | AE6: 26 | AF6: 28.35 | AG6: 26.05 | AH6: 26.1 | AI6: 26.5 | AJ6: 28.15 | AK6: 26.2 | AL6: 27 | AM6: 25.5 | AN6: 27.1 | AP6: 27.106667
A7: 35215020 | B7: AEROPUERTO YOPAL - AUT [35215020] | C7: Casanare | D7: Yopal | E7: Area Operativa 06 - Boyacá-Casanare-Vichada | F7: TSSM_MEDIA_D | G7: 5.320444444 | H7: -72.3875 | I7: 325 | J7: 30.6 | K7: 29.066667 | L7: 25.733333 | M7: 27.533333 | N7: 28.4 | O7: 27.2 | P7: 27.066667 | Q7: 28.666667 | R7: 28 | S7: 29.2 | T7: 25.733333 | U7: 28.333333 | V7: 27.4 | W7: 27.533333 | X7: 27.266667 | Y7: 29.133333 | Z7: 29.933333 | AA7: 29.466667 | AB7: 29.933333 | AC7: 29.533333 | AD7: 29.466667 | AE7: 29.466667 | AF7: 30.133333 | AG7: 31.133333 | AH7: 30.733333 | AI7: 29.6 | AJ7: 29.066667 | AK7: 29.6 | AL7: 30.133333 | AM7: 26.866667 | AN7: 27.2 | AP7: 28.68172
A8: 24035430 | B8: TUNGUAVITA - AUT [24035430] | C8: Boyacá | D8: Paipa | E8: Area Operativa 06 - Boyacá-Casanare-Vichada | F8: TSSM_MEDIA_D | G8: 5.74583 | H8: -73.11636 | I8: 2521 | J8: 15.25 | K8: 14.85 | L8: 13.9 | M8: 14.65 | N8: 13.3 | O8: 14.6 | P8: 13.95 | Q8: 13.65 | R8: 15.1 | S8: 14.35 | T8: 14.35 | U8: 14.3 | V8: 15.6 | W8: 14.4 | X8: 15.45 | Y8: 16.05 | Z8: 12.7 | AA8: 13.35 | AB8: 15.3 | AC8: 15.9 | AD8: 17.05 | AE8: 15.8 | AF8: 14.55 | AG8: 16.35 | AH8: 15.7 | AI8: 14.15 | AJ8: 13.575 | AK8: 15.3 | AL8: 15.7 | AM8: 15.3 | AN8: 15.15 | AP8: 14.826613
A9: 25025002 | B9: LOS ALAMOS - AUT [25025002] | C9: Magdalena | D9: San Sebastián De Buenavista | E9: Area Operativa 05 - Magdalena-Cesar-Guajira-San Andrés | F9: TSSM_MEDIA_D | G9: 9.304055556 | H9: -74.27363889 | I9: 25 | K9: 27.65 | L9: 27.45 | M9: 27.9 | N9: 26.8 | O9: 27.4 | P9: 27.8 | Q9: 28.95 | R9: 28.45 | S9: 27.95 | T9: 27.9 | U9: 27.75 | V9: 28.1 | W9: 27.55 | X9: 26.45 | Y9: 28.65 | Z9: 28.1 | AA9: 28.85 | AB9: 28.7 | AC9: 29.1 | AD9: 28 | AE9: 28.4 | AF9: 26.2 | AG9: 28.25 | AH9: 28.45 | AI9: 28.35 | AJ9: 28.95 | AK9: 26.5 | AL9: 28.5 | AM9: 29.05 | AN9: 29.05 | AP9: 28.04
A10: 29015000 | B10: EL GUAMO - AUT [29015000] | C10: Bolivar | D10: El Guamo | E10: Area Operativa 02 - Atlántico-Bolivar-Sucre | F10: TSSM_MEDIA_D | G10: 10.034607 | H10: -74.976638 | I10: 75 | J10: 30.25 | K10: 28.6 | L10: 28.3 | M10: 28.35 | N10: 28.15 | O10: 28.05 | P10: 28.7 | Q10: 27.25 | R10: 29.8 | S10: 29.2 | T10: 29 | U10: 28.25 | V10: 28.35 | W10: 27.7 | X10: 28.3 | AC10: 29.4 | AD10: 29.6 | AE10: 29.2 | AF10: 27.8 | AG10: 27.75 | AH10: 29.3 | AI10: 30.8 | AJ10: 27.7 | AK10: 27.15 | AL10: 28.05 | AM10: 27.6 | AN10: 28.45 | AP10: 28.557407
A11: 35235050 | B11: TAMARA - AUT [35235050] | C11: Casanare | D11: Támara | E11: Area Operativa 06 - Boyacá-Casanare-Vichada | F11: TSSM_MEDIA_D | G11: 5.818583333 | H11: -72.16677778 | I11: 117 | J11: 24.533333 | K11: 24.066667 | L11: 23.733333 | M11: 24.733333 | N11: 23.666667 | O11: 23 | P11: 23.4 | Q11: 23.933333 | R11: 24.133333 | S11: 23.666667 | U11: 23.666667 | X11: 22.766667 | Y11: 23.933333 | Z11: 23.733333 | AA11: 24.133333 | AB11: 24.933333 | AC11: 23.733333 | AD11: 23.933333 | AE11: 23.133333 | AF11: 24.266667 | AL11: 23.733333 | AM11: 23.333333 | AN11: 23.733333 | AP11: 23.821739
A12: 35075040 | B12: INSTITUCION AGRICOLA MACANAL [35075040] | C12: Boyacá | D12: Macanal | E12: Area Operativa 06 - Boyacá-Casanare-Vichada | F12: TSSM_MEDIA_D | G12: 4.974361111 | H12: -73.31675 | I12: 1300 | J12: 18.333333 | K12: 18.133333 | L12: 17.4 | M12: 18.933333 | N12: 17.866667 | O12: 17.533333 | P12: 17.066667 | Q12: 17.466667 | R12: 18.466667 | S12: 18.066667 | T12: 16.866667 | U12: 17.733333 | V12: 17.533333 | W12: 17.066667 | X12: 17.733333 | Y12: 18.866667 | Z12: 19.466667 | AA12: 18.733333 | AB12: 18.133333 | AC12: 19.533333 | AD12: 18.933333 | AE12: 18.2 | AF12: 19.133333 | AG12: 18.466667 | AH12: 19.2 | AI12: 18.6 | AJ12: 19.6 | AK12: 18.866667 | AL12: 17.933333 | AM12: 17.666667 | AN12: 18.266667 | AP12: 18.251613
A13: 23125060 | B13: ALBANIA [23125060] | C13: Santander | D13: Albania | E13: Area Operativa 08 - Santanderes-Arauca | F13: TSSM_MEDIA_D | G13: 5.758333333 | H13: -73.91333333 | I13: 1690 | J13: 22.15 | K13: 19 | L13: 19.65 | M13: 19.85 | N13: 19.3 | O13: 18.15 | P13: 19.5 | Q13: 20.1 | R13: 19.75 | S13: 18.6 | T13: 18.25 | U13: 17.9 | V13: 19.55 | W13: 19.5 | X13: 19 | Y13: 18.25 | Z13: 19.65 | AA13: 20.75 | AB13: 20.35 | AC13: 20.35 | AD13: 20.25 | AE13: 19.25 | AF13: 19.75 | AG13: 19.15 | AH13: 20.1 | AI13: 19.35 | AJ13: 18.95 | AK13: 19.75 | AL13: 19.45 | AM13: 18.7 | AN13: 19.35 | AP13: 19.472581
A14: 23195180 | B14: ESCUELA AGRICOLA CACHIRA [23195180] | C14: Norte De Santander | D14: Cáchira | E14: Area Operativa 08 - Santanderes-Arauca | F14: TSSM_MEDIA_D | G14: 7.735277778 | H14: -73.05166667 | I14: 1882 | Q14: 17.933333 | R14: 17.8 | S14: 16.733333 | V14: 16.866667 | X14: 18.2 | Y14: 16.066667 | Z14: 18.6 | AA14: 19.066667 | AB14: 17.6 | AC14: 17.133333 | AD14: 16.6 | AE14: 17.6 | AJ14: 16.2 | AM14: 17.8 | AN14: 16.666667 | AP14: 17.391111
A15: 16025030 | B15: SALAZAR [16025030] | C15: Norte De Santander | D15: Salazar | E15: Area Operativa 08 - Santanderes-Arauca | F15: TSSM_MEDIA_D | G15: 7.774583333 | H15: -72.83055556 | I15: 860 | J15: 23.333333 | K15: 23 | L15: 23.2 | M15: 24.733333 | N15: 22.266667 | O15: 21.8 | P15: 21.933333 | Q15: 22 | R15: 23.333333 | S15: 21.6 | T15: 22 | U15: 21.333333 | V15: 20.8 | W15: 23 | X15: 24.666667 | Y15: 23.8 | Z15: 23.666667 | AA15: 23.866667 | AB15: 22.133333 | AC15: 21.933333 | AD15: 20.466667 | AE15: 22.4 | AF15: 23 | AG15: 22.466667 | AH15: 21.533333 | AI15: 22.6 | AJ15: 21.466667 | AK15: 20.6 | AL15: 20.733333 | AM15: 22.2 | AN15: 22.866667 | AP15: 22.410753
A16: 12015020 | B16: UNIBAN [12015020] | C16: Antioquia | D16: Apartadó | E16: Area Operativa 01 - Antioquia-Chocó | F16: TSSM_MEDIA_D | G16: 7.825916667 | H16: -76.65133333 | I16: 43 | K16: 26 | L16: 25.5 | M16: 23.9 | N16: 24.65 | O16: 24.7 | P16: 27.4 | Q16: 27.3 | R16: 26.25 | S16: 24.85 | T16: 25.55 | U16: 24.3 | V16: 25.7 | W16: 25.75 | X16: 25.25 | Y16: 26.8 | Z16: 26.9 | AA16: 27.4 | AB16: 26.4 | AC16: 26.9 | AD16: 27.15 | AE16: 26.7 | AF16: 25.9 | AG16: 24.85 | AH16: 27.2 | AI16: 27.75 | AJ16: 26.4 | AK16: 26.25 | AL16: 26.45 | AM16: 25.8 | AN16: 25.35 | AP16: 26.043333
A17: 16025010 | B17: CARMEN DE TONCHALA [16025010] | C17: Norte De Santander | D17: Cúcuta | E17: Area Operativa 08 - Santanderes-Arauca | F17: TSSM_MEDIA_D | G17: 7.848888889 | H17: -72.56611111 | I17: 285 | J17: 28.133333 | K17: 29.333333 | L17: 27.933333 | M17: 27.866667 | N17: 25.2 | O17: 23.866667 | P17: 24.6 | Q17: 26.333333 | R17: 26.266667 | S17: 25.2 | T17: 25.366667 | U17: 24.8 | V17: 24.666667 | W17: 27.066667 | X17: 29.933333 | Y17: 27.733333 | Z17: 28.6 | AA17: 26.6 | AB17: 27.733333 | AC17: 25.733333 | AD17: 25.466667 | AE17: 25.8 | AF17: 26.533333 | AG17: 25.866667 | AH17: 25.6 | AI17: 26.266667 | AJ17: 25.333333 | AK17: 24.533333 | AL17: 26.6 | AM17: 26.533333 | AN17: 27.733333 | AP17: 26.426882
A18: 15085030 | B18: ESCUELA AGRICOLA CARRAIPIA - AUT [15085030] | C18: La Guajira | D18: Maicao | E18: Area Operativa 05 - Magdalena-Cesar-Guajira-San Andrés | F18: TSSM_MEDIA_D | G18: 11.21675 | H18: -72.35994444 | I18: 118 | P18: 26.65 | Q18: 27.1 | R18: 26.9 | S18: 26.85 | T18: 27.35 | U18: 26.85 | V18: 27.3 | W18: 26.8 | X18: 27.85 | Y18: 28.25 | Z18: 28.25 | AA18: 27.8 | AB18: 27.4 | AC18: 27.5 | AD18: 27.55 | AE18: 27.2 | AF18: 28.4 | AG18: 28.4 | AH18: 28.3 | AI18: 27.8 | AJ18: 27.5 | AK18: 26.85 | AL18: 27.2 | AM18: 27.05 | AN18: 28.15 | AP18: 27.49
A19: 27015260 | B19: LA SALADA [27015260] | C19: Antioquia | D19: Caldas | E19: Area Operativa 01 - Antioquia-Chocó | F19: TSSM_MEDIA_D | G19: 6.048361111 | H19: -75.62466667 | I19: 1923 | J19: 18.6 | K19: 17.533333 | L19: 17.866667 | M19: 17.533333 | N19: 16.4 | O19: 17.266667 | P19: 17.066667 | Q19: 16.6 | R19: 18.333333 | S19: 17.266667 | T19: 17.066667 | U19: 16 | V19: 16.2 | W19: 18 | X19: 17.8 | Y19: 18.2 | Z19: 20.133333 | AA19: 18.6 | AB19: 19.566667 | AC19: 18.2 | AD19: 20.533333 | AE19: 18.8 | AF19: 17.933333 | AG19: 18.2 | AH19: 17.066667 | AI19: 17.6 | AJ19: 18.066667 | AK19: 17.8 | AL19: 18.2 | AM19: 17.533333 | AN19: 17.733333 | AP19: 17.86129
A20: 24055030 | B20: ZAPATOCA [24055030] | C20: Santander | D20: Zapatoca | E20: Area Operativa 08 - Santanderes-Arauca | F20: TSSM_MEDIA_D | G20: 6.792777778 | H20: -73.28275 | I20: 1810 | J20: 19.866667 | K20: 19.266667 | L20: 18.933333 | M20: 18.6 | N20: 19.266667 | O20: 18.066667 | P20: 18.866667 | Q20: 19.133333 | R20: 19.4 | S20: 18.866667 | T20: 18.666667 | U20: 17.6 | V20: 18.333333 | W20: 18.866667 | X20: 18.933333 | Y20: 19.466667 | Z20: 19.266667 | AA20: 20.2 | AB20: 20.466667 | AC20: 20 | AD20: 19.8 | AE20: 20.133333 | AF20: 20 | AG20: 19 | AH20: 18.2 | AI20: 19.4 | AJ20: 18.666667 | AK20: 19.333333 | AL20: 19.066667 | AM20: 19.2 | AP20: 19.162222
A21: 24035400 | B21: VOLCAN EL [24035400] | C21: Santander | D21: Cerrito | E21: Area Operativa 08 - Santanderes-Arauca | F21: TSSM_MEDIA_D | G21: 6.845277778 | H21: -72.67777778 | I21: 2841 | J21: 14.133333 | K21: 14.466667 | L21: 13.133333 | M21: 13.133333 | N21: 11.933333 | O21: 13.466667 | P21: 13.2 | Q21: 13.133333 | R21: 13.666667 | S21: 14.066667 | T21: 13.666667 | U21: 13.8 | V21: 13.8 | W21: 14.4 | X21: 14.333333 | Y21: 15 | Z21: 15.466667 | AA21: 15.066667 | AB21: 15.133333 | AC21: 12.533333 | AD21: 14.933333 | AE21: 14.066667 | AF21: 13.266667 | AG21: 14.333333 | AH21: 13.533333 | AI21: 13.333333 | AJ21: 14.266667 | AK21: 13.4 | AL21: 14.8 | AM21: 14.733333 | AN21: 15.133333 | AP21: 13.978495
A22: 23155040 | B22: CENTRO EL [23155040] | C22: Santander | D22: Barrancabermeja | E22: Area Operativa 08 - Santanderes-Arauca | F22: TSSM_MEDIA_D | G22: 6.859555556 | H22: -73.76508333 | I22: 114 | M22: 25.933333 | N22: 26.133333 | O22: 26.333333 | P22: 27.933333 | Q22: 27.333333 | R22: 28.466667 | S22: 29.466667 | T22: 27 | U22: 25.466667 | V22: 27.2 | W22: 26.866667 | X22: 27.533333 | AB22: 28.933333 | AC22: 28.466667 | AD22: 28.4 | AE22: 29.133333 | AF22: 28.4 | AH22: 28.2 | AI22: 27.333333 | AJ22: 26.4 | AN22: 27.066667 | AP22: 27.52381
A23: 24035250 | B23: CHITA - AUT [24035250] | C23: Boyacá | D23: Chita | E23: Area Operativa 06 - Boyacá-Casanare-Vichada | F23: TSSM_MEDIA_D | G23: 6.18778 | H23: -72.46556 | I23: 2961 | J23: 14.2 | K23: 13.2 | L23: 14 | M23: 14.666667 | N23: 12.6 | O23: 12.133333 | P23: 12.933333 | Q23: 12 | R23: 12.2 | S23: 13.4 | T23: 13 | U23: 13.266667 | V23: 13.666667 | W23: 13.333333 | X23: 11.733333 | Y23: 12.4 | Z23: 13.533333 | AA23: 13.733333 | AB23: 12.933333 | AC23: 13.666667 | AD23: 14.666667 | AE23: 13.866667 | AF23: 14 | AG23: 12 | AH23: 13.6 | AK23: 13.333333 | AL23: 13.733333 | AM23: 12.733333 | AN23: 14.933333 | AP23: 13.291954
A24: 23085110 | B24: EL PENOL [23085110] | C24: Antioquia | D24: Peñol | E24: Area Operativa 01 - Antioquia-Chocó | F24: TSSM_MEDIA_D | G24: 6.2138889 | H24: -75.241388889 | I24: 2022 | J24: 19.05 | K24: 18.1 | L24: 18.05 | M24: 18 | N24: 16.4 | O24: 17.1 | P24: 17.4 | Q24: 16.95 | R24: 17.95 | S24: 17.25 | T24: 17.95 | U24: 16.95 | V24: 17.6 | W24: 18.45 | X24: 18.05 | Y24: 17.45 | Z24: 18.65 | AA24: 18.5 | AB24: 18.1 | AC24: 18.45 | AD24: 18.6 | AE24: 18.25 | AF24: 18.05 | AG24: 17.7 | AH24: 17.9 | AI24: 17.7 | AJ24: 17.5 | AK24: 18.05 | AL24: 17.75 | AM24: 18.3 | AN24: 17.55 | AP24: 17.862903
A25: 24015250 | B25: LAJA LA [24015250] | C25: Santander | D25: Guadalupe | E25: Area Operativa 08 - Santanderes-Arauca | F25: TSSM_MEDIA_D | G25: 6.237166667 | H25: -73.41538889 | I25: 1400 | J25: 21.533333 | K25: 21.066667 | L25: 21.066667 | M25: 20.666667 | N25: 21.133333 | O25: 20.666667 | P25: 21 | Q25: 20.933333 | R25: 21.066667 | S25: 21.133333 | T25: 20.866667 | U25: 20.2 | V25: 20.333333 | W25: 20.866667 | X25: 21 | Y25: 20.933333 | Z25: 21.6 | AA25: 21.6 | AB25: 21.6 | AC25: 21.066667 | AD25: 21.466667 | AE25: 21 | AF25: 21.533333 | AG25: 20.333333 | AH25: 21.133333 | AI25: 21.466667 | AJ25: 21 | AK25: 20.466667 | AL25: 21.6 | AM25: 21.266667 | AN25: 21.133333 | AP25: 21.055914
A26: 23125120 | B26: CIMITARRA [23125120] | C26: Santander | D26: Cimitarra | E26: Area Operativa 08 - Santanderes-Arauca | F26: TSSM_MEDIA_D | G26: 6.308611111 | H26: -73.95222222 | I26: 198 | J26: 28.066667 | K26: 26.866667 | L26: 27.6 | M26: 27.933333 | N26: 26.533333 | O26: 26.933333 | P26: 26.933333 | Q26: 26.4 | R26: 28.4 | S26: 26.266667 | T26: 26.333333 | U26: 25.6 | V26: 27.2 | W26: 26.533333 | X26: 27.133333 | Y26: 26.466667 | Z26: 28.533333 | AA26: 29.266667 | AB26: 27.266667 | AC26: 28.266667 | AD26: 28.8 | AE26: 27.266667 | AF26: 27.2 | AG26: 27.466667 | AH26: 27.133333 | AI26: 26.933333 | AJ26: 26.733333 | AK26: 27.4 | AL26: 27.133333 | AM26: 26.333333 | AN26: 26.666667 | AP26: 27.212903
A27: 27015090 | B27: TULIO OSPINA [27015090] | C27: Antioquia | D27: Bello | E27: Area Operativa 01 - Antioquia-Chocó | F27: TSSM_MEDIA_D | G27: 6.319694444 | H27: -75.55325 | I27: 1453 | AK27: 23.6 | AP27: 23.6
A28: 11075020 | B28: URRAO [11075020] | C28: Antioquia | D28: Urrao | E28: Area Operativa 01 - Antioquia-Chocó | F28: TSSM_MEDIA_D | G28: 6.298305556 | H28: -76.143305556 | I28: 1833 | J28: 19.066667 | K28: 19.8 | L28: 19.533333 | M28: 19.2 | N28: 19.133333 | O28: 18.266667 | P28: 19.333333 | Q28: 18.866667 | R28: 19.133333 | S28: 18.6 | T28: 19.066667 | U28: 18.8 | V28: 18.8 | W28: 18.533333 | X28: 19.066667 | Y28: 18.4 | Z28: 17.133333 | AA28: 19.333333 | AB28: 19.933333 | AC28: 19.4 | AD28: 18.866667 | AE28: 20.2 | AF28: 18.8 | AG28: 18.866667 | AH28: 19.133333 | AI28: 19.266667 | AJ28: 19 | AK28: 19.066667 | AL28: 19.333333 | AM28: 19.2 | AN28: 19.066667 | AP28: 19.03871
A29: 24035330 | B29: BOAVITA [24035330] | C29: Boyacá | D29: Boavita | E29: Area Operativa 06 - Boyacá-Casanare-Vichada | F29: TSSM_MEDIA_D | G29: 6.328972222 | H29: -72.58227778 | I29: 2150 | J29: 19.133333 | K29: 17.333333 | L29: 16.533333 | M29: 17 | N29: 17.066667 | O29: 18.2 | P29: 16.2 | Q29: 16.6 | R29: 16.866667 | S29: 16.2 | T29: 16.666667 | U29: 16.533333 | V29: 15.533333 | W29: 16.533333 | X29: 16.466667 | Y29: 16.666667 | Z29: 18.333333 | AA29: 18.533333 | AB29: 19.2 | AC29: 18.533333 | AD29: 19.066667 | AE29: 18.533333 | AF29: 18.466667 | AG29: 17.333333 | AH29: 18.333333 | AI29: 17.733333 | AJ29: 17.333333 | AK29: 17 | AL29: 18.4 | AM29: 18.4 | AN29: 18.333333 | AP29: 17.51828
A30: 26205080 | B30: LA ALDEA [26205080] | C30: Antioquia | D30: Medellín | E30: Area Operativa 01 - Antioquia-Chocó | F30: TSSM_MEDIA_D | G30: 6.341055556 | H30: -75.70094444 | I30: 1737 | J30: 21.866667 | K30: 19.6 | L30: 18.466667 | M30: 19.066667 | N30: 19.333333 | O30: 18.866667 | P30: 19.4 | Q30: 17.6 | R30: 19 | S30: 18.733333 | T30: 18.333333 | U30: 17.533333 | V30: 18.6 | W30: 20.633333 | X30: 18 | Y30: 18.8 | Z30: 21.6 | AA30: 22.133333 | AB30: 20.466667 | AC30: 20.4 | AD30: 20.8 | AE30: 20.066667 | AF30: 20.2 | AG30: 20.6 | AH30: 19.666667 | AI30: 19.2 | AJ30: 18.866667 | AL30: 20.666667 | AM30: 18.466667 | AN30: 19.533333 | AP30: 19.55
A31: 24015260 | B31: CHIMA [24015260] | C31: Santander | D31: Chima | E31: Area Operativa 08 - Santanderes-Arauca | F31: TSSM_MEDIA_D | G31: 6.355 | H31: -73.36833333 | I31: 190 | J31: 25.45 | K31: 24.75 | L31: 25.7 | M31: 25.5 | N31: 25.05 | O31: 25 | P31: 24.35 | Q31: 24.95 | R31: 25.45 | S31: 25.25 | T31: 24.95 | U31: 23.25 | V31: 24.3 | W31: 25.05 | X31: 24.45 | Y31: 24.6 | Z31: 25.8 | AA31: 26 | AB31: 25.35 | AC31: 25.9 | AD31: 26.25 | AE31: 25.65 | AF31: 25.85 | AG31: 25.05 | AH31: 25 | AI31: 25.1 | AJ31: 24.85 | AK31: 25.55 | AL31: 25.5 | AM31: 25.85 | AN31: 25.35 | AP31: 25.196774
A32: 23085030 | B32: ALEJANDRIA [23085030] | C32: Antioquia | D32: Alejandría | E32: Area Operativa 01 - Antioquia-Chocó | F32: TSSM_MEDIA_D | G32: 6.37625 | H32: -75.14338889 | I32: 1712 | J32: 19.533333 | K32: 20.066667 | L32: 20.4 | M32: 20.8 | N32: 19.866667 | O32: 19.6 | P32: 19.533333 | Q32: 19.133333 | R32: 19.866667 | S32: 20.333333 | T32: 19.466667 | U32: 19.8 | V32: 20.2 | W32: 19.933333 | X32: 20.4 | Y32: 20.333333 | Z32: 21.133333 | AA32: 21.066667 | AB32: 20.333333 | AC32: 20.533333 | AD32: 20.466667 | AE32: 20.133333 | AF32: 21.066667 | AG32: 20.333333 | AH32: 20 | AI32: 19.733333 | AJ32: 20.4 | AK32: 20.333333 | AL32: 20.066667 | AM32: 20.666667 | AN32: 20.133333 | AP32: 20.182796
A33: 36025010 | B33: TAME [36025010] | C33: Arauca | D33: Tame | E33: Area Operativa 06 - Boyacá-Casanare-Vichada | F33: TSSM_MEDIA_D | G33: 6.456194444 | H33: -71.74502778 | I33: 350 | K33: 27.4 | L33: 26 | M33: 26.733333 | N33: 27.866667 | O33: 27.466667 | P33: 24.933333 | Q33: 25.466667 | R33: 26.733333 | S33: 26.2 | T33: 25.8 | U33: 26.533333 | V33: 23.2 | W33: 26.533333 | X33: 27.333333 | Y33: 27.933333 | Z33: 28.033333 | AA33: 26.2 | AB33: 26.866667 | AC33: 26.933333 | AD33: 27.533333 | AE33: 26.266667 | AF33: 28.666667 | AG33: 28.2 | AH33: 27.8 | AI33: 27.533333 | AJ33: 23.933333 | AK33: 24.133333 | AL33: 26.466667 | AM33: 25.266667 | AN33: 26.866667 | AP33: 26.561111
A34: 24035070 | B34: GUICAN [24035070] | C34: Boyacá | D34: Guicán | E34: Area Operativa 06 - Boyacá-Casanare-Vichada | F34: TSSM_MEDIA_D | G34: 6.463472222 | H34: -72.40919444 | I34: 2963 | J34: 14.566667 | K34: 13.933333 | L34: 13.433333 | M34: 13.166667 | N34: 13.666667 | O34: 12.466667 | P34: 12.9 | Q34: 13.233333 | R34: 13.633333 | S34: 13.533333 | T34: 13.033333 | U34: 13.166667 | V34: 13.466667 | W34: 14.533333 | X34: 13.9 | Y34: 14.366667 | Z34: 14.2 | AA34: 14.1 | AB34: 14.733333 | AC34: 14.566667 | AD34: 13.933333 | AE34: 13.833333 | AF34: 14.233333 | AG34: 13.7 | AH34: 14.4 | AI34: 13.7 | AJ34: 11.966667 | AK34: 14.266667 | AL34: 14.4 | AM34: 13.7 | AN34: 14.4 | AP34: 13.778495
A35: 24025040 | B35: ESCUELA AGRICOLA MOGOTES [24025040] | C35: Santander | D35: Mogotes | E35: Area Operativa 08 - Santanderes-Arauca | F35: TSSM_MEDIA_D | G35: 6.47 | H35: -72.96888889 | I35: 1673 | J35: 19.4 | K35: 19.4 | L35: 19.2 | M35: 18.4 | N35: 18.6 | O35: 18.533333 | P35: 18.4 | Q35: 18.4 | R35: 19.333333 | S35: 18.333333 | T35: 18.666667 | U35: 19.333333 | V35: 18.333333 | W35: 19.4 | X35: 18.666667 | Y35: 19.4 | Z35: 19.8 | AC35: 18.866667 | AD35: 18.8 | AE35: 19.6 | AF35: 18.666667 | AG35: 18.533333 | AH35: 18.6 | AI35: 18.733333 | AJ35: 19.266667 | AK35: 20.2 | AL35: 19.866667 | AM35: 19.666667 | AN35: 19 | AP35: 19.013793
A36: 23085080 | B36: GRANJA EXPERIMENTAL EL NUS [23085080] | C36: Antioquia | D36: San Roque | E36: Area Operativa 01 - Antioquia-Chocó | F36: TSSM_MEDIA_D | G36: 6.483583333 | H36: -74.83669444 | I36: 859 | J36: 23.2 | K36: 24 | L36: 23.95 | M36: 22.15 | N36: 22.85 | O36: 22.6 | P36: 23.1 | Q36: 23.85 | R36: 23.45 | S36: 23 | T36: 22.45 | U36: 22.55 | V36: 22.55 | W36: 23.9 | X36: 23.3 | Y36: 22.5 | Z36: 24.15 | AA36: 24 | AB36: 22.55 | AC36: 24.2 | AD36: 23.55 | AE36: 23.6 | AF36: 23.15 | AG36: 22.85 | AH36: 22.85 | AI36: 24.55 | AJ36: 23.7 | AK36: 23 | AL36: 22.55 | AM36: 23.3 | AN36: 23.3 | AP36: 23.248387
A37: 24035260 | B37: CAPITANEJO [24035260] | C37: Santander | D37: Capitanejo | E37: Area Operativa 06 - Boyacá-Casanare-Vichada | F37: TSSM_MEDIA_D | G37: 6.520722222 | H37: -72.69661111 | I37: 1160 | J37: 28.133333 | K37: 26 | L37: 25.533333 | M37: 24.666667 | N37: 25.133333 | O37: 24.266667 | P37: 24.6 | Q37: 25.333333 | R37: 26.333333 | S37: 25.6 | T37: 25.733333 | U37: 24.6 | V37: 26.333333 | W37: 25.4 | X37: 25.4 | Y37: 25.866667 | Z37: 27.133333 | AA37: 28.133333 | AB37: 27.266667 | AC37: 27.2 | AD37: 26.733333 | AE37: 27.2 | AF37: 28.266667 | AG37: 27.133333 | AH37: 26.866667 | AI37: 27.2 | AJ37: 24.933333 | AN37: 25.466667 | AP37: 26.159524
A38: 24035310 | B38: CHISCAS [24035310] | C38: Boyacá | D38: Chiscas | E38: Area Operativa 06 - Boyacá-Casanare-Vichada | F38: TSSM_MEDIA_D | G38: 6.549527778 | H38: -72.50472222 | I38: 2350 | J38: 15.6 | K38: 15.7 | L38: 14.966667 | M38: 14.833333 | N38: 14.833333 | O38: 14.8 | P38: 14.266667 | Q38: 15.866667 | R38: 14.9 | S38: 15.3 | V38: 14.9 | W38: 17.566667 | X38: 17.633333 | Y38: 20.066667 | Z38: 18.233333 | AA38: 16.3 | AB38: 15.366667 | AC38: 14.533333 | AD38: 15.566667 | AE38: 16.5 | AF38: 16.866667 | AG38: 16.866667 | AH38: 16.2 | AP38: 15.985507
A39: 24055040 | B39: PALMAR EL [24055040] | C39: Santander | D39: Palmar | E39: Area Operativa 08 - Santanderes-Arauca | F39: TSSM_MEDIA_D | G39: 6.549722222 | H39: -73.292 | I39: 940 | J39: 27.75 | K39: 27.45 | L39: 26.8 | M39: 26.4 | N39: 26.9 | O39: 26.6 | P39: 27.05 | Q39: 27.15 | R39: 27.3 | S39: 25.9 | T39: 26.35 | U39: 26.55 | V39: 25.85 | W39: 26.15 | X39: 27 | Y39: 27.35 | Z39: 27.8 | AA39: 28.1 | AB39: 28.45 | AC39: 27.75 | AD39: 28.5 | AE39: 28.6 | AF39: 27.75 | AG39: 26.55 | AH39: 27.65 | AI39: 27.2 | AJ39: 27.1 | AK39: 27 | AL39: 26.8 | AM39: 27 | AN39: 26.5 | AP39: 27.13871
A40: 23125050 | B40: CARARE [23125050] | C40: Santander | D40: Puerto Parra | E40: Area Operativa 08 - Santanderes-Arauca | F40: TSSM_MEDIA_D | G40: 6.649444444 | H40: -74.06138889 | I40: 168 | J40: 28.133333 | K40: 27.466667 | L40: 27.133333 | M40: 27.333333 | N40: 28.333333 | O40: 28.4 | R40: 29.4 | S40: 27.8 | AP40: 28
...

Sheet Climatologia_TMED
A1: INFORMACIÓN GENERAL ESTACIONES | J1: NORMAL CLIMATOLÓGICA ESTÁNDAR DE LA TEMPERATURA MEDIA PARA EL PERIODO 1991-2020 (°C) | W1: Cumplen la directriz No 1203 del 2017 de la OMM | AA1: Mes | AB1: Nombre | AC1: Días
A2: CÓDIGO | B2: CATEGORÍA | C2: NOMBRE | D2: MUNICIPIO | E2: DEPARTAMENTO | F2: AO | G2: ELEVACIÓN (m) | H2: LONGITUD | I2: LATITUD | J2: ENE | K2: FEB | L2: MAR | M2: ABR | N2: MAY | O2: JUN | P2: JUL | Q2: AGO | R2: SEP | S2: OCT | T2: NOV | U2: DIC | V2: ANUAL | W2: Número de meses | X2: % de cumplimiento | AA2: 1 | AB2: ENERO | AC2: 31
A3: 48015050 | B3: SP | C3: Aeropuerto Vásquez Cobo | D3: Leticia | E3: Amazonas | F3: 11 | G3: 84 | H3: -69.940917 | I3: -4.1938611 | J3: 26.085174 | K3: 26.108177 | L3: 26.156511 | M3: 26.124859 | N3: 25.909813 | O3: 25.39885 | P3: 25.368949 | Q3: 25.960297 | R3: 26.375668 | S3: 26.594524 | T3: 26.520375 | U3: 26.220827 | V3: 26.068669 | W3: 313 | X3: 0.86944444 | AA3: 2 | AB3: FEBRERO | AC3: 28
A4: 23085030 | B4: CO | C4: Alejandría | D4: Alejandría | E4: Antioquia | F4: 1 | G4: 1712 | H4: -75.143389 | I4: 6.37625 | J4: 19.439403 | K4: 19.463612 | L4: 19.559946 | M4: 19.638992 | N4: 19.820966 | O4: 19.797733 | P4: 19.787198 | Q4: 19.861807 | R4: 19.739292 | S4: 19.457461 | T4: 19.441878 | U4: 19.409182 | V4: 19.618123 | W4: 352 | X4: 0.97777778 | AA4: 3 | AB4: MARZO | AC4: 31
A5: 26195020 | B5: PM | C5: Ita Andes | D5: Andes | E5: Antioquia | F5: 1 | G5: 1180 | H5: -75.880222 | I5: 5.691 | J5: 22.166784 | K5: 22.662346 | L5: 22.569536 | M5: 22.22114 | N5: 22.027244 | O5: 21.899252 | P5: 21.873026 | Q5: 21.923675 | R5: 21.739445 | S5: 21.604313 | T5: 21.61131 | U5: 21.723519 | V5: 22.001799 | W5: 306 | X5: 0.85 | AA5: 4 | AB5: ABRIL | AC5: 30
A6: 27025030 | B6: CO | C6: Anorí | D6: Anorí | E6: Antioquia | F6: 1 | G6: 1601 | H6: -75.150528 | I6: 7.0719167 | J6: 18.696273 | K6: 18.801756 | L6: 18.995495 | M6: 19.313351 | N6: 19.641322 | O6: 19.89447 | P6: 19.968575 | Q6: 20.010286 | R6: 19.561235 | S6: 19.13126 | T6: 18.837092 | U6: 18.749848 | V6: 19.30008 | W6: 312 | X6: 0.86666667 | AA6: 5 | AB6: MAYO | AC6: 31
A7: 12015020 | B7: AM | C7: Uniban | D7: Apartadó | E7: Antioquia | F7: 1 | G7: 43 | H7: -76.651333 | I7: 7.8259167 | J7: 26.650864 | K7: 26.862929 | L7: 27.038561 | M7: 27.071348 | N7: 26.984341 | O7: 26.879616 | P7: 26.827472 | Q7: 26.885476 | R7: 26.682698 | S7: 26.480026 | T7: 26.39194 | U7: 26.466597 | V7: 26.768489 | W7: 342 | X7: 0.95 | AA7: 6 | AB7: JUNIO | AC7: 30
A8: 12045010 | B8: CP | C8: Arboletes | D8: Arboletes | E8: Antioquia | F8: 2 | G8: 4 | H8: -76.431944 | I8: 8.8469444 | J8: 27.536242 | K8: 27.83698 | L8: 27.883739 | M8: 28.057423 | N8: 27.623098 | O8: 27.793961 | P8: 27.752686 | Q8: 27.517115 | R8: 27.293075 | S8: 27.174029 | T8: 27.207002 | U8: 27.566788 | V8: 27.603511 | W8: 111 | X8: 0.925 | AA8: 7 | AB8: JULIO | AC8: 31
A9: 27015090 | B9: CO | C9: Tulio Ospina | D9: Bello | E9: Antioquia | F9: 1 | G9: 1453 | H9: -75.55325 | I9: 6.3196944 | J9: 22.091988 | K9: 22.669161 | L9: 22.471452 | M9: 22.361298 | N9: 22.390786 | O9: 22.652805 | P9: 22.851791 | Q9: 22.984159 | R9: 22.425573 | S9: 21.706254 | T9: 21.524249 | U9: 21.863012 | V9: 22.332711 | W9: 326 | X9: 0.90555556 | AA9: 8 | AB9: AGOSTO | AC9: 31
A10: 26225040 | B10: CO | C10: Hacienda Piunti | D10: Buriticá | E10: Antioquia | F10: 1 | G10: 1650 | H10: -75.912972 | I10: 6.7295 | J10: 21.366581 | K10: 21.60111 | L10: 21.595055 | M10: 21.217564 | N10: 20.926444 | O10: 20.879438 | P10: 20.986371 | Q10: 21.017987 | R10: 20.846107 | S10: 20.538089 | T10: 20.606095 | U10: 20.784936 | V10: 21.030481 | W10: 227 | X10: 0.94583333 | AA10: 9 | AB10: SEPTIEMBRE | AC10: 30
A11: 27015260 | B11: AM | C11: La Salada | D11: Caldas | E11: Antioquia | F11: 1 | G11: 1923 | H11: -75.624667 | I11: 6.0483611 | J11: 18.152745 | K11: 18.420099 | L11: 18.44749 | M11: 18.191389 | N11: 18.202649 | O11: 18.426217 | P11: 18.492109 | Q11: 18.507205 | R11: 18.027767 | S11: 17.809526 | T11: 17.572124 | U11: 17.928154 | V11: 18.181456 | W11: 298 | X11: 0.82777778 | AA11: 10 | AB11: OCTUBRE | AC11: 31
A12: 11115020 | B12: CO | C12: Cañasgordas - Aut | D12: Cañasgordas | E12: Antioquia | F12: 1 | G12: 1294 | H12: -76.029667 | I12: 6.7580278 | J12: 21.581866 | K12: 21.598939 | L12: 21.686227 | M12: 21.518054 | N12: 21.385314 | O12: 21.559922 | P12: 21.597024 | Q12: 21.696395 | R12: 21.455748 | S12: 21.019762 | T12: 21.078845 | U12: 21.350034 | V12: 21.460677 | W12: 337 | X12: 0.93611111 | AA12: 11 | AB12: NOVIEMBRE | AC12: 30
A13: 12015070 | B13: SP | C13: Aeropuerto Los Cedros | D13: Carepa | E13: Antioquia | F13: 1 | G13: 41 | H13: -76.717889 | I13: 7.8163889 | J13: 27.282793 | K13: 27.339785 | L13: 27.403673 | M13: 27.578406 | N13: 27.582963 | O13: 27.688536 | P13: 27.637653 | Q13: 27.745849 | R13: 27.412401 | S13: 27.208269 | T13: 27.080774 | U13: 27.150424 | V13: 27.425961 | W13: 327 | X13: 0.90833333 | AA13: 12 | AB13: DICIEMBRE | AC13: 31
A14: 12015060 | B14: CO | C14: Tulenapa | D14: Carepa | E14: Antioquia | F14: 1 | G14: 39 | H14: -76.67 | I14: 7.77 | J14: 26.633025 | K14: 26.795576 | L14: 26.964239 | M14: 27.144452 | N14: 26.991432 | O14: 26.889423 | P14: 26.853707 | Q14: 26.855174 | R14: 26.747469 | S14: 26.604295 | T14: 26.455186 | U14: 26.506753 | V14: 26.786727 | W14: 228 | X14: 0.95
A15: 27045020 | B15: CO | C15: Caseri | D15: Caucasia | E15: Antioquia | F15: 1 | G15: 72 | H15: -74.935972 | I15: 7.8117222 | J15: 27.976768 | K15: 28.138513 | L15: 28.222161 | M15: 28.013863 | N15: 27.825908 | O15: 27.903416 | P15: 27.917161 | Q15: 27.847153 | R15: 27.668783 | S15: 27.683753 | T15: 27.449367 | U15: 27.695889 | V15: 27.861894 | W15: 204 | X15: 0.85
A16: 11025010 | B16: CO | C16: La Mansa | D16: Ciudad Bolívar | E16: Antioquia | F16: 1 | G16: 2018 | H16: -76.084333 | I16: 5.8783056 | J16: 16.896215 | K16: 17.053446 | L16: 17.119351 | M16: 17.179944 | N16: 17.151431 | O16: 17.057127 | P16: 17.045877 | Q16: 17.031295 | R16: 16.811354 | S16: 16.587058 | T16: 16.568317 | U16: 16.791396 | V16: 16.941068 | W16: 347 | X16: 0.96388889
A17: 26215010 | B17: CO | C17: Concordia | D17: Concordia | E17: Antioquia | F17: 1 | G17: 2032 | H17: -75.919528 | I17: 6.0395556 | J17: 18.950975 | K17: 19.246407 | L17: 19.120945 | M17: 18.878526 | N17: 18.920508 | O17: 19.228169 | P17: 19.223499 | Q17: 19.14161 | R17: 18.82627 | S17: 18.327525 | T17: 18.049689 | U17: 18.522927 | V17: 18.869754 | W17: 325 | X17: 0.90277778
A18: 27015150 | B18: CO | C18: Hacienda El Progreso | D18: Don Matías | E18: Antioquia | F18: 1 | G18: 1345 | H18: -75.397167 | I18: 6.4474722 | J18: 22.124708 | K18: 22.086855 | L18: 22.13824 | M18: 22.081855 | N18: 22.424476 | O18: 22.262604 | P18: 22.237047 | Q18: 22.418273 | R18: 22.342848 | S18: 22.177379 | T18: 22.278433 | U18: 22.151675 | V18: 22.227033 | W18: 118 | X18: 0.98333333
A19: 26175040 | B19: CO | C19: Hacienda Tunez | D19: Fredonia | E19: Antioquia | F19: 1 | G19: 604 | H19: -75.650972 | I19: 5.80025 | J19: 26.124143 | K19: 26.74093 | L19: 26.723077 | M19: 26.180773 | N19: 25.820623 | O19: 25.781737 | P19: 25.88623 | Q19: 26.093413 | R19: 25.832924 | S19: 25.484403 | T19: 25.504761 | U19: 25.703462 | V19: 25.989706 | W19: 289 | X19: 0.80277778
A20: 11115040 | B20: CO | C20: Musinga | D20: Frontino | E20: Antioquia | F20: 1 | G20: 1396 | H20: -76.203333 | I20: 6.7779722 | J20: 20.260985 | K20: 20.433287 | L20: 20.556792 | M20: 20.462708 | N20: 20.416507 | O20: 20.410893 | P20: 20.349111 | Q20: 20.36895 | R20: 20.300168 | S20: 20.142025 | T20: 20.078751 | U20: 20.160398 | V20: 20.328381 | W20: 353 | X20: 0.98055556
A21: 26195030 | B21: CO | C21: El Jardín | D21: Jardín | E21: Antioquia | F21: 1 | G21: 2161 | H21: -75.800556 | I21: 5.5877222 | J21: 17.180686 | K21: 17.395641 | L21: 17.440058 | M21: 17.29258 | N21: 17.219545 | O21: 17.23416 | P21: 17.181899 | Q21: 17.08486 | R21: 16.957726 | S21: 16.788819 | T21: 16.792722 | U21: 17.012144 | V21: 17.131737 | W21: 287 | X21: 0.79722222
A22: 26185020 | B22: CO | C22: Mesopotamia | D22: La Unión | E22: Antioquia | F22: 1 | G22: 2408 | H22: -75.318639 | I22: 5.8863611 | J22: 14.656851 | K22: 14.907681 | L22: 15.056664 | M22: 15.20128 | N22: 15.344646 | O22: 15.227834 | P22: 15.017929 | Q22: 15.085211 | R22: 14.973387 | S22: 14.761223 | T22: 14.63759 | U22: 14.669181 | V22: 14.961623 | W22: 360 | X22: 1
A23: 27015330 | B23: SP | C23: Aeropuerto Olaya Herrera - AUT | D23: Medellín | E23: Antioquia | F23: 1 | G23: 1490 | H23: -75.59 | I23: 6.22 | J23: 23.023437 | K23: 23.340606 | L23: 23.074807 | M23: 22.806906 | N23: 22.950101 | O23: 23.664186 | P23: 23.983624 | Q23: 23.942684 | R23: 23.202497 | S23: 22.205912 | T23: 21.956184 | U23: 22.455704 | V23: 23.050554 | W23: 346 | X23: 0.96111111
A24: 12015010 | B24: CO | C24: Villarteaga | D24: Mutatá | E24: Antioquia | F24: 1 | G24: 132 | H24: -76.486028 | I24: 7.3346667 | J24: 26.146996 | K24: 26.220101 | L24: 26.144473 | M24: 26.229575 | N24: 26.029573 | O24: 25.972648 | P24: 25.792511 | Q24: 25.842042 | R24: 26.066213 | S24: 25.816349 | T24: 25.723963 | U24: 25.81239 | V24: 25.98307 | W24: 109 | X24: 0.90833333
