Workbook

Sheet Temperatura
A2: VARIABLE | B2: TEMPERATURA MAXIMA (°C) | C2: MES | D2: =VLOOKUP(E2,Maximos_TMAX!AS1:AU13,2,FALSE) -> JULIO | E2: 7 | F2: AÑO | G2: 2026 | H2: DIAS | I2: =VLOOKUP(E2,Maximos_TMAX!AS1:AU13,3,FALSE) -> 31 | J2: Máximo | K2: =MAX(K5:K287) -> 40 | L2: =MAX(L5:L287) -> 39.2 | M2: =MAX(M5:M287) -> 37.6 | N2: =MAX(N5:N287) -> 36.2 | O2: =MAX(O5:O287) -> 39.4 | P2: =MAX(P5:P287) -> 40 | Q2: =MAX(Q5:Q287) -> 41 | R2: =MAX(R5:R287) -> 40.6 | ... AO2: =MAX(AO5:AO287) -> 0 | AP2: =MAX(K2:AO2) -> 42
A4: CODIGO | B4: ESTACION | C4: AREA_OP | D4: LON | E4: LAT | F4: ELEV | G4: COD_DPTO | H4: COD_MUNICIPIO | I4: DEPARTAMENTO | J4: MUNICIPIO | K4: 1 | L4: 2 | M4: 3 | N4: 4 | O4: 5 | P4: 6 | Q4: 7 | R4: 8 | S4: 9 | T4: 10 | U4: 11 | V4: 12 | W4: 13 | X4: 14 | Y4: 15 | Z4: 16 | AA4: 17 | AB4: 18 | AC4: 19 | AD4: 20 | AE4: 21 | AF4: 22 | AG4: 23 | AH4: 24 | AI4: 25 | AJ4: 26 | AK4: 27 | AL4: 28 | AM4: 29 | AN4: 30 | AO4: 31 | AP4: NUM_DATOS | AQ4: MEDIA_MENSUAL | AR4: MEDIA_MULTIANUAL | AS4: ANOMALIA | AT4: MAX_MES | AU4: MAX_HISTORICO | AV4: FECHA | AW4: DIFERENCIA
A5: 17015010 | B5: Aeropuerto Sesquicentenario | C5: Met_Aeronautica | D5: -81.703889 | E5: 12.586944 | F5: 1 | G5: 88 | H5: 88001 | I5: Archipiélago de San Andres, Providencia y Santa Catalina | J5: Isla de San Andrés | K5: 32.3 | L5: 32.3 | M5: 31.4 | N5: 29.3 | O5: 30.6 | P5: 32.1 | Q5: 31.7 | R5: 31.7 | S5: 32.1 | T5: 31.1 | U5: 31.6 | V5: 31.9 | W5: 29.6 | X5: 30.3 | Y5: 29.9 | Z5: 31 | AA5: 31.9 | AB5: 30.9 | AP5: =COUNTIF(K5:AO5,">0") -> 18 | AQ5: =IF(AP5>14,AVERAGE(K5:AO5),"") -> 31.205556 | AR5: =IFERROR(VLOOKUP(A5,Climatologia_TMAX!A:U,9+$E$2,FALSE),"") -> 30.197372 | AS5: =IF(OR(AQ5="",AR5=""),"",IFERROR(AQ5-AR5,"")) -> 1.0081838 | AT5: =IF(COUNT(K5:AO5)=0,"",MAX(K5:AO5)) -> 32.3 | AU5: {=IFERROR( _xlfn.LET( _xlpm.mesTxt, INDEX({"ENERO","FEBRERO","MARZO","ABRIL","MAYO","JUNIO","JULIO","AGOSTO","SEPTIEMBRE","OCTUBRE","NOVIEMBRE","DICIEMBRE"}, E$2), _xlpm.colIni, MATCH(_xlpm.mesTxt, Maximos_TMAX!$1:$1, 0), _xlpm.fila, MATCH($A5, Maximos_TMAX!$A:$A, 0), _xlpm.val, INDEX(Maximos_TMAX!$A:$ZZ, _xlpm.fila, _xlpm.colIni), IF(_xlpm.val="", "", _xlpm.val) ), "")} -> 32.7 | AV5: {=IFERROR( _xlfn.LET( _xlpm.mesNum, E$2, _xlpm.mesTxt, INDEX({"ENERO","FEBRERO","MARZO","ABRIL","MAYO","JUNIO","JULIO","AGOSTO","SEPTIEMBRE","OCTUBRE","NOVIEMBRE","DICIEMBRE"}, _xlpm.mesNum), _xlpm.colIni, MATCH(_xlpm.mesTxt, Maximos_TMAX!$1:$1, 0), _xlpm.fila, MATCH($A5, Maximos_TMAX!$A:$A, 0), _xlpm.anio, INDEX(Maximos_TMAX!$A:$ZZ, _xlpm.fila, _xlpm.colIni+1), _xlpm.dia, INDEX(Maximos_TMAX!$A:$ZZ, _xlpm.fila, _xlpm.colIni+2), IF(OR(_xlpm.anio="",_xlpm.dia=""), "", DATE(_xlpm.anio, _xlpm.mesNum, _xlpm.dia)) ), "")} -> 41467 | AW5: =IF(OR(AT5="",AU5=""),"NA",IFERROR(AT5-AU5,"NA")) -> -0.4
A6: 17025020 | B6: Aeropuerto El Embrujo | C6: Met_Aeronautica | D6: -81.357722 | E6: 13.3595 | F6: 7 | G6: 88 | H6: 88564 | I6: Archipiélago de San Andres, Providencia y Santa Catalina | J6: Isla de Providencia | K6: 30.4 | L6: 31.5 | M6: 32 | N6: 29.5 | O6: 30 | P6: 30.8 | Q6: 31 | R6: 30.7 | S6: 31 | T6: 30.4 | U6: 31.2 | V6: 30.8 | W6: 29.2 | X6: 29.7 | Y6: 29.8 | Z6: 31.5 | AA6: 31.2 | AB6: 31.1 | AP6: =COUNTIF(K6:AO6,">0") -> 18 | AQ6: =IF(AP6>14,AVERAGE(K6:AO6),"") -> 30.655556 | AR6: =IFERROR(VLOOKUP(A6,Climatologia_TMAX!A:U,9+$E$2,FALSE),"") -> 30.65428 | AS6: =IF(OR(AQ6="",AR6=""),"",IFERROR(AQ6-AR6,"")) -> 0.0012751585 | AT6: =IF(COUNT(K6:AO6)=0,"",MAX(K6:AO6)) -> 32 | AU6: {=IFERROR( _xlfn.LET( _xlpm.mesTxt, INDEX({"ENERO","FEBRERO","MARZO","ABRIL","MAYO","JUNIO","JULIO","AGOSTO","SEPTIEMBRE","OCTUBRE","NOVIEMBRE","DICIEMBRE"}, E$2), _xlpm.colIni, MATCH(_xlpm.mesTxt, Maximos_TMAX!$1:$1, 0), _xlpm.fila, MATCH($A6, Maximos_TMAX!$A:$A, 0), _xlpm.val, INDEX(Maximos_TMAX!$A:$ZZ, _xlpm.fila, _xlpm.colIni), IF(_xlpm.val="", "", _xlpm.val) ), "")} -> 32.5 | AV6: {=IFERROR( _xlfn.LET( _xlpm.mesNum, E$2, _xlpm.mesTxt, INDEX({"ENERO","FEBRERO","MARZO","ABRIL","MAYO","JUNIO","JULIO","AGOSTO","SEPTIEMBRE","OCTUBRE","NOVIEMBRE","DICIEMBRE"}, _xlpm.mesNum), _xlpm.colIni, MATCH(_xlpm.mesTxt, Maximos_TMAX!$1:$1, 0), _xlpm.fila, MATCH($A6, Maximos_TMAX!$A:$A, 0), _xlpm.anio, INDEX(Maximos_TMAX!$A:$ZZ, _xlpm.fila, _xlpm.colIni+1), _xlpm.dia, INDEX(Maximos_TMAX!$A:$ZZ, _xlpm.fila, _xlpm.colIni+2), IF(OR(_xlpm.anio="",_xlpm.dia=""), "", DATE(_xlpm.anio, _xlpm.mesNum, _xlpm.dia)) ), "")} -> 38549 | AW6: =IF(OR(AT6="",AU6=""),"NA",IFERROR(AT6-AU6,"NA")) -> -0.5
A7: 15015050 | B7: Aeropuerto Simón Bolívar | C7: Met_Aeronautica | D7: -74.228889 | E7: 11.128333 | F7: 4 | G7: 47 | H7: 47001 | I7: Magdalena | J7: Santa Marta | K7: 36.2 | L7: 36.8 | M7: 33.5 | N7: 31.4 | O7: 35.2 | P7: 36.4 | Q7: 37.9 | R7: 38.4 | S7: 33 | T7: 34.2 | U7: 37.2 | V7: 36.6 | W7: 36.2 | X7: 37 | Y7: 38.6 | Z7: 38.3 | AA7: 38.6 | AB7: 35.8 | AP7: =COUNTIF(K7:AO7,">0") -> 18 | AQ7: =IF(AP7>14,AVERAGE(K7:AO7),"") -> 36.183333 | AR7: =IFERROR(VLOOKUP(A7,Climatologia_TMAX!A:U,9+$E$2,FALSE),"") -> 33.366016 | AS7: =IF(OR(AQ7="",AR7=""),"",IFERROR(AQ7-AR7,"")) -> 2.8173173 | AT7: =IF(COUNT(K7:AO7)=0,"",MAX(K7:AO7)) -> 38.6 | AU7: {=IFERROR( _xlfn.LET( _xlpm.mesTxt, INDEX({"ENERO","FEBRERO","MARZO","ABRIL","MAYO","JUNIO","JULIO","AGOSTO","SEPTIEMBRE","OCTUBRE","NOVIEMBRE","DICIEMBRE"}, E$2), _xlpm.colIni, MATCH(_xlpm.mesTxt, Maximos_TMAX!$1:$1, 0), _xlpm.fila, MATCH($A7, Maximos_TMAX!$A:$A, 0), _xlpm.val, INDEX(Maximos_TMAX!$A:$ZZ, _xlpm.fila, _xlpm.colIni), IF(_xlpm.val="", "", _xlpm.val) ), "")} -> 38.4 | AV7: {=IFERROR( _xlfn.LET( _xlpm.mesNum, E$2, _xlpm.mesTxt, INDEX({"ENERO","FEBRERO","MARZO","ABRIL","MAYO","JUNIO","JULIO","AGOSTO","SEPTIEMBRE","OCTUBRE","NOVIEMBRE","DICIEMBRE"}, _xlpm.mesNum), _xlpm.colIni, MATCH(_xlpm.mesTxt, Maximos_TMAX!$1:$1, 0), _xlpm.fila, MATCH($A7, Maximos_TMAX!$A:$A, 0), _xlpm.anio, INDEX(Maximos_TMAX!$A:$ZZ, _xlpm.fila, _xlpm.colIni+1), _xlpm.dia, INDEX(Maximos_TMAX!$A:$ZZ, _xlpm.fila, _xlpm.colIni+2), IF(OR(_xlpm.anio="",_xlpm.dia=""), "", DATE(_xlpm.anio, _xlpm.mesNum, _xlpm.dia)) ), "")} -> 42189 | AW7: =IF(OR(AT7="",AU7=""),"NA",IFERROR(AT7-AU7,"NA")) -> 0.2
A8: 14015080 | B8: Aeropuerto Rafael Nuñez | C8: Met_Aeronautica | D8: -75.516028 | E8: 10.44725 | F8: 2 | G8: 13 | H8: 13001 | I8: Bolívar | J8: Cartagena de Indias | K8: 33.2 | L8: 33.8 | M8: 32.3 | N8: 31.4 | O8: 32.5 | P8: 34.2 | Q8: 34.3 | R8: 34.6 | S8: 34.4 | T8: 33.6 | U8: 33.2 | V8: 33 | W8: 32 | X8: 33.6 | Y8: 33.8 | Z8: 34.5 | AA8: 33.9 | AB8: 34.1 | AP8: =COUNTIF(K8:AO8,">0") -> 18 | AQ8: =IF(AP8>14,AVERAGE(K8:AO8),"") -> 33.466667 | AR8: =IFERROR(VLOOKUP(A8,Climatologia_TMAX!A:U,9+$E$2,FALSE),"") -> 32.249043 | AS8: =IF(OR(AQ8="",AR8=""),"",IFERROR(AQ8-AR8,"")) -> 1.2176237 | AT8: =IF(COUNT(K8:AO8)=0,"",MAX(K8:AO8)) -> 34.6 | AU8: {=IFERROR( _xlfn.LET( _xlpm.mesTxt, INDEX({"ENERO","FEBRERO","MARZO","ABRIL","MAYO","JUNIO","JULIO","AGOSTO","SEPTIEMBRE","OCTUBRE","NOVIEMBRE","DICIEMBRE"}, E$2), _xlpm.colIni, MATCH(_xlpm.mesTxt, Maximos_TMAX!$1:$1, 0), _xlpm.fila, MATCH($A8, Maximos_TMAX!$A:$A, 0), _xlpm.val, INDEX(Maximos_TMAX!$A:$ZZ, _xlpm.fila, _xlpm.colIni), IF(_xlpm.val="", "", _xlpm.val) ), "")} -> 38 | AV8: {=IFERROR( _xlfn.LET( _xlpm.mesNum, E$2, _xlpm.mesTxt, INDEX({"ENERO","FEBRERO","MARZO","ABRIL","MAYO","JUNIO","JULIO","AGOSTO","SEPTIEMBRE","OCTUBRE","NOVIEMBRE","DICIEMBRE"}, _xlpm.mesNum), _xlpm.colIni, MATCH(_xlpm.mesTxt, Maximos_TMAX!$1:$1, 0), _xlpm.fila, MATCH($A8, Maximos_TMAX!$A:$A, 0), _xlpm.anio, INDEX(Maximos_TMAX!$A:$ZZ, _xlpm.fila, _xlpm.colIni+1), _xlpm.dia, INDEX(Maximos_TMAX!$A:$ZZ, _xlpm.fila, _xlpm.colIni+2), IF(OR(_xlpm.anio="",_xlpm.dia=""), "", DATE(_xlpm.anio, _xlpm.mesNum, _xlpm.dia)) ), "")} -> 45127 | AW8: =IF(OR(AT8="",AU8=""),"NA",IFERROR(AT8-AU8,"NA")) -> -3.4
A9: 29045190 | B9: Aeropuerto Ernesto Cortissoz - AUT | C9: Met_Aeronautica | D9: -74.779722 | E9: 10.917778 | F9: 14 | G9: 8 | H9: 8758 | I9: Atlántico | J9: Soledad | K9: 33.7 | L9: 34.5 | M9: 32.9 | N9: 30.7 | O9: 35.3 | P9: 33.2 | Q9: 34.6 | R9: 35.8 | S9: 35 | T9: 33.9 | U9: 33 | V9: 33.6 | W9: 34.4 | X9: 35.1 | Y9: 34.7 | Z9: 33.2 | AA9: 34.2 | AB9: 34.1 | AP9: =COUNTIF(K9:AO9,">0") -> 18 | AQ9: =IF(AP9>14,AVERAGE(K9:AO9),"") -> 33.994444 | AR9: =IFERROR(VLOOKUP(A9,Climatologia_TMAX!A:U,9+$E$2,FALSE),"") -> 33.091246 | AS9: =IF(OR(AQ9="",AR9=""),"",IFERROR(AQ9-AR9,"")) -> 0.90319831 | AT9: =IF(COUNT(K9:AO9)=0,"",MAX(K9:AO9)) -> 35.8 | AU9: {=IFERROR( _xlfn.LET( _xlpm.mesTxt, INDEX({"ENERO","FEBRERO","MARZO","ABRIL","MAYO","JUNIO","JULIO","AGOSTO","SEPTIEMBRE","OCTUBRE","NOVIEMBRE","DICIEMBRE"}, E$2), _xlpm.colIni, MATCH(_xlpm.mesTxt, Maximos_TMAX!$1:$1, 0), _xlpm.fila, MATCH($A9, Maximos_TMAX!$A:$A, 0), _xlpm.val, INDEX(Maximos_TMAX!$A:$ZZ, _xlpm.fila, _xlpm.colIni), IF(_xlpm.val="", "", _xlpm.val) ), "")} -> 38.4 | AV9: {=IFERROR( _xlfn.LET( _xlpm.mesNum, E$2, _xlpm.mesTxt, INDEX({"ENERO","FEBRERO","MARZO","ABRIL","MAYO","JUNIO","JULIO","AGOSTO","SEPTIEMBRE","OCTUBRE","NOVIEMBRE","DICIEMBRE"}, _xlpm.mesNum), _xlpm.colIni, MATCH(_xlpm.mesTxt, Maximos_TMAX!$1:$1, 0), _xlpm.fila, MATCH($A9, Maximos_TMAX!$A:$A, 0), _xlpm.anio, INDEX(Maximos_TMAX!$A:$ZZ, _xlpm.fila, _xlpm.colIni+1), _xlpm.dia, INDEX(Maximos_TMAX!$A:$ZZ, _xlpm.fila, _xlpm.colIni+2), IF(OR(_xlpm.anio="",_xlpm.dia=""), "", DATE(_xlpm.anio, _xlpm.mesNum, _xlpm.dia)) ), "")} -> 35638 | AW9: =IF(OR(AT9="",AU9=""),"NA",IFERROR(AT9-AU9,"NA")) -> -2.6
A10: 15065180 | B10: Aeropuerto Almirante Padilla | C10: Met_Aeronautica | D10: -72.917667 | E10: 11.529611 | F10: 4 | G10: 44 | H10: 44001 | I10: La Guajira | J10: Riohacha | K10: 36.6 | L10: 36 | M10: 32.4 | N10: 34 | O10: 35.9 | P10: 36 | Q10: 36.9 | R10: 37.1 | S10: 34.9 | T10: 33.9 | U10: 35.8 | V10: 36.8 | W10: 35.9 | X10: 36.7 | Y10: 37 | Z10: 35.7 | AA10: 36.9 | AB10: 36.3 | AP10: =COUNTIF(K10:AO10,">0") -> 18 | AQ10: =IF(AP10>14,AVERAGE(K10:AO10),"") -> 35.822222 | AR10: =IFERROR(VLOOKUP(A10,Climatologia_TMAX!A:U,9+$E$2,FALSE),"") -> 35.380238 | AS10: =IF(OR(AQ10="",AR10=""),"",IFERROR(AQ10-AR10,"")) -> 0.44198399 | AT10: =IF(COUNT(K10:AO10)=0,"",MAX(K10:AO10)) -> 37.1 | AU10: {=IFERROR( _xlfn.LET( _xlpm.mesTxt, INDEX({"ENERO","FEBRERO","MARZO","ABRIL","MAYO","JUNIO","JULIO","AGOSTO","SEPTIEMBRE","OCTUBRE","NOVIEMBRE","DICIEMBRE"}, E$2), _xlpm.colIni, MATCH(_xlpm.mesTxt, Maximos_TMAX!$1:$1, 0), _xlpm.fila, MATCH($A10, Maximos_TMAX!$A:$A, 0), _xlpm.val, INDEX(Maximos_TMAX!$A:$ZZ, _xlpm.fila, _xlpm.colIni), IF(_xlpm.val="", "", _xlpm.val) ), "")} -> 39.2 | AV10: {=IFERROR( _xlfn.LET( _xlpm.mesNum, E$2, _xlpm.mesTxt, INDEX({"ENERO","FEBRERO","MARZO","ABRIL","MAYO","JUNIO","JULIO","AGOSTO","SEPTIEMBRE","OCTUBRE","NOVIEMBRE","DICIEMBRE"}, _xlpm.mesNum), _xlpm.colIni, MATCH(_xlpm.mesTxt, Maximos_TMAX!$1:$1, 0), _xlpm.fila, MATCH($A10, Maximos_TMAX!$A:$A, 0), _xlpm.anio, INDEX(Maximos_TMAX!$A:$ZZ, _xlpm.fila, _xlpm.colIni+1), _xlpm.dia, INDEX(Maximos_TMAX!$A:$ZZ, _xlpm.fila, _xlpm.colIni+2), IF(OR(_xlpm.anio="",_xlpm.dia=""), "", DATE(_xlpm.anio, _xlpm.mesNum, _xlpm.dia)) ), "")} -> 41836 | AW10: =IF(OR(AT10="",AU10=""),"NA",IFERROR(AT10-AU10,"NA")) -> -2.1
A11: 28025502 | B11: Aeropuerto Alfonso López | C11: Met_Aeronautica | D11: -73.247667 | E11: 10.436167 | F11: 138 | G11: 20 | H11: 20001 | I11: Cesar | J11: Valledupar | K11: 39.2 | L11: 38 | M11: 35 | N11: 34.6 | O11: 38.8 | P11: 37.8 | Q11: 40.5 | R11: 39.7 | S11: 37.5 | T11: 37.9 | U11: 38 | V11: 38.4 | W11: 37.4 | X11: 40.4 | Y11: 40.4 | Z11: 38.8 | AA11: 39.6 | AB11: 38.3 | AP11: =COUNTIF(K11:AO11,">0") -> 18 | AQ11: =IF(AP11>14,AVERAGE(K11:AO11),"") -> 38.35 | AR11: =IFERROR(VLOOKUP(A11,Climatologia_TMAX!A:U,9+$E$2,FALSE),"") -> 35.537284 | AS11: =IF(OR(AQ11="",AR11=""),"",IFERROR(AQ11-AR11,"")) -> 2.8127159 | AT11: =IF(COUNT(K11:AO11)=0,"",MAX(K11:AO11)) -> 40.5 | AU11: {=IFERROR( _xlfn.LET( _xlpm.mesTxt, INDEX({"ENERO","FEBRERO","MARZO","ABRIL","MAYO","JUNIO","JULIO","AGOSTO","SEPTIEMBRE","OCTUBRE","NOVIEMBRE","DICIEMBRE"}, E$2), _xlpm.colIni, MATCH(_xlpm.mesTxt, Maximos_TMAX!$1:$1, 0), _xlpm.fila, MATCH($A11, Maximos_TMAX!$A:$A, 0), _xlpm.val, INDEX(Maximos_TMAX!$A:$ZZ, _xlpm.fila, _xlpm.colIni), IF(_xlpm.val="", "", _xlpm.val) ), "")} -> 41.4 | AV11: {=IFERROR( _xlfn.LET( _xlpm.mesNum, E$2, _xlpm.mesTxt, INDEX({"ENERO","FEBRERO","MARZO","ABRIL","MAYO","JUNIO","JULIO","AGOSTO","SEPTIEMBRE","OCTUBRE","NOVIEMBRE","DICIEMBRE"}, _xlpm.mesNum), _xlpm.colIni, MATCH(_xlpm.mesTxt, Maximos_TMAX!$1:$1, 0), _xlpm.fila, MATCH($A11, Maximos_TMAX!$A:$A, 0), _xlpm.anio, INDEX(Maximos_TMAX!$A:$ZZ, _xlpm.fila, _xlpm.colIni+1), _xlpm.dia, INDEX(Maximos_TMAX!$A:$ZZ, _xlpm.fila, _xlpm.colIni+2), IF(OR(_xlpm.anio="",_xlpm.dia=""), "", DATE(_xlpm.anio, _xlpm.mesNum, _xlpm.dia)) ), "")} -> 41840 | AW11: =IF(OR(AT11="",AU11=""),"NA",IFERROR(AT11-AU11,"NA")) -> -0.9
A12: 13035501 | B12: Aeropuerto Los Garzones | C12: Met_Aeronautica | D12: -75.825139 | E12: 8.8258333 | F12: 20 | G12: 23 | H12: 23001 | I12: Córdoba | J12: Montería | K12: 36.8 | L12: 36.2 | M12: 35 | N12: 31.6 | O12: 36.1 | P12: 35.3 | Q12: 36.2 | R12: 37.1 | S12: 30 | T12: 34.5 | U12: 35 | V12: 33.8 | W12: 33.7 | X12: 36.4 | Y12: 37.1 | Z12: 37.5 | AA12: 37.9 | AB12: 36.7 | AP12: =COUNTIF(K12:AO12,">0") -> 18 | AQ12: =IF(AP12>14,AVERAGE(K12:AO12),"") -> 35.383333 | AR12: =IFERROR(VLOOKUP(A12,Climatologia_TMAX!A:U,9+$E$2,FALSE),"") -> 33.224937 | AS12: =IF(OR(AQ12="",AR12=""),"",IFERROR(AQ12-AR12,"")) -> 2.1583967 | AT12: =IF(COUNT(K12:AO12)=0,"",MAX(K12:AO12)) -> 37.9 | AU12: {=IFERROR( _xlfn.LET( _xlpm.mesTxt, INDEX({"ENERO","FEBRERO","MARZO","ABRIL","MAYO","JUNIO","JULIO","AGOSTO","SEPTIEMBRE","OCTUBRE","NOVIEMBRE","DICIEMBRE"}, E$2), _xlpm.colIni, MATCH(_xlpm.mesTxt, Maximos_TMAX!$1:$1, 0), _xlpm.fila, MATCH($A12, Maximos_TMAX!$A:$A, 0), _xlpm.val, INDEX(Maximos_TMAX!$A:$ZZ, _xlpm.fila, _xlpm.colIni), IF(_xlpm.val="", "", _xlpm.val) ), "")} -> 38.4 | AV12: {=IFERROR( _xlfn.LET( _xlpm.mesNum, E$2, _xlpm.mesTxt, INDEX({"ENERO","FEBRERO","MARZO","ABRIL","MAYO","JUNIO","JULIO","AGOSTO","SEPTIEMBRE","OCTUBRE","NOVIEMBRE","DICIEMBRE"}, _xlpm.mesNum), _xlpm.colIni, MATCH(_xlpm.mesTxt, Maximos_TMAX!$1:$1, 0), _xlpm.fila, MATCH($A12, Maximos_TMAX!$A:$A, 0), _xlpm.anio, INDEX(Maximos_TMAX!$A:$ZZ, _xlpm.fila, _xlpm.colIni+1), _xlpm.dia, INDEX(Maximos_TMAX!$A:$ZZ, _xlpm.fila, _xlpm.colIni+2), IF(OR(_xlpm.anio="",_xlpm.dia=""), "", DATE(_xlpm.anio, _xlpm.mesNum, _xlpm.dia)) ), "")} -> 42188 | AW12: =IF(OR(AT12="",AU12=""),"NA",IFERROR(AT12-AU12,"NA")) -> -0.5
A13: 23155030 | B13: Aeropuerto Yariguies | C13: Met_Aeronautica | D13: -73.808611 | E13: 7.0263889 | F13: 126 | G13: 68 | H13: 68081 | I13: Santander | J13: Barrancabermeja | K13: 34.8 | L13: 32.7 | M13: 35.6 | N13: 30.5 | O13: 34.6 | P13: 36.2 | Q13: 36.2 | R13: 36.3 | S13: 29 | T13: 34.5 | U13: 35.4 | V13: 32.3 | W13: 34.4 | X13: 36 | Y13: 35.6 | Z13: 37.2 | AA13: 38.3 | AB13: 35.8 | AP13: =COUNTIF(K13:AO13,">0") -> 18 | AQ13: =IF(AP13>14,AVERAGE(K13:AO13),"") -> 34.744444 | AR13: =IFERROR(VLOOKUP(A13,Climatologia_TMAX!A:U,9+$E$2,FALSE),"") -> 32.673982 | AS13: =IF(OR(AQ13="",AR13=""),"",IFERROR(AQ13-AR13,"")) -> 2.0704622 | AT13: =IF(COUNT(K13:AO13)=0,"",MAX(K13:AO13)) -> 38.3 | AU13: {=IFERROR( _xlfn.LET( _xlpm.mesTxt, INDEX({"ENERO","FEBRERO","MARZO","ABRIL","MAYO","JUNIO","JULIO","AGOSTO","SEPTIEMBRE","OCTUBRE","NOVIEMBRE","DICIEMBRE"}, E$2), _xlpm.colIni, MATCH(_xlpm.mesTxt, Maximos_TMAX!$1:$1, 0), _xlpm.fila, MATCH($A13, Maximos_TMAX!$A:$A, 0), _xlpm.val, INDEX(Maximos_TMAX!$A:$ZZ, _xlpm.fila, _xlpm.colIni), IF(_xlpm.val="", "", _xlpm.val) ), "")} -> 37.6 | AV13: {=IFERROR( _xlfn.LET( _xlpm.mesNum, E$2, _xlpm.mesTxt, INDEX({"ENERO","FEBRERO","MARZO","ABRIL","MAYO","JUNIO","JULIO","AGOSTO","SEPTIEMBRE","OCTUBRE","NOVIEMBRE","DICIEMBRE"}, _xlpm.mesNum), _xlpm.colIni, MATCH(_xlpm.mesTxt, Maximos_TMAX!$1:$1, 0), _xlpm.fila, MATCH($A13, Maximos_TMAX!$A:$A, 0), _xlpm.anio, INDEX(Maximos_TMAX!$A:$ZZ, _xlpm.fila, _xlpm.colIni+1), _xlpm.dia, INDEX(Maximos_TMAX!$A:$ZZ, _xlpm.fila, _xlpm.colIni+2), IF(OR(_xlpm.anio="",_xlpm.dia=""), "", DATE(_xlpm.anio, _xlpm.mesNum, _xlpm.dia)) ), "")} -> 42187 | AW13: =IF(OR(AT13="",AU13=""),"NA",IFERROR(AT13-AU13,"NA")) -> 0.7
A14: 23195502 | B14: Aeropuerto Palonegro | C14: Met_Aeronautica | D14: -73.184528 | E14: 7.1214722 | F14: 1189 | G14: 68 | H14: 68406 | I14: Santander | J14: Lebrija | K14: 28.8 | L14: 27.5 | M14: 26.8 | N14: 25.5 | O14: 29.2 | P14: 30.4 | Q14: 30 | R14: 30.2 | S14: 24.5 | T14: 27.8 | U14: 27.4 | V14: 24.8 | W14: 27.6 | X14: 27.6 | Y14: 30.1 | Z14: 30.3 | AA14: 31.6 | AB14: 27.6 | AP14: =COUNTIF(K14:AO14,">0") -> 18 | AQ14: =IF(AP14>14,AVERAGE(K14:AO14),"") -> 28.205556 | AR14: =IFERROR(VLOOKUP(A14,Climatologia_TMAX!A:U,9+$E$2,FALSE),"") -> 26.059871 | AS14: =IF(OR(AQ14="",AR14=""),"",IFERROR(AQ14-AR14,"")) -> 2.1456847 | AT14: =IF(COUNT(K14:AO14)=0,"",MAX(K14:AO14)) -> 31.6 | AU14: {=IFERROR( _xlfn.LET( _xlpm.mesTxt, INDEX({"ENERO","FEBRERO","MARZO","ABRIL","MAYO","JUNIO","JULIO","AGOSTO","SEPTIEMBRE","OCTUBRE","NOVIEMBRE","DICIEMBRE"}, E$2), _xlpm.colIni, MATCH(_xlpm.mesTxt, Maximos_TMAX!$1:$1, 0), _xlpm.fila, MATCH($A14, Maximos_TMAX!$A:$A, 0), _xlpm.val, INDEX(Maximos_TMAX!$A:$ZZ, _xlpm.fila, _xlpm.colIni), IF(_xlpm.val="", "", _xlpm.val) ), "")} -> 30 | AV14: {=IFERROR( _xlfn.LET( _xlpm.mesNum, E$2, _xlpm.mesTxt, INDEX({"ENERO","FEBRERO","MARZO","ABRIL","MAYO","JUNIO","JULIO","AGOSTO","SEPTIEMBRE","OCTUBRE","NOVIEMBRE","DICIEMBRE"}, _xlpm.mesNum), _xlpm.colIni, MATCH(_xlpm.mesTxt, Maximos_TMAX!$1:$1, 0), _xlpm.fila, MATCH($A14, Maximos_TMAX!$A:$A, 0), _xlpm.anio, INDEX(Maximos_TMAX!$A:$ZZ, _xlpm.fila, _xlpm.colIni+1), _xlpm.dia, INDEX(Maximos_TMAX!$A:$ZZ, _xlpm.fila, _xlpm.colIni+2), IF(OR(_xlpm.anio="",_xlpm.dia=""), "", DATE(_xlpm.anio, _xlpm.mesNum, _xlpm.dia)) ), "")} -> 43652 | AW14: =IF(OR(AT14="",AU14=""),"NA",IFERROR(AT14-AU14,"NA")) -> 1.6
A15: 16015010 | B15: Aeropuerto Camilo Daza | C15: Met_Aeronautica | D15: -72.509167 | E15: 7.9302778 | F15: 250 | G15: 54 | H15: 54001 | I15: Norte de Santander | J15: Cúcuta | K15: 35.1 | L15: 32 | M15: 32.5 | N15: 30.9 | O15: 35.5 | P15: 35.4 | Q15: 33.8 | R15: 37.2 | S15: 30.9 | T15: 34.2 | U15: 33.5 | V15: 32 | W15: 34.7 | X15: 33.8 | Y15: 35.7 | Z15: 33.7 | AA15: 34.6 | AB15: 32.3 | AP15: =COUNTIF(K15:AO15,">0") -> 18 | AQ15: =IF(AP15>14,AVERAGE(K15:AO15),"") -> 33.766667 | AR15: =IFERROR(VLOOKUP(A15,Climatologia_TMAX!A:U,9+$E$2,FALSE),"") -> 33.250962 | AS15: =IF(OR(AQ15="",AR15=""),"",IFERROR(AQ15-AR15,"")) -> 0.51570426 | AT15: =IF(COUNT(K15:AO15)=0,"",MAX(K15:AO15)) -> 37.2 | AU15: {=IFERROR( _xlfn.LET( _xlpm.mesTxt, INDEX({"ENERO","FEBRERO","MARZO","ABRIL","MAYO","JUNIO","JULIO","AGOSTO","SEPTIEMBRE","OCTUBRE","NOVIEMBRE","DICIEMBRE"}, E$2), _xlpm.colIni, MATCH(_xlpm.mesTxt, Maximos_TMAX!$1:$1, 0), _xlpm.fila, MATCH($A15, Maximos_TMAX!$A:$A, 0), _xlpm.val, INDEX(Maximos_TMAX!$A:$ZZ, _xlpm.fila, _xlpm.colIni), IF(_xlpm.val="", "", _xlpm.val) ), "")} -> 37.5 | AV15: {=IFERROR( _xlfn.LET( _xlpm.mesNum, E$2, _xlpm.mesTxt, INDEX({"ENERO","FEBRERO","MARZO","ABRIL","MAYO","JUNIO","JULIO","AGOSTO","SEPTIEMBRE","OCTUBRE","NOVIEMBRE","DICIEMBRE"}, _xlpm.mesNum), _xlpm.colIni, MATCH(_xlpm.mesTxt, Maximos_TMAX!$1:$1, 0), _xlpm.fila, MATCH($A15, Maximos_TMAX!$A:$A, 0), _xlpm.anio, INDEX(Maximos_TMAX!$A:$ZZ, _xlpm.fila, _xlpm.colIni+1), _xlpm.dia, INDEX(Maximos_TMAX!$A:$ZZ, _xlpm.fila, _xlpm.colIni+2), IF(OR(_xlpm.anio="",_xlpm.dia=""), "", DATE(_xlpm.anio, _xlpm.mesNum, _xlpm.dia)) ), "")} -> 33058 | AW15: =IF(OR(AT15="",AU15=""),"NA",IFERROR(AT15-AU15,"NA")) -> -0.3
A16: 12015070 | B16: Aeropuerto Los Cedros | C16: Met_Aeronautica | D16: -76.717889 | E16: 7.8163889 | F16: 41 | G16: 5 | H16: 5147 | I16: Antioquia | J16: Carepa | K16: 32.7 | L16: 32.9 | M16: 32.2 | N16: 29.9 | O16: 33.4 | P16: 29.2 | Q16: 32.9 | R16: 33.4 | S16: 27.3 | T16: 32 | U16: 32 | V16: 29.5 | W16: 32.2 | X16: 32.6 | Y16: 33.1 | Z16: 33.5 | AA16: 33.5 | AB16: 33.1 | AP16: =COUNTIF(K16:AO16,">0") -> 18 | AQ16: =IF(AP16>14,AVERAGE(K16:AO16),"") -> 31.966667 | AR16: =IFERROR(VLOOKUP(A16,Climatologia_TMAX!A:U,9+$E$2,FALSE),"") -> 31.735337 | AS16: =IF(OR(AQ16="",AR16=""),"",IFERROR(AQ16-AR16,"")) -> 0.23132921 | AT16: =IF(COUNT(K16:AO16)=0,"",MAX(K16:AO16)) -> 33.5 | AU16: {=IFERROR( _xlfn.LET( _xlpm.mesTxt, INDEX({"ENERO","FEBRERO","MARZO","ABRIL","MAYO","JUNIO","JULIO","AGOSTO","SEPTIEMBRE","OCTUBRE","NOVIEMBRE","DICIEMBRE"}, E$2), _xlpm.colIni, MATCH(_xlpm.mesTxt, Maximos_TMAX!$1:$1, 0), _xlpm.fila, MATCH($A16, Maximos_TMAX!$A:$A, 0), _xlpm.val, INDEX(Maximos_TMAX!$A:$ZZ, _xlpm.fila, _xlpm.colIni), IF(_xlpm.val="", "", _xlpm.val) ), "")} -> 36 | AV16: {=IFERROR( _xlfn.LET( _xlpm.mesNum, E$2, _xlpm.mesTxt, INDEX({"ENERO","FEBRERO","MARZO","ABRIL","MAYO","JUNIO","JULIO","AGOSTO","SEPTIEMBRE","OCTUBRE","NOVIEMBRE","DICIEMBRE"}, _xlpm.mesNum), _xlpm.colIni, MATCH(_xlpm.mesTxt, Maximos_TMAX!$1:$1, 0), _xlpm.fila, MATCH($A16, Maximos_TMAX!$A:$A, 0), _xlpm.anio, INDEX(Maximos_TMAX!$A:$ZZ, _xlpm.fila, _xlpm.colIni+1), _xlpm.dia, INDEX(Maximos_TMAX!$A:$ZZ, _xlpm.fila, _xlpm.colIni+2), IF(OR(_xlpm.anio="",_xlpm.dia=""), "", DATE(_xlpm.anio, _xlpm.mesNum, _xlpm.dia)) ), "")} -> 41461 | AW16: =IF(OR(AT16="",AU16=""),"NA",IFERROR(AT16-AU16,"NA")) -> -2.5
... A31: 48015050 | B31: Aeropuerto Vásquez Cobo | C31: Met_Aeronautica | D31: -69.940917 | E31: -4.1938611 | F31: 84 | G31: 91 | H31: 91001 | I31: Amazonas | J31: Leticia | K31: 29.1 | L31: 31.3 | M31: 31.7 | N31: 26.1 | O31: 30.1 | P31: 30.1 | Q31: 31 | R31: 27.7 | S31: 32 | T31: 30.4 | U31: 27.6 | V31: 30.4 | W31: 29.3 | X31: 31.1 | Y31: 29.2 | Z31: 31.9 | AA31: 32.8 | AB31: 32.9 | AP31: =COUNTIF(K31:AO31,">0") -> 18 | AQ31: =IF(AP31>14,AVERAGE(K31:AO31),"") -> 30.261111 | AR31: =IFERROR(VLOOKUP(A31,Climatologia_TMAX!A:U,9+$E$2,FALSE),"") -> 30.342533 | AS31: =IF(OR(AQ31="",AR31=""),"",IFERROR(AQ31-AR31,"")) -> -0.081421744 | AT31: =IF(COUNT(K31:AO31)=0,"",MAX(K31:AO31)) -> 32.9 | AU31: {=IFERROR( _xlfn.LET( _xlpm.mesTxt, INDEX({"ENERO","FEBRERO","MARZO","ABRIL","MAYO","JUNIO","JULIO","AGOSTO","SEPTIEMBRE","OCTUBRE","NOVIEMBRE","DICIEMBRE"}, E$2), _xlpm.colIni, MATCH(_xlpm.mesTxt, Maximos_TMAX!$1:$1, 0), _xlpm.fila, MATCH($A31, Maximos_TMAX!$A:$A, 0), _xlpm.val, INDEX(Maximos_TMAX!$A:$ZZ, _xlpm.fila, _xlpm.colIni), IF(_xlpm.val="", "", _xlpm.val) ), "")} -> 35.2 | AV31: {=IFERROR( _xlfn.LET( _xlpm.mesNum, E$2, _xlpm.mesTxt, INDEX({"ENERO","FEBRERO","MARZO","ABRIL","MAYO","JUNIO","JULIO","AGOSTO","SEPTIEMBRE","OCTUBRE","NOVIEMBRE","DICIEMBRE"}, _xlpm.mesNum), _xlpm.colIni, MATCH(_xlpm.mesTxt, Maximos_TMAX!$1:$1, 0), _xlpm.fila, MATCH($A31, Maximos_TMAX!$A:$A, 0), _xlpm.anio, INDEX(Maximos_TMAX!$A:$ZZ, _xlpm.fila, _xlpm.colIni+1), _xlpm.dia, INDEX(Maximos_TMAX!$A:$ZZ, _xlpm.fila, _xlpm.colIni+2), IF(OR(_xlpm.anio="",_xlpm.dia=""), "", DATE(_xlpm.anio, _xlpm.mesNum, _xlpm.dia)) ), "")} -> 42944 | AW31: =IF(OR(AT31="",AU31=""),"NA",IFERROR(AT31-AU31,"NA")) -> -2.3
A32: 23085030 | B32: Alejandria | C32: Area Operativa 01 - Antioquia-Chocó | D32: -75.143389 | E32: 6.37625 | F32: 1712 | G32: 5 | H32: 5021 | I32: Antioquia | J32: Alejandría | AP32: =COUNTIF(K32:AO32,">0") -> 0 | AQ32: =IF(AP32>14,AVERAGE(K32:AO32),"") | AR32: =IFERROR(VLOOKUP(A32,Climatologia_TMAX!A:U,9+$E$2,FALSE),"") -> 25.092837 | AS32: =IF(OR(AQ32="",AR32=""),"",IFERROR(AQ32-AR32,"")) | AT32: =IF(COUNT(K32:AO32)=0,"",MAX(K32:AO32)) | AU32: {=IFERROR( _xlfn.LET( _xlpm.mesTxt, INDEX({"ENERO","FEBRERO","MARZO","ABRIL","MAYO","JUNIO","JULIO","AGOSTO","SEPTIEMBRE","OCTUBRE","NOVIEMBRE","DICIEMBRE"}, E$2), _xlpm.colIni, MATCH(_xlpm.mesTxt, Maximos_TMAX!$1:$1, 0), _xlpm.fila, MATCH($A32, Maximos_TMAX!$A:$A, 0), _xlpm.val, INDEX(Maximos_TMAX!$A:$ZZ, _xlpm.fila, _xlpm.colIni), IF(_xlpm.val="", "", _xlpm.val) ), "")} -> 28.6 | AV32: {=IFERROR( _xlfn.LET( _xlpm.mesNum, E$2, _xlpm.mesTxt, INDEX({"ENERO","FEBRERO","MARZO","ABRIL","MAYO","JUNIO","JULIO","AGOSTO","SEPTIEMBRE","OCTUBRE","NOVIEMBRE","DICIEMBRE"}, _xlpm.mesNum), _xlpm.colIni, MATCH(_xlpm.mesTxt, Maximos_TMAX!$1:$1, 0), _xlpm.fila, MATCH($A32, Maximos_TMAX!$A:$A, 0), _xlpm.anio, INDEX(Maximos_TMAX!$A:$ZZ, _xlpm.fila, _xlpm.colIni+1), _xlpm.dia, INDEX(Maximos_TMAX!$A:$ZZ, _xlpm.fila, _xlpm.colIni+2), IF(OR(_xlpm.anio="",_xlpm.dia=""), "", DATE(_xlpm.anio, _xlpm.mesNum, _xlpm.dia)) ), "")} -> 33788 | AW32: =IF(OR(AT32="",AU32=""),"NA",IFERROR(AT32-AU32,"NA")) -> NA
A33: 23085110 | B33: El Penol | C33: Area Operativa 01 - Antioquia-Chocó | D33: -75.241389 | E33: 6.2138889 | F33: 2022 | G33: 5 | H33: 5541 | I33: Antioquia | J33: Peñol | K33: 27 | L33: 25.6 | M33: 26.8 | N33: 23 | O33: 27 | P33: 27.2 | Q33: 26.6 | R33: 27.8 | S33: 25.2 | T33: 26.4 | U33: 25.6 | V33: 24 | W33: 25.6 | X33: 25.8 | Y33: 26.4 | Z33: 28 | AA33: 27.6 | AB33: 27.8 | AP33: =COUNTIF(K33:AO33,">0") -> 18 | AQ33: =IF(AP33>14,AVERAGE(K33:AO33),"") -> 26.3 | AR33: =IFERROR(VLOOKUP(A33,Climatologia_TMAX!A:U,9+$E$2,FALSE),"") -> 24.633661 | AS33: =IF(OR(AQ33="",AR33=""),"",IFERROR(AQ33-AR33,"")) -> 1.666339 | AT33: =IF(COUNT(K33:AO33)=0,"",MAX(K33:AO33)) -> 28 | AU33: {=IFERROR( _xlfn.LET( _xlpm.mesTxt, INDEX({"ENERO","FEBRERO","MARZO","ABRIL","MAYO","JUNIO","JULIO","AGOSTO","SEPTIEMBRE","OCTUBRE","NOVIEMBRE","DICIEMBRE"}, E$2), _xlpm.colIni, MATCH(_xlpm.mesTxt, Maximos_TMAX!$1:$1, 0), _xlpm.fila, MATCH($A33, Maximos_TMAX!$A:$A, 0), _xlpm.val, INDEX(Maximos_TMAX!$A:$ZZ, _xlpm.fila, _xlpm.colIni), IF(_xlpm.val="", "", _xlpm.val) ), "")} -> 28 | AV33: {=IFERROR( _xlfn.LET( _xlpm.mesNum, E$2, _xlpm.mesTxt, INDEX({"ENERO","FEBRERO","MARZO","ABRIL","MAYO","JUNIO","JULIO","AGOSTO","SEPTIEMBRE","OCTUBRE","NOVIEMBRE","DICIEMBRE"}, _xlpm.mesNum), _xlpm.colIni, MATCH(_xlpm.mesTxt, Maximos_TMAX!$1:$1, 0), _xlpm.fila, MATCH($A33, Maximos_TMAX!$A:$A, 0), _xlpm.anio, INDEX(Maximos_TMAX!$A:$ZZ, _xlpm.fila, _xlpm.colIni+1), _xlpm.dia, INDEX(Maximos_TMAX!$A:$ZZ, _xlpm.fila, _xlpm.colIni+2), IF(OR(_xlpm.anio="",_xlpm.dia=""), "", DATE(_xlpm.anio, _xlpm.mesNum, _xlpm.dia)) ), "")} -> 45499 | AW33: =IF(OR(AT33="",AU33=""),"NA",IFERROR(AT33-AU33,"NA")) -> 0
A34: 23085080 | B34: Granja Experimental El Nus | C34: Area Operativa 01 - Antioquia-Chocó | D34: -74.836694 | E34: 6.4835833 | F34: 859 | G34: 5 | H34: 5670 | I34: Antioquia | J34: San Roque | AP34: =COUNTIF(K34:AO34,">0") -> 0 | AQ34: =IF(AP34>14,AVERAGE(K34:AO34),"") | AR34: =IFERROR(VLOOKUP(A34,Climatologia_TMAX!A:U,9+$E$2,FALSE),"") -> 28.17908 | AS34: =IF(OR(AQ34="",AR34=""),"",IFERROR(AQ34-AR34,"")) | AT34: =IF(COUNT(K34:AO34)=0,"",MAX(K34:AO34)) | AU34: {=IFERROR( _xlfn.LET( _xlpm.mesTxt, INDEX({"ENERO","FEBRERO","MARZO","ABRIL","MAYO","JUNIO","JULIO","AGOSTO","SEPTIEMBRE","OCTUBRE","NOVIEMBRE","DICIEMBRE"}, E$2), _xlpm.colIni, MATCH(_xlpm.mesTxt, Maximos_TMAX!$1:$1, 0), _xlpm.fila, MATCH($A34, Maximos_TMAX!$A:$A, 0), _xlpm.val, INDEX(Maximos_TMAX!$A:$ZZ, _xlpm.fila, _xlpm.colIni), IF(_xlpm.val="", "", _xlpm.val) ), "")} -> 33.6 | AV34: {=IFERROR( _xlfn.LET( _xlpm.mesNum, E$2, _xlpm.mesTxt, INDEX({"ENERO","FEBRERO","MARZO","ABRIL","MAYO","JUNIO","JULIO","AGOSTO","SEPTIEMBRE","OCTUBRE","NOVIEMBRE","DICIEMBRE"}, _xlpm.mesNum), _xlpm.colIni, MATCH(_xlpm.mesTxt, Maximos_TMAX!$1:$1, 0), _xlpm.fila, MATCH($A34, Maximos_TMAX!$A:$A, 0), _xlpm.anio, INDEX(Maximos_TMAX!$A:$ZZ, _xlpm.fila, _xlpm.colIni+1), _xlpm.dia, INDEX(Maximos_TMAX!$A:$ZZ, _xlpm.fila, _xlpm.colIni+2), IF(OR(_xlpm.anio="",_xlpm.dia=""), "", DATE(_xlpm.anio, _xlpm.mesNum, _xlpm.dia)) ), "")} -> 38185 | AW34: =IF(OR(AT34="",AU34=""),"NA",IFERROR(AT34-AU34,"NA")) -> NA
A35: 26175030 | B35: Granja La Nacional | C35: Area Operativa 01 - Antioquia-Chocó | D35: -75.690917 | E35: 5.7173333 | F35: 1153 | G35: 5 | H35: 5789 | I35: Antioquia | J35: Támesis | AP35: =COUNTIF(K35:AO35,">0") -> 0 | AQ35: =IF(AP35>14,AVERAGE(K35:AO35),"") | AR35: =IFERROR(VLOOKUP(A35,Climatologia_TMAX!A:U,9+$E$2,FALSE),"") -> 27.956697 | AS35: =IF(OR(AQ35="",AR35=""),"",IFERROR(AQ35-AR35,"")) | AT35: =IF(COUNT(K35:AO35)=0,"",MAX(K35:AO35)) | AU35: {=IFERROR( _xlfn.LET( _xlpm.mesTxt, INDEX({"ENERO","FEBRERO","MARZO","ABRIL","MAYO","JUNIO","JULIO","AGOSTO","SEPTIEMBRE","OCTUBRE","NOVIEMBRE","DICIEMBRE"}, E$2), _xlpm.colIni, MATCH(_xlpm.mesTxt, Maximos_TMAX!$1:$1, 0), _xlpm.fila, MATCH($A35, Maximos_TMAX!$A:$A, 0), _xlpm.val, INDEX(Maximos_TMAX!$A:$ZZ, _xlpm.fila, _xlpm.colIni), IF(_xlpm.val="", "", _xlpm.val) ), "")} -> 34.4 | AV35: {=IFERROR( _xlfn.LET( _xlpm.mesNum, E$2, _xlpm.mesTxt, INDEX({"ENERO","FEBRERO","MARZO","ABRIL","MAYO","JUNIO","JULIO","AGOSTO","SEPTIEMBRE","OCTUBRE","NOVIEMBRE","DICIEMBRE"}, _xlpm.mesNum), _xlpm.colIni, MATCH(_xlpm.mesTxt, Maximos_TMAX!$1:$1, 0), _xlpm.fila, MATCH($A35, Maximos_TMAX!$A:$A, 0), _xlpm.anio, INDEX(Maximos_TMAX!$A:$ZZ, _xlpm.fila, _xlpm.colIni+1), _xlpm.dia, INDEX(Maximos_TMAX!$A:$ZZ, _xlpm.fila, _xlpm.colIni+2), IF(OR(_xlpm.anio="",_xlpm.dia=""), "", DATE(_xlpm.anio, _xlpm.mesNum, _xlpm.dia)) ), "")} -> 35635 | AW35: =IF(OR(AT35="",AU35=""),"NA",IFERROR(AT35-AU35,"NA")) -> NA
A36: 26175040 | B36: Hacienda Tunez | C36: Area Operativa 01 - Antioquia-Chocó | D36: -75.650972 | E36: 5.80025 | F36: 604 | G36: 5 | H36: 5282 | I36: Antioquia | J36: Fredonia | K36: 36.6 | L36: 32.2 | M36: 33.6 | N36: 31.6 | O36: 36.2 | P36: 36.4 | Q36: 37 | R36: 35 | S36: 35 | T36: 38.4 | U36: 34.8 | V36: 34 | W36: 39 | X36: 39.4 | Y36: 35.2 | Z36: 39 | AA36: 39.2 | AB36: 39 | AP36: =COUNTIF(K36:AO36,">0") -> 18 | AQ36: =IF(AP36>14,AVERAGE(K36:AO36),"") -> 36.2 | AR36: =IFERROR(VLOOKUP(A36,Climatologia_TMAX!A:U,9+$E$2,FALSE),"") -> 33.66953 | AS36: =IF(OR(AQ36="",AR36=""),"",IFERROR(AQ36-AR36,"")) -> 2.5304701 | AT36: =IF(COUNT(K36:AO36)=0,"",MAX(K36:AO36)) -> 39.4 | AU36: {=IFERROR( _xlfn.LET( _xlpm.mesTxt, INDEX({"ENERO","FEBRERO","MARZO","ABRIL","MAYO","JUNIO","JULIO","AGOSTO","SEPTIEMBRE","OCTUBRE","NOVIEMBRE","DICIEMBRE"}, E$2), _xlpm.colIni, MATCH(_xlpm.mesTxt, Maximos_TMAX!$1:$1, 0), _xlpm.fila, MATCH($A36, Maximos_TMAX!$A:$A, 0), _xlpm.val, INDEX(Maximos_TMAX!$A:$ZZ, _xlpm.fila, _xlpm.colIni), IF(_xlpm.val="", "", _xlpm.val) ), "")} -> 39.8 | AV36: {=IFERROR( _xlfn.LET( _xlpm.mesNum, E$2, _xlpm.mesTxt, INDEX({"ENERO","FEBRERO","MARZO","ABRIL","MAYO","JUNIO","JULIO","AGOSTO","SEPTIEMBRE","OCTUBRE","NOVIEMBRE","DICIEMBRE"}, _xlpm.mesNum), _xlpm.colIni, MATCH(_xlpm.mesTxt, Maximos_TMAX!$1:$1, 0), _xlpm.fila, MATCH($A36, Maximos_TMAX!$A:$A, 0), _xlpm.anio, INDEX(Maximos_TMAX!$A:$ZZ, _xlpm.fila, _xlpm.colIni+1), _xlpm.dia, INDEX(Maximos_TMAX!$A:$ZZ, _xlpm.fila, _xlpm.colIni+2), IF(OR(_xlpm.anio="",_xlpm.dia=""), "", DATE(_xlpm.anio, _xlpm.mesNum, _xlpm.dia)) ), "")} -> 41848 | AW36: =IF(OR(AT36="",AU36=""),"NA",IFERROR(AT36-AU36,"NA")) -> -0.4
A37: 26195020 | B37: Ita Andes | C37: Area Operativa 01 - Antioquia-Chocó | D37: -75.880222 | E37: 5.691 | F37: 1180 | G37: 5 | H37: 5034 | I37: Antioquia | J37: Andes | AP37: =COUNTIF(K37:AO37,">0") -> 0 | AQ37: =IF(AP37>14,AVERAGE(K37:AO37),"") | AR37: =IFERROR(VLOOKUP(A37,Climatologia_TMAX!A:U,9+$E$2,FALSE),"") -> 28.567947 | AS37: =IF(OR(AQ37="",AR37=""),"",IFERROR(AQ37-AR37,"")) | AT37: =IF(COUNT(K37:AO37)=0,"",MAX(K37:AO37)) | AU37: {=IFERROR( _xlfn.LET( _xlpm.mesTxt, INDEX({"ENERO","FEBRERO","MARZO","ABRIL","MAYO","JUNIO","JULIO","AGOSTO","SEPTIEMBRE","OCTUBRE","NOVIEMBRE","DICIEMBRE"}, E$2), _xlpm.colIni, MATCH(_xlpm.mesTxt, Maximos_TMAX!$1:$1, 0), _xlpm.fila, MATCH($A37, Maximos_TMAX!$A:$A, 0), _xlpm.val, INDEX(Maximos_TMAX!$A:$ZZ, _xlpm.fila, _xlpm.colIni), IF(_xlpm.val="", "", _xlpm.val) ), "")} -> 34.6 | AV37: {=IFERROR( _xlfn.LET( _xlpm.mesNum, E$2, _xlpm.mesTxt, INDEX({"ENERO","FEBRERO","MARZO","ABRIL","MAYO","JUNIO","JULIO","AGOSTO","SEPTIEMBRE","OCTUBRE","NOVIEMBRE","DICIEMBRE"}, _xlpm.mesNum), _xlpm.colIni, MATCH(_xlpm.mesTxt, Maximos_TMAX!$1:$1, 0), _xlpm.fila, MATCH($A37, Maximos_TMAX!$A:$A, 0), _xlpm.anio, INDEX(Maximos_TMAX!$A:$ZZ, _xlpm.fila, _xlpm.colIni+1), _xlpm.dia, INDEX(Maximos_TMAX!$A:$ZZ, _xlpm.fila, _xlpm.colIni+2), IF(OR(_xlpm.anio="",_xlpm.dia=""), "", DATE(_xlpm.anio, _xlpm.mesNum, _xlpm.dia)) ), "")} -> 30149 | AW37: =IF(OR(AT37="",AU37=""),"NA",IFERROR(AT37-AU37,"NA")) -> NA
A38: 26205080 | B38: La Aldea | C38: Area Operativa 01 - Antioquia-Chocó | D38: -75.700944 | E38: 6.3410556 | F38: 1737 | G38: 5 | H38: 5001 | I38: Antioquia | J38: Medellín | K38: 27.6 | L38: 28.2 | M38: 28.4 | N38: 24.2 | O38: 29.2 | P38: 30.6 | Q38: 31 | R38: 29 | S38: 25 | T38: 28.4 | U38: 27.4 | V38: 24.8 | W38: 28 | X38: 29.2 | Y38: 27.8 | Z38: 30.4 | AA38: 29.8 | AB38: 28.6 | AP38: =COUNTIF(K38:AO38,">0") -> 18 | AQ38: =IF(AP38>14,AVERAGE(K38:AO38),"") -> 28.2 | AR38: =IFERROR(VLOOKUP(A38,Climatologia_TMAX!A:U,9+$E$2,FALSE),"") | AS38: =IF(OR(AQ38="",AR38=""),"",IFERROR(AQ38-AR38,"")) | AT38: =IF(COUNT(K38:AO38)=0,"",MAX(K38:AO38)) -> 31 | AU38: {=IFERROR( _xlfn.LET( _xlpm.mesTxt, INDEX({"ENERO","FEBRERO","MARZO","ABRIL","MAYO","JUNIO","JULIO","AGOSTO","SEPTIEMBRE","OCTUBRE","NOVIEMBRE","DICIEMBRE"}, E$2), _xlpm.colIni, MATCH(_xlpm.mesTxt, Maximos_TMAX!$1:$1, 0), _xlpm.fila, MATCH($A38, Maximos_TMAX!$A:$A, 0), _xlpm.val, INDEX(Maximos_TMAX!$A:$ZZ, _xlpm.fila, _xlpm.colIni), IF(_xlpm.val="", "", _xlpm.val) ), "")} -> 30 | AV38: {=IFERROR( _xlfn.LET( _xlpm.mesNum, E$2, _xlpm.mesTxt, INDEX({"ENERO","FEBRERO","MARZO","ABRIL","MAYO","JUNIO","JULIO","AGOSTO","SEPTIEMBRE","OCTUBRE","NOVIEMBRE","DICIEMBRE"}, _xlpm.mesNum), _xlpm.colIni, MATCH(_xlpm.mesTxt, Maximos_TMAX!$1:$1, 0), _xlpm.fila, MATCH($A38, Maximos_TMAX!$A:$A, 0), _xlpm.anio, INDEX(Maximos_TMAX!$A:$ZZ, _xlpm.fila, _xlpm.colIni+1), _xlpm.dia, INDEX(Maximos_TMAX!$A:$ZZ, _xlpm.fila, _xlpm.colIni+2), IF(OR(_xlpm.anio="",_xlpm.dia=""), "", DATE(_xlpm.anio, _xlpm.mesNum, _xlpm.dia)) ), "")} -> 45502 | AW38: =IF(OR(AT38="",AU38=""),"NA",IFERROR(AT38-AU38,"NA")) -> 1
A39: 27015260 | B39: La Salada | C39: Area Operativa 01 - Antioquia-Chocó | D39: -75.624667 | E39: 6.0483611 | F39: 1923 | G39: 5 | H39: 5129 | I39: Antioquia | J39: Caldas | K39: 27.4 | L39: 27.2 | M39: 27 | N39: 25 | O39: 28.2 | P39: 28 | Q39: 27.8 | R39: 27.4 | S39: 24.8 | T39: 27.2 | U39: 25.4 | V39: 24.4 | W39: 26.6 | X39: 27 | Y39: 26.2 | Z39: 27.2 | AA39: 27.4 | AB39: 27.8 | AP39: =COUNTIF(K39:AO39,">0") -> 18 | AQ39: =IF(AP39>14,AVERAGE(K39:AO39),"") -> 26.777778 | AR39: =IFERROR(VLOOKUP(A39,Climatologia_TMAX!A:U,9+$E$2,FALSE),"") -> 23.752467 | AS39: =IF(OR(AQ39="",AR39=""),"",IFERROR(AQ39-AR39,"")) -> 3.0253111 | AT39: =IF(COUNT(K39:AO39)=0,"",MAX(K39:AO39)) -> 28.2 | AU39: {=IFERROR( _xlfn.LET( _xlpm.mesTxt, INDEX({"ENERO","FEBRERO","MARZO","ABRIL","MAYO","JUNIO","JULIO","AGOSTO","SEPTIEMBRE","OCTUBRE","NOVIEMBRE","DICIEMBRE"}, E$2), _xlpm.colIni, MATCH(_xlpm.mesTxt, Maximos_TMAX!$1:$1, 0), _xlpm.fila, MATCH($A39, Maximos_TMAX!$A:$A, 0), _xlpm.val, INDEX(Maximos_TMAX!$A:$ZZ, _xlpm.fila, _xlpm.colIni), IF(_xlpm.val="", "", _xlpm.val) ), "")} -> 30 | AV39: {=IFERROR( _xlfn.LET( _xlpm.mesNum, E$2, _xlpm.mesTxt, INDEX({"ENERO","FEBRERO","MARZO","ABRIL","MAYO","JUNIO","JULIO","AGOSTO","SEPTIEMBRE","OCTUBRE","NOVIEMBRE","DICIEMBRE"}, _xlpm.mesNum), _xlpm.colIni, MATCH(_xlpm.mesTxt, Maximos_TMAX!$1:$1, 0), _xlpm.fila, MATCH($A39, Maximos_TMAX!$A:$A, 0), _xlpm.anio, INDEX(Maximos_TMAX!$A:$ZZ, _xlpm.fila, _xlpm.colIni+1), _xlpm.dia, INDEX(Maximos_TMAX!$A:$ZZ, _xlpm.fila, _xlpm.colIni+2), IF(OR(_xlpm.anio="",_xlpm.dia=""), "", DATE(_xlpm.anio, _xlpm.mesNum, _xlpm.dia)) ), "")} -> 44397 | AW39: =IF(OR(AT39="",AU39=""),"NA",IFERROR(AT39-AU39,"NA")) -> -1.8
A40: 26185020 | B40: Mesopotamia | C40: Area Operativa 01 - Antioquia-Chocó | D40: -75.318639 | E40: 5.8863611 | F40: 2408 | G40: 5 | H40: 5400 | I40: Antioquia | J40: La Unión | K40: 22.2 | L40: 21.6 | M40: 21.2 | N40: 20.4 | O40: 22 | P40: 22.4 | Q40: 23.2 | R40: 22.8 | S40: 21.2 | T40: 21 | U40: 21.4 | V40: 19.4 | W40: 21 | X40: 20.8 | Y40: 21.4 | Z40: 21.6 | AA40: 22 | AB40: 22.4 | AP40: =COUNTIF(K40:AO40,">0") -> 18 | AQ40: =IF(AP40>14,AVERAGE(K40:AO40),"") -> 21.555556 | AR40: =IFERROR(VLOOKUP(A40,Climatologia_TMAX!A:U,9+$E$2,FALSE),"") -> 20.412982 | AS40: =IF(OR(AQ40="",AR40=""),"",IFERROR(AQ40-AR40,"")) -> 1.1425732 | AT40: =IF(COUNT(K40:AO40)=0,"",MAX(K40:AO40)) -> 23.2 | AU40: {=IFERROR( _xlfn.LET( _xlpm.mesTxt, INDEX({"ENERO","FEBRERO","MARZO","ABRIL","MAYO","JUNIO","JULIO","AGOSTO","SEPTIEMBRE","OCTUBRE","NOVIEMBRE","DICIEMBRE"}, E$2), _xlpm.colIni, MATCH(_xlpm.mesTxt, Maximos_TMAX!$1:$1, 0), _xlpm.fila, MATCH($A40, Maximos_TMAX!$A:$A, 0), _xlpm.val, INDEX(Maximos_TMAX!$A:$ZZ, _xlpm.fila, _xlpm.colIni), IF(_xlpm.val="", "", _xlpm.val) ), "")} | AV40: {=IFERROR( _xlfn.LET( _xlpm.mesNum, E$2, _xlpm.mesTxt, INDEX({"ENERO","FEBRERO","MARZO","ABRIL","MAYO","JUNIO","JULIO","AGOSTO","SEPTIEMBRE","OCTUBRE","NOVIEMBRE","DICIEMBRE"}, _xlpm.mesNum), _xlpm.colIni, MATCH(_xlpm.mesTxt, Maximos_TMAX!$1:$1, 0), _xlpm.fila, MATCH($A40, Maximos_TMAX!$A:$A, 0), _xlpm.anio, INDEX(Maximos_TMAX!$A:$ZZ, _xlpm.fila, _xlpm.colIni+1), _xlpm.dia, INDEX(Maximos_TMAX!$A:$ZZ, _xlpm.fila, _xlpm.colIni+2), IF(OR(_xlpm.anio="",_xlpm.dia=""), "", DATE(_xlpm.anio, _xlpm.mesNum, _xlpm.dia)) ), "")} | AW40: =IF(OR(AT40="",AU40=""),"NA",IFERROR(AT40-AU40,"NA")) -> NA
A41: 23085140 | B41: San Francisco | C41: Area Operativa 01 - Antioquia-Chocó | D41: -75.100694 | E41: 5.9638056 | F41: 1325 | G41: 5 | H41: 5652 | I41: Antioquia | J41: San Francisco | AP41: =COUNTIF(K41:AO41,">0") -> 0 | AQ41: =IF(AP41>14,AVERAGE(K41:AO41),"") | AR41: =IFERROR(VLOOKUP(A41,Climatologia_TMAX!A:U,9+$E$2,FALSE),"") -> 26.30914 | AS41: =IF(OR(AQ41="",AR41=""),"",IFERROR(AQ41-AR41,"")) | AT41: =IF(COUNT(K41:AO41)=0,"",MAX(K41:AO41)) | AU41: {=IFERROR( _xlfn.LET( _xlpm.mesTxt, INDEX({"ENERO","FEBRERO","MARZO","ABRIL","MAYO","JUNIO","JULIO","AGOSTO","SEPTIEMBRE","OCTUBRE","NOVIEMBRE","DICIEMBRE"}, E$2), _xlpm.colIni, MATCH(_xlpm.mesTxt, Maximos_TMAX!$1:$1, 0), _xlpm.fila, MATCH($A41, Maximos_TMAX!$A:$A, 0), _xlpm.val, INDEX(Maximos_TMAX!$A:$ZZ, _xlpm.fila, _xlpm.colIni), IF(_xlpm.val="", "", _xlpm.val) ), "")} -> 31 | AV41: {=IFERROR( _xlfn.LET( _xlpm.mesNum, E$2, _xlpm.mesTxt, INDEX({"ENERO","FEBRERO","MARZO","ABRIL","MAYO","JUNIO","JULIO","AGOSTO","SEPTIEMBRE","OCTUBRE","NOVIEMBRE","DICIEMBRE"}, _xlpm.mesNum), _xlpm.colIni, MATCH(_xlpm.mesTxt, Maximos_TMAX!$1:$1, 0), _xlpm.fila, MATCH($A41, Maximos_TMAX!$A:$A, 0), _xlpm.anio, INDEX(Maximos_TMAX!$A:$ZZ, _xlpm.fila, _xlpm.colIni+1), _xlpm.dia, INDEX(Maximos_TMAX!$A:$ZZ, _xlpm.fila, _xlpm.colIni+2), IF(OR(_xlpm.anio="",_xlpm.dia=""), "", DATE(_xlpm.anio, _xlpm.mesNum, _xlpm.dia)) ), "")} -> 42187 | AW41: =IF(OR(AT41="",AU41=""),"NA",IFERROR(AT41-AU41,"NA")) -> NA
A42: 27015090 | B42: Tulio Ospina | C42: Area Operativa 01 - Antioquia-Chocó | D42: -75.55325 | E42: 6.3196944 | F42: 1453 | G42: 5 | H42: 5088 | I42: Antioquia | J42: Bello | K42: 32 | L42: 32.6 | M42: 32 | N42: 28.6 | O42: 33.2 | P42: 35 | Q42: 35 | R42: 34.4 | S42: 28.2 | T42: 32.8 | U42: 33.2 | V42: 28.2 | W42: 32 | X42: 33 | Y42: 32 | Z42: 33.4 | AA42: 34 | AB42: 33.8 | AP42: =COUNTIF(K42:AO42,">0") -> 18 | AQ42: =IF(AP42>14,AVERAGE(K42:AO42),"") -> 32.411111 | AR42: =IFERROR(VLOOKUP(A42,Climatologia_TMAX!A:U,9+$E$2,FALSE),"") | AS42: =IF(OR(AQ42="",AR42=""),"",IFERROR(AQ42-AR42,"")) | AT42: =IF(COUNT(K42:AO42)=0,"",MAX(K42:AO42)) -> 35 | AU42: {=IFERROR( _xlfn.LET( _xlpm.mesTxt, INDEX({"ENERO","FEBRERO","MARZO","ABRIL","MAYO","JUNIO","JULIO","AGOSTO","SEPTIEMBRE","OCTUBRE","NOVIEMBRE","DICIEMBRE"}, E$2), _xlpm.colIni, MATCH(_xlpm.mesTxt, Maximos_TMAX!$1:$1, 0), _xlpm.fila, MATCH($A42, Maximos_TMAX!$A:$A, 0), _xlpm.val, INDEX(Maximos_TMAX!$A:$ZZ, _xlpm.fila, _xlpm.colIni), IF(_xlpm.val="", "", _xlpm.val) ), "")} -> 34 | AV42: {=IFERROR( _xlfn.LET( _xlpm.mesNum, E$2, _xlpm.mesTxt, INDEX({"ENERO","FEBRERO","MARZO","ABRIL","MAYO","JUNIO","JULIO","AGOSTO","SEPTIEMBRE","OCTUBRE","NOVIEMBRE","DICIEMBRE"}, _xlpm.mesNum), _xlpm.colIni, MATCH(_xlpm.mesTxt, Maximos_TMAX!$1:$1, 0), _xlpm.fila, MATCH($A42, Maximos_TMAX!$A:$A, 0), _xlpm.anio, INDEX(Maximos_TMAX!$A:$ZZ, _xlpm.fila, _xlpm.colIni+1), _xlpm.dia, INDEX(Maximos_TMAX!$A:$ZZ, _xlpm.fila, _xlpm.colIni+2), IF(OR(_xlpm.anio="",_xlpm.dia=""), "", DATE(_xlpm.anio, _xlpm.mesNum, _xlpm.dia)) ), "")} -> 45502 | AW42: =IF(OR(AT42="",AU42=""),"NA",IFERROR(AT42-AU42,"NA")) -> 1
A43: 12015020 | B43: Uniban | C43: Area Operativa 01 - Antioquia-Chocó | D43: -76.651333 | E43: 7.8259167 | F43: 43 | G43: 5 | H43: 5045 | I43: Antioquia | J43: Apartadó | K43: 33 | L43: 31.6 | M43: 33.2 | N43: 30.8 | O43: 33.4 | P43: 32.4 | Q43: 33.2 | R43: 33.4 | S43: 29.8 | T43: 32.4 | U43: 33 | V43: 30.2 | W43: 32 | X43: 33 | Y43: 34.8 | Z43: 33.4 | AA43: 33.2 | AB43: 32.8 | AP43: =COUNTIF(K43:AO43,">0") -> 18 | AQ43: =IF(AP43>14,AVERAGE(K43:AO43),"") -> 32.533333 | AR43: =IFERROR(VLOOKUP(A43,Climatologia_TMAX!A:U,9+$E$2,FALSE),"") -> 31.608867 | AS43: =IF(OR(AQ43="",AR43=""),"",IFERROR(AQ43-AR43,"")) -> 0.92446661 | AT43: =IF(COUNT(K43:AO43)=0,"",MAX(K43:AO43)) -> 34.8 | AU43: {=IFERROR( _xlfn.LET( _xlpm.mesTxt, INDEX({"ENERO","FEBRERO","MARZO","ABRIL","MAYO","JUNIO","JULIO","AGOSTO","SEPTIEMBRE","OCTUBRE","NOVIEMBRE","DICIEMBRE"}, E$2), _xlpm.colIni, MATCH(_xlpm.mesTxt, Maximos_TMAX!$1:$1, 0), _xlpm.fila, MATCH($A43, Maximos_TMAX!$A:$A, 0), _xlpm.val, INDEX(Maximos_TMAX!$A:$ZZ, _xlpm.fila, _xlpm.colIni), IF(_xlpm.val="", "", _xlpm.val) ), "")} -> 36 | AV43: {=IFERROR( _xlfn.LET( _xlpm.mesNum, E$2, _xlpm.mesTxt, INDEX({"ENERO","FEBRERO","MARZO","ABRIL","MAYO","JUNIO","JULIO","AGOSTO","SEPTIEMBRE","OCTUBRE","NOVIEMBRE","DICIEMBRE"}, _xlpm.mesNum), _xlpm.colIni, MATCH(_xlpm.mesTxt, Maximos_TMAX!$1:$1, 0), _xlpm.fila, MATCH($A43, Maximos_TMAX!$A:$A, 0), _xlpm.anio, INDEX(Maximos_TMAX!$A:$ZZ, _xlpm.fila, _xlpm.colIni+1), _xlpm.dia, INDEX(Maximos_TMAX!$A:$ZZ, _xlpm.fila, _xlpm.colIni+2), IF(OR(_xlpm.anio="",_xlpm.dia=""), "", DATE(_xlpm.anio, _xlpm.mesNum, _xlpm.dia)) ), "")} -> 44386 | AW43: =IF(OR(AT43="",AU43=""),"NA",IFERROR(AT43-AU43,"NA")) -> -1.2
A44: 11075020 | B44: Urrao | C44: Area Operativa 01 - Antioquia-Chocó | D44: -76.143306 | E44: 6.2983056 | F44: 1833 | G44: 5 | H44: 5847 | I44: Antioquia | J44: Urrao | K44: 27.2 | L44: 27.4 | M44: 26.8 | N44: 27.2 | O44: 26.8 | P44: 22 | Q44: 27.2 | R44: 27.6 | S44: 27.8 | T44: 28 | U44: 28 | V44: 27.2 | W44: 27.8 | X44: 28.6 | Y44: 28.4 | Z44: 28 | AA44: 29 | AB44: 28.4 | AP44: =COUNTIF(K44:AO44,">0") -> 18 | AQ44: =IF(AP44>14,AVERAGE(K44:AO44),"") -> 27.411111 | AR44: =IFERROR(VLOOKUP(A44,Climatologia_TMAX!A:U,9+$E$2,FALSE),"") -> 22.961797 | AS44: =IF(OR(AQ44="",AR44=""),"",IFERROR(AQ44-AR44,"")) -> 4.4493136 | AT44: =IF(COUNT(K44:AO44)=0,"",MAX(K44:AO44)) -> 29 | AU44: {=IFERROR( _xlfn.LET( _xlpm.mesTxt, INDEX({"ENERO","FEBRERO","MARZO","ABRIL","MAYO","JUNIO","JULIO","AGOSTO","SEPTIEMBRE","OCTUBRE","NOVIEMBRE","DICIEMBRE"}, E$2), _xlpm.colIni, MATCH(_xlpm.mesTxt, Maximos_TMAX!$1:$1, 0), _xlpm.fila, MATCH($A44, Maximos_TMAX!$A:$A, 0), _xlpm.val, INDEX(Maximos_TMAX!$A:$ZZ, _xlpm.fila, _xlpm.colIni), IF(_xlpm.val="", "", _xlpm.val) ), "")} -> 29 | AV44: {=IFERROR( _xlfn.LET( _xlpm.mesNum, E$2, _xlpm.mesTxt, INDEX({"ENERO","FEBRERO","MARZO","ABRIL","MAYO","JUNIO","JULIO","AGOSTO","SEPTIEMBRE","OCTUBRE","NOVIEMBRE","DICIEMBRE"}, _xlpm.mesNum), _xlpm.colIni, MATCH(_xlpm.mesTxt, Maximos_TMAX!$1:$1, 0), _xlpm.fila, MATCH($A44, Maximos_TMAX!$A:$A, 0), _xlpm.anio, INDEX(Maximos_TMAX!$A:$ZZ, _xlpm.fila, _xlpm.colIni+1), _xlpm.dia, INDEX(Maximos_TMAX!$A:$ZZ, _xlpm.fila, _xlpm.colIni+2), IF(OR(_xlpm.anio="",_xlpm.dia=""), "", DATE(_xlpm.anio, _xlpm.mesNum, _xlpm.dia)) ), "")} -> 45127 | AW44: =IF(OR(AT44="",AU44=""),"NA",IFERROR(AT44-AU44,"NA")) -> 0
A45: 25025080 | B45: Aeropuerto Rafael Barvo | C45: Area Operativa 02 - Atlántico-Bolivar-Sucre | D45: -75.283056 | E45: 9.3338889 | F45: 166 | G45: 70 | H45: 70215 | I45: Sucre | J45: Corozal | K45: 36.8 | L45: 37 | M45: 36.8 | N45: 33.6 | O45: 35.8 | P45: 36.6 | Q45: 37.8 | R45: 38 | S45: 31.8 | T45: 36.8 | U45: 36.6 | V45: 34.2 | W45: 35.2 | X45: 36 | Y45: 37.6 | Z45: 37.8 | AA45: 38.2 | AB45: 36.8 | AP45: =COUNTIF(K45:AO45,">0") -> 18 | AQ45: =IF(AP45>14,AVERAGE(K45:AO45),"") -> 36.3 | AR45: =IFERROR(VLOOKUP(A45,Climatologia_TMAX!A:U,9+$E$2,FALSE),"") -> 33.381792 | AS45: =IF(OR(AQ45="",AR45=""),"",IFERROR(AQ45-AR45,"")) -> 2.9182079 | AT45: =IF(COUNT(K45:AO45)=0,"",MAX(K45:AO45)) -> 38.2 | AU45: {=IFERROR( _xlfn.LET( _xlpm.mesTxt, INDEX({"ENERO","FEBRERO","MARZO","ABRIL","MAYO","JUNIO","JULIO","AGOSTO","SEPTIEMBRE","OCTUBRE","NOVIEMBRE","DICIEMBRE"}, E$2), _xlpm.colIni, MATCH(_xlpm.mesTxt, Maximos_TMAX!$1:$1, 0), _xlpm.fila, MATCH($A45, Maximos_TMAX!$A:$A, 0), _xlpm.val, INDEX(Maximos_TMAX!$A:$ZZ, _xlpm.fila, _xlpm.colIni), IF(_xlpm.val="", "", _xlpm.val) ), "")} -> 38.2 | AV45: {=IFERROR( _xlfn.LET( _xlpm.mesNum, E$2, _xlpm.mesTxt, INDEX({"ENERO","FEBRERO","MARZO","ABRIL","MAYO","JUNIO","JULIO","AGOSTO","SEPTIEMBRE","OCTUBRE","NOVIEMBRE","DICIEMBRE"}, _xlpm.mesNum), _xlpm.colIni, MATCH(_xlpm.mesTxt, Maximos_TMAX!$1:$1, 0), _xlpm.fila, MATCH($A45, Maximos_TMAX!$A:$A, 0), _xlpm.anio, INDEX(Maximos_TMAX!$A:$ZZ, _xlpm.fila, _xlpm.colIni+1), _xlpm.dia, INDEX(Maximos_TMAX!$A:$ZZ, _xlpm.fila, _xlpm.colIni+2), IF(OR(_xlpm.anio="",_xlpm.dia=""), "", DATE(_xlpm.anio, _xlpm.mesNum, _xlpm.dia)) ), "")} -> 35635 | AW45: =IF(OR(AT45="",AU45=""),"NA",IFERROR(AT45-AU45,"NA")) -> 0
A46: 12045010 | B46: Arboletes | C46: Area Operativa 02 - Atlántico-Bolivar-Sucre | D46: -76.431944 | E46: 8.8469444 | F46: 4 | G46: 5 | H46: 5051 | I46: Antioquia | J46: Arboletes | K46: 32.4 | L46: 32.2 | M46: 31.8 | N46: 31 | O46: 32.2 | P46: 32 | Q46: 32.8 | R46: 32.6 | S46: 28.8 | T46: 31.8 | U46: 32 | V46: 31.8 | W46: 30.2 | X46: 32.2 | Y46: 32.8 | Z46: 33 | AA46: 32.8 | AB46: 32.6 | AP46: =COUNTIF(K46:AO46,">0") -> 18 | AQ46: =IF(AP46>14,AVERAGE(K46:AO46),"") -> 31.944444 | AR46: =IFERROR(VLOOKUP(A46,Climatologia_TMAX!A:U,9+$E$2,FALSE),"") | AS46: =IF(OR(AQ46="",AR46=""),"",IFERROR(AQ46-AR46,"")) | AT46: =IF(COUNT(K46:AO46)=0,"",MAX(K46:AO46)) -> 33 | AU46: {=IFERROR( _xlfn.LET( _xlpm.mesTxt, INDEX({"ENERO","FEBRERO","MARZO","ABRIL","MAYO","JUNIO","JULIO","AGOSTO","SEPTIEMBRE","OCTUBRE","NOVIEMBRE","DICIEMBRE"}, E$2), _xlpm.colIni, MATCH(_xlpm.mesTxt, Maximos_TMAX!$1:$1, 0), _xlpm.fila, MATCH($A46, Maximos_TMAX!$A:$A, 0), _xlpm.val, INDEX(Maximos_TMAX!$A:$ZZ, _xlpm.fila, _xlpm.colIni), IF(_xlpm.val="", "", _xlpm.val) ), "")} -> 36 | AV46: {=IFERROR( _xlfn.LET( _xlpm.mesNum, E$2, _xlpm.mesTxt, INDEX({"ENERO","FEBRERO","MARZO","ABRIL","MAYO","JUNIO","JULIO","AGOSTO","SEPTIEMBRE","OCTUBRE","NOVIEMBRE","DICIEMBRE"}, _xlpm.mesNum), _xlpm.colIni, MATCH(_xlpm.mesTxt, Maximos_TMAX!$1:$1, 0), _xlpm.fila, MATCH($A46, Maximos_TMAX!$A:$A, 0), _xlpm.anio, INDEX(Maximos_TMAX!$A:$ZZ, _xlpm.fila, _xlpm.colIni+1), _xlpm.dia, INDEX(Maximos_TMAX!$A:$ZZ, _xlpm.fila, _xlpm.colIni+2), IF(OR(_xlpm.anio="",_xlpm.dia=""), "", DATE(_xlpm.anio, _xlpm.mesNum, _xlpm.dia)) ), "")} -> 33437 | AW46: =IF(OR(AT46="",AU46=""),"NA",IFERROR(AT46-AU46,"NA")) -> -3
A47: 14010050 | B47: Cañaveral | C47: Area Operativa 02 - Atlántico-Bolivar-Sucre | D47: -75.335295 | E47: 10.392974 | F47: 75 | G47: 13 | H47: 13836 | I47: Bolívar | J47: Turbaco | AP47: =COUNTIF(K47:AO47,">0") -> 0 | AQ47: =IF(AP47>14,AVERAGE(K47:AO47),"") | AR47: =IFERROR(VLOOKUP(A47,Climatologia_TMAX!A:U,9+$E$2,FALSE),"") | AS47: =IF(OR(AQ47="",AR47=""),"",IFERROR(AQ47-AR47,"")) | AT47: =IF(COUNT(K47:AO47)=0,"",MAX(K47:AO47)) | AU47: {=IFERROR( _xlfn.LET( _xlpm.mesTxt, INDEX({"ENERO","FEBRERO","MARZO","ABRIL","MAYO","JUNIO","JULIO","AGOSTO","SEPTIEMBRE","OCTUBRE","NOVIEMBRE","DICIEMBRE"}, E$2), _xlpm.colIni, MATCH(_xlpm.mesTxt, Maximos_TMAX!$1:$1, 0), _xlpm.fila, MATCH($A47, Maximos_TMAX!$A:$A, 0), _xlpm.val, INDEX(Maximos_TMAX!$A:$ZZ, _xlpm.fila, _xlpm.colIni), IF(_xlpm.val="", "", _xlpm.val) ), "")} | AV47: {=IFERROR( _xlfn.LET( _xlpm.mesNum, E$2, _xlpm.mesTxt, INDEX({"ENERO","FEBRERO","MARZO","ABRIL","MAYO","JUNIO","JULIO","AGOSTO","SEPTIEMBRE","OCTUBRE","NOVIEMBRE","DICIEMBRE"}, _xlpm.mesNum), _xlpm.colIni, MATCH(_xlpm.mesTxt, Maximos_TMAX!$1:$1, 0), _xlpm.fila, MATCH($A47, Maximos_TMAX!$A:$A, 0), _xlpm.anio, INDEX(Maximos_TMAX!$A:$ZZ, _xlpm.fila, _xlpm.colIni+1), _xlpm.dia, INDEX(Maximos_TMAX!$A:$ZZ, _xlpm.fila, _xlpm.colIni+2), IF(OR(_xlpm.anio="",_xlpm.dia=""), "", DATE(_xlpm.anio, _xlpm.mesNum, _xlpm.dia)) ), "")} | AW47: =IF(OR(AT47="",AU47=""),"NA",IFERROR(AT47-AU47,"NA")) -> NA
A48: 13090040 | B48: Chalan | C48: Area Operativa 02 - Atlántico-Bolivar-Sucre | D48: -75.3225 | E48: 9.5386111 | F48: 100 | G48: 70 | H48: 70230 | I48: Sucre | J48: Chalán | AP48: =COUNTIF(K48:AO48,">0") -> 0 | AQ48: =IF(AP48>14,AVERAGE(K48:AO48),"") | AR48: =IFERROR(VLOOKUP(A48,Climatologia_TMAX!A:U,9+$E$2,FALSE),"") | AS48: =IF(OR(AQ48="",AR48=""),"",IFERROR(AQ48-AR48,"")) | AT48: =IF(COUNT(K48:AO48)=0,"",MAX(K48:AO48)) | AU48: {=IFERROR( _xlfn.LET( _xlpm.mesTxt, INDEX({"ENERO","FEBRERO","MARZO","ABRIL","MAYO","JUNIO","JULIO","AGOSTO","SEPTIEMBRE","OCTUBRE","NOVIEMBRE","DICIEMBRE"}, E$2), _xlpm.colIni, MATCH(_xlpm.mesTxt, Maximos_TMAX!$1:$1, 0), _xlpm.fila, MATCH($A48, Maximos_TMAX!$A:$A, 0), _xlpm.val, INDEX(Maximos_TMAX!$A:$ZZ, _xlpm.fila, _xlpm.colIni), IF(_xlpm.val="", "", _xlpm.val) ), "")} | AV48: {=IFERROR( _xlfn.LET( _xlpm.mesNum, E$2, _xlpm.mesTxt, INDEX({"ENERO","FEBRERO","MARZO","ABRIL","MAYO","JUNIO","JULIO","AGOSTO","SEPTIEMBRE","OCTUBRE","NOVIEMBRE","DICIEMBRE"}, _xlpm.mesNum), _xlpm.colIni, MATCH(_xlpm.mesTxt, Maximos_TMAX!$1:$1, 0), _xlpm.fila, MATCH($A48, Maximos_TMAX!$A:$A, 0), _xlpm.anio, INDEX(Maximos_TMAX!$A:$ZZ, _xlpm.fila, _xlpm.colIni+1), _xlpm.dia, INDEX(Maximos_TMAX!$A:$ZZ, _xlpm.fila, _xlpm.colIni+2), IF(OR(_xlpm.anio="",_xlpm.dia=""), "", DATE(_xlpm.anio, _xlpm.mesNum, _xlpm.dia)) ), "")} | AW48: =IF(OR(AT48="",AU48=""),"NA",IFERROR(AT48-AU48,"NA")) -> NA
A49: 13075010 | B49: Chima | C49: Area Operativa 02 - Atlántico-Bolivar-Sucre | D49: -75.622083 | E49: 9.15075 | F49: 20 | G49: 23 | H49: 23168 | I49: Córdoba | J49: Chimá | K49: 37.2 | L49: 35.6 | M49: 34.2 | N49: 30 | O49: 36 | P49: 35 | Q49: 36.4 | R49: 37.2 | S49: 31.8 | T49: 35.6 | U49: 34.8 | V49: 33.6 | W49: 33.2 | X49: 36 | Y49: 37.2 | Z49: 37.8 | AA49: 37.8 | AB49: 36.6 | AP49: =COUNTIF(K49:AO49,">0") -> 18 | AQ49: =IF(AP49>14,AVERAGE(K49:AO49),"") -> 35.333333 | AR49: =IFERROR(VLOOKUP(A49,Climatologia_TMAX!A:U,9+$E$2,FALSE),"") -> 32.823446 | AS49: =IF(OR(AQ49="",AR49=""),"",IFERROR(AQ49-AR49,"")) -> 2.5098877 | AT49: =IF(COUNT(K49:AO49)=0,"",MAX(K49:AO49)) -> 37.8 | AU49: {=IFERROR( _xlfn.LET( _xlpm.mesTxt, INDEX({"ENERO","FEBRERO","MARZO","ABRIL","MAYO","JUNIO","JULIO","AGOSTO","SEPTIEMBRE","OCTUBRE","NOVIEMBRE","DICIEMBRE"}, E$2), _xlpm.colIni, MATCH(_xlpm.mesTxt, Maximos_TMAX!$1:$1, 0), _xlpm.fila, MATCH($A49, Maximos_TMAX!$A:$A, 0), _xlpm.val, INDEX(Maximos_TMAX!$A:$ZZ, _xlpm.fila, _xlpm.colIni), IF(_xlpm.val="", "", _xlpm.val) ), "")} -> 39.6 | AV49: {=IFERROR( _xlfn.LET( _xlpm.mesNum, E$2, _xlpm.mesTxt, INDEX({"ENERO","FEBRERO","MARZO","ABRIL","MAYO","JUNIO","JULIO","AGOSTO","SEPTIEMBRE","OCTUBRE","NOVIEMBRE","DICIEMBRE"}, _xlpm.mesNum), _xlpm.colIni, MATCH(_xlpm.mesTxt, Maximos_TMAX!$1:$1, 0), _xlpm.fila, MATCH($A49, Maximos_TMAX!$A:$A, 0), _xlpm.anio, INDEX(Maximos_TMAX!$A:$ZZ, _xlpm.fila, _xlpm.colIni+1), _xlpm.dia, INDEX(Maximos_TMAX!$A:$ZZ, _xlpm.fila, _xlpm.colIni+2), IF(OR(_xlpm.anio="",_xlpm.dia=""), "", DATE(_xlpm.anio, _xlpm.mesNum, _xlpm.dia)) ), "")} -> 42189 | AW49: =IF(OR(AT49="",AU49=""),"NA",IFERROR(AT49-AU49,"NA")) -> -1.8
A50: 25020470 | B50: Chinu - AUT | C50: Area Operativa 02 - Atlántico-Bolivar-Sucre | D50: -75.393333 | E50: 9.1177778 | F50: 125 | G50: 23 | H50: 23182 | I50: Córdoba | J50: Chinú | AP50: =COUNTIF(K50:AO50,">0") -> 0 | AQ50: =IF(AP50>14,AVERAGE(K50:AO50),"") | AR50: =IFERROR(VLOOKUP(A50,Climatologia_TMAX!A:U,9+$E$2,FALSE),"") | AS50: =IF(OR(AQ50="",AR50=""),"",IFERROR(AQ50-AR50,"")) | AT50: =IF(COUNT(K50:AO50)=0,"",MAX(K50:AO50)) | AU50: {=IFERROR( _xlfn.LET( _xlpm.mesTxt, INDEX({"ENERO","FEBRERO","MARZO","ABRIL","MAYO","JUNIO","JULIO","AGOSTO","SEPTIEMBRE","OCTUBRE","NOVIEMBRE","DICIEMBRE"}, E$2), _xlpm.colIni, MATCH(_xlpm.mesTxt, Maximos_TMAX!$1:$1, 0), _xlpm.fila, MATCH($A50, Maximos_TMAX!$A:$A, 0), _xlpm.val, INDEX(Maximos_TMAX!$A:$ZZ, _xlpm.fila, _xlpm.colIni), IF(_xlpm.val="", "", _xlpm.val) ), "")} | AV50: {=IFERROR( _xlfn.LET( _xlpm.mesNum, E$2, _xlpm.mesTxt, INDEX({"ENERO","FEBRERO","MARZO","ABRIL","MAYO","JUNIO","JULIO","AGOSTO","SEPTIEMBRE","OCTUBRE","NOVIEMBRE","DICIEMBRE"}, _xlpm.mesNum), _xlpm.colIni, MATCH(_xlpm.mesTxt, Maximos_TMAX!$1:$1, 0), _xlpm.fila, MATCH($A50, Maximos_TMAX!$A:$A, 0), _xlpm.anio, INDEX(Maximos_TMAX!$A:$ZZ, _xlpm.fila, _xlpm.colIni+1), _xlpm.dia, INDEX(Maximos_TMAX!$A:$ZZ, _xlpm.fila, _xlpm.colIni+2), IF(OR(_xlpm.anio="",_xlpm.dia=""), "", DATE(_xlpm.anio, _xlpm.mesNum, _xlpm.dia)) ), "")} | AW50: =IF(OR(AT50="",AU50=""),"NA",IFERROR(AT50-AU50,"NA")) -> NA
A51: 25025170 | B51: Colomboy | C51: Area Operativa 02 - Atlántico-Bolivar-Sucre | D51: -75.498833 | E51: 8.7408611 | F51: 125 | G51: 23 | H51: 23660 | I51: Córdoba | J51: Sahagún | AP51: =COUNTIF(K51:AO51,">0") -> 0 | AQ51: =IF(AP51>14,AVERAGE(K51:AO51),"") | AR51: =IFERROR(VLOOKUP(A51,Climatologia_TMAX!A:U,9+$E$2,FALSE),"") -> 32.006171 | AS51: =IF(OR(AQ51="",AR51=""),"",IFERROR(AQ51-AR51,"")) | AT51: =IF(COUNT(K51:AO51)=0,"",MAX(K51:AO51)) | AU51: {=IFERROR( _xlfn.LET( _xlpm.mesTxt, INDEX({"ENERO","FEBRERO","MARZO","ABRIL","MAYO","JUNIO","JULIO","AGOSTO","SEPTIEMBRE","OCTUBRE","NOVIEMBRE","DICIEMBRE"}, E$2), _xlpm.colIni, MATCH(_xlpm.mesTxt, Maximos_TMAX!$1:$1, 0), _xlpm.fila, MATCH($A51, Maximos_TMAX!$A:$A, 0), _xlpm.val, INDEX(Maximos_TMAX!$A:$ZZ, _xlpm.fila, _xlpm.colIni), IF(_xlpm.val="", "", _xlpm.val) ), "")} -> 37.2 | AV51: {=IFERROR( _xlfn.LET( _xlpm.mesNum, E$2, _xlpm.mesTxt, INDEX({"ENERO","FEBRERO","MARZO","ABRIL","MAYO","JUNIO","JULIO","AGOSTO","SEPTIEMBRE","OCTUBRE","NOVIEMBRE","DICIEMBRE"}, _xlpm.mesNum), _xlpm.colIni, MATCH(_xlpm.mesTxt, Maximos_TMAX!$1:$1, 0), _xlpm.fila, MATCH($A51, Maximos_TMAX!$A:$A, 0), _xlpm.anio, INDEX(Maximos_TMAX!$A:$ZZ, _xlpm.fila, _xlpm.colIni+1), _xlpm.dia, INDEX(Maximos_TMAX!$A:$ZZ, _xlpm.fila, _xlpm.colIni+2), IF(OR(_xlpm.anio="",_xlpm.dia=""), "", DATE(_xlpm.anio, _xlpm.mesNum, _xlpm.dia)) ), "")} -> 41839 | AW51: =IF(OR(AT51="",AU51=""),"NA",IFERROR(AT51-AU51,"NA")) -> NA
A52: 12045020 | B52: Cristo Rey - AUT | C52: Area Operativa 02 - Atlántico-Bolivar-Sucre | D52: -76.224444 | E52: 9.0711111 | F52: 15 | G52: 23 | H52: 23574 | I52: Córdoba | J52: Puerto Escondido | K52: 32.8 | M52: 31.6 | N52: 31.4 | O52: 32 | P52: 32.2 | Q52: 33 | R52: 32.6 | S52: 31.4 | T52: 31.6 | U52: 32 | V52: 31.6 | W52: 31 | X52: 32.4 | Y52: 32.8 | Z52: 33.2 | AA52: 34 | AB52: 33 | AP52: =COUNTIF(K52:AO52,">0") -> 17 | AQ52: =IF(AP52>14,AVERAGE(K52:AO52),"") -> 32.270588 | AR52: =IFERROR(VLOOKUP(A52,Climatologia_TMAX!A:U,9+$E$2,FALSE),"") -> 31.351722 | AS52: =IF(OR(AQ52="",AR52=""),"",IFERROR(AQ52-AR52,"")) -> 0.91886585 | AT52: =IF(COUNT(K52:AO52)=0,"",MAX(K52:AO52)) -> 34 | AU52: {=IFERROR( _xlfn.LET( _xlpm.mesTxt, INDEX({"ENERO","FEBRERO","MARZO","ABRIL","MAYO","JUNIO","JULIO","AGOSTO","SEPTIEMBRE","OCTUBRE","NOVIEMBRE","DICIEMBRE"}, E$2), _xlpm.colIni, MATCH(_xlpm.mesTxt, Maximos_TMAX!$1:$1, 0), _xlpm.fila, MATCH($A52, Maximos_TMAX!$A:$A, 0), _xlpm.val, INDEX(Maximos_TMAX!$A:$ZZ, _xlpm.fila, _xlpm.colIni), IF(_xlpm.val="", "", _xlpm.val) ), "")} | AV52: {=IFERROR( _xlfn.LET( _xlpm.mesNum, E$2, _xlpm.mesTxt, INDEX({"ENERO","FEBRERO","MARZO","ABRIL","MAYO","JUNIO","JULIO","AGOSTO","SEPTIEMBRE","OCTUBRE","NOVIEMBRE","DICIEMBRE"}, _xlpm.mesNum), _xlpm.colIni, MATCH(_xlpm.mesTxt, Maximos_TMAX!$1:$1, 0), _xlpm.fila, MATCH($A52, Maximos_TMAX!$A:$A, 0), _xlpm.anio, INDEX(Maximos_TMAX!$A:$ZZ, _xlpm.fila, _xlpm.colIni+1), _xlpm.dia, INDEX(Maximos_TMAX!$A:$ZZ, _xlpm.fila, _xlpm.colIni+2), IF(OR(_xlpm.anio="",_xlpm.dia=""), "", DATE(_xlpm.anio, _xlpm.mesNum, _xlpm.dia)) ), "")} | AW52: =IF(OR(AT52="",AU52=""),"NA",IFERROR(AT52-AU52,"NA")) -> NA
A53: 25025160 | B53: Cuba Hacienda | C53: Area Operativa 02 - Atlántico-Bolivar-Sucre | D53: -75.402778 | E53: 8.0038889 | F53: 50 | G53: 23 | H53: 23466 | I53: Córdoba | J53: Montelíbano | K53: 35.2 | L53: 34 | M53: 34.2 | N53: 32 | O53: 35.2 | P53: 35 | Q53: 35.2 | R53: 37 | S53: 30.2 | T53: 34 | U53: 36.2 | V53: 33.8 | W53: 32.8 | X53: 34.8 | Y53: 35.8 | Z53: 35.8 | AA53: 36.8 | AB53: 34.2 | AP53: =COUNTIF(K53:AO53,">0") -> 18 | AQ53: =IF(AP53>14,AVERAGE(K53:AO53),"") -> 34.566667 | AR53: =IFERROR(VLOOKUP(A53,Climatologia_TMAX!A:U,9+$E$2,FALSE),"") -> 32.406929 | AS53: =IF(OR(AQ53="",AR53=""),"",IFERROR(AQ53-AR53,"")) -> 2.1597377 | AT53: =IF(COUNT(K53:AO53)=0,"",MAX(K53:AO53)) -> 37 | AU53: {=IFERROR( _xlfn.LET( _xlpm.mesTxt, INDEX({"ENERO","FEBRERO","MARZO","ABRIL","MAYO","JUNIO","JULIO","AGOSTO","SEPTIEMBRE","OCTUBRE","NOVIEMBRE","DICIEMBRE"}, E$2), _xlpm.colIni, MATCH(_xlpm.mesTxt, Maximos_TMAX!$1:$1, 0), _xlpm.fila, MATCH($A53, Maximos_TMAX!$A:$A, 0), _xlpm.val, INDEX(Maximos_TMAX!$A:$ZZ, _xlpm.fila, _xlpm.colIni), IF(_xlpm.val="", "", _xlpm.val) ), "")} -> 36 | AV53: {=IFERROR( _xlfn.LET( _xlpm.mesNum, E$2, _xlpm.mesTxt, INDEX({"ENERO","FEBRERO","MARZO","ABRIL","MAYO","JUNIO","JULIO","AGOSTO","SEPTIEMBRE","OCTUBRE","NOVIEMBRE","DICIEMBRE"}, _xlpm.mesNum), _xlpm.colIni, MATCH(_xlpm.mesTxt, Maximos_TMAX!$1:$1, 0), _xlpm.fila, MATCH($A53, Maximos_TMAX!$A:$A, 0), _xlpm.anio, INDEX(Maximos_TMAX!$A:$ZZ, _xlpm.fila, _xlpm.colIni+1), _xlpm.dia, INDEX(Maximos_TMAX!$A:$ZZ, _xlpm.fila, _xlpm.colIni+2), IF(OR(_xlpm.anio="",_xlpm.dia=""), "", DATE(_xlpm.anio, _xlpm.mesNum, _xlpm.dia)) ), "")} -> 45127 | AW53: =IF(OR(AT53="",AU53=""),"NA",IFERROR(AT53-AU53,"NA")) -> 1
A54: 29015000 | B54: El Guamo - AUT | C54: Area Operativa 02 - Atlántico-Bolivar-Sucre | D54: -74.976638 | E54: 10.034607 | F54: 75 | G54: 13 | H54: 13248 | I54: Bolívar | J54: El Guamo | K54: 37.8 | L54: 38.8 | Q54: 39 | R54: 40 | S54: 34 | T54: 38.4 | U54: 38.8 | V54: 36.6 | W54: 36 | X54: 38.4 | Y54: 40.4 | Z54: 40.6 | AA54: 41.6 | AB54: 39.4 | AP54: =COUNTIF(K54:AO54,">0") -> 14 | AQ54: =IF(AP54>14,AVERAGE(K54:AO54),"") | AR54: =IFERROR(VLOOKUP(A54,Climatologia_TMAX!A:U,9+$E$2,FALSE),"") | AS54: =IF(OR(AQ54="",AR54=""),"",IFERROR(AQ54-AR54,"")) | AT54: =IF(COUNT(K54:AO54)=0,"",MAX(K54:AO54)) -> 41.6 | AU54: {=IFERROR( _xlfn.LET( _xlpm.mesTxt, INDEX({"ENERO","FEBRERO","MARZO","ABRIL","MAYO","JUNIO","JULIO","AGOSTO","SEPTIEMBRE","OCTUBRE","NOVIEMBRE","DICIEMBRE"}, E$2), _xlpm.colIni, MATCH(_xlpm.mesTxt, Maximos_TMAX!$1:$1, 0), _xlpm.fila, MATCH($A54, Maximos_TMAX!$A:$A, 0), _xlpm.val, INDEX(Maximos_TMAX!$A:$ZZ, _xlpm.fila, _xlpm.colIni), IF(_xlpm.val="", "", _xlpm.val) ), "")} -> 42 | AV54: {=IFERROR( _xlfn.LET( _xlpm.mesNum, E$2, _xlpm.mesTxt, INDEX({"ENERO","FEBRERO","MARZO","ABRIL","MAYO","JUNIO","JULIO","AGOSTO","SEPTIEMBRE","OCTUBRE","NOVIEMBRE","DICIEMBRE"}, _xlpm.mesNum), _xlpm.colIni, MATCH(_xlpm.mesTxt, Maximos_TMAX!$1:$1, 0), _xlpm.fila, MATCH($A54, Maximos_TMAX!$A:$A, 0), _xlpm.anio, INDEX(Maximos_TMAX!$A:$ZZ, _xlpm.fila, _xlpm.colIni+1), _xlpm.dia, INDEX(Maximos_TMAX!$A:$ZZ, _xlpm.fila, _xlpm.colIni+2), IF(OR(_xlpm.anio="",_xlpm.dia=""), "", DATE(_xlpm.anio, _xlpm.mesNum, _xlpm.dia)) ), "")} -> 42188 | AW54: =IF(OR(AT54="",AU54=""),"NA",IFERROR(AT54-AU54,"NA")) -> -0.4
